Workbook
Name rNum: PROCESSOS!$A$5:$A$1004
Name rEmpresa: PROCESSOS!$B$5:$B$1004
Name rRamo: PROCESSOS!$C$5:$C$1004
Name rDataFisc: PROCESSOS!$D$5:$D$1004
Name rNotif: PROCESSOS!$E$5:$E$1004
Name rTipo: PROCESSOS!$F$5:$F$1004
Name rStatus: PROCESSOS!$G$5:$G$1004
Name rResp: PROCESSOS!$H$5:$H$1004
Name rNumNotif: PROCESSOS!$I$5:$I$1004
Name rProcOrig: PROCESSOS!$J$5:$J$1004
Name rDataOrig: PROCESSOS!$K$5:$K$1004
Name rPrazo: PROCESSOS!$L$5:$L$1004
Name rDias: PROCESSOS!$M$5:$M$1004
Name rSit: PROCESSOS!$N$5:$N$1004
Name rIdade: PROCESSOS!$O$5:$O$1004
Name PrazoConst: CADASTROS!$M$6
Name PrazoEsc: CADASTROS!$M$7
Name DiasAlerta: CADASTROS!$M$8
Name MetaMensal: CADASTROS!$M$9
Name critResp: CALC!$C$3
Name hProx: CALC!$BF$5:$BF$1004
Name hUlt: CALC!$BG$5:$BG$1004
Name FiltroResp: PAINEL!$K$7
Name FiltroAno: PAINEL!$Y$7

Sheet PAINEL
B2: PAINEL DE GESTÃO DE PROCESSOS | AJ2: ATUALIZADO EM
AJ3: =TODAY() -> 46303
B4: Fluxo de Notificações e Fiscalizações • Visão do Gerente de Processos | AJ4: ="Base: "&COUNTA(rEmpresa)&" processos cadastrados" -> Base: 96 processos cadastrados
B7: FILTROS | F7: Responsável: | K7: TODOS | T7: Ano ref.: | Y7: 2026 | AD7: ▸ GRÁFICOS | AI7: ▸ PROCESSOS | AN7: ▸ CADASTROS | AS7: ▸ INSTRUÇÕES
B9: INDICADORES PRINCIPAIS
B12: TOTAL DE PROCESSOS | J12: EM PRAZO D.P | R12: EM DECISÃO D.P | Z12: DENTRO DO PRAZO | AH12: ="VENCEM EM ATÉ "&DiasAlerta&" DIAS" -> VENCEM EM ATÉ 5 DIAS | AP12: FISCALIZAÇÕES NO MÊS
B13: =COUNTIFS(rEmpresa,"<>",rResp,critResp) -> 96 | J13: =COUNTIFS(rEmpresa,"<>",rResp,critResp,rStatus,"PRAZO D.P") -> 29 | R13: =COUNTIFS(rEmpresa,"<>",rResp,critResp,rStatus,"DECISÃO D.P") -> 67 | Z13: =COUNTIFS(rEmpresa,"<>",rResp,critResp,rSit,"NO PRAZO") -> 6 | AH13: =COUNTIFS(rEmpresa,"<>",rResp,critResp,rSit,"VENCE EM BREVE") -> 6 | AP13: =COUNTIFS(rEmpresa,"<>",rResp,critResp,rDataFisc,">="&DATE(YEAR(TODAY()),MONTH(TODAY()),1),rDataFisc,"<"&DATE(YEAR(TODAY()),MONTH(TODAY())+1,1)) -> 10
B15: registros na base (filtro aplicado) | J15: =IFERROR(J13/B13,0) -> 0.30208333 | M15: do total | R15: =IFERROR(R13/B13,0) -> 0.69791667 | U15: do total | Z15: =IFERROR(Z13/J13,0) -> 0.20689655 | AC15: dos em prazo D.P | AH15: =IFERROR(AH13/J13,0) -> 0.20689655 | AK15: dos em prazo D.P | AP15: =AP13-COUNTIFS(rEmpresa,"<>",rResp,critResp,rDataFisc,">="&DATE(YEAR(TODAY()),MONTH(TODAY())-1,1),rDataFisc,"<"&DATE(YEAR(TODAY()),MONTH(TODAY()),1)) -> -13 | AS15: vs mês anterior
B18: NOTIF. DE CONSTATAÇÃO | J18: NOTIF. DE ESCLARECIMENTO | R18: NOTIFICAÇÕES PRESENCIAIS | Z18: NOTIFICAÇÕES ELETRÔNICAS | AH18: IDADE MÉDIA DOS PROCESSOS | AP18: FISCALIZAÇÕES NO ANO REF.
B19: =COUNTIFS(rEmpresa,"<>",rResp,critResp,rNotif,"NOTIFICAÇÃO DE CONSTATAÇÃO") -> 62 | J19: =COUNTIFS(rEmpresa,"<>",rResp,critResp,rNotif,"NOTIFICAÇÃO DE ESCLARECIMENTO") -> 34 | R19: =COUNTIFS(rEmpresa,"<>",rResp,critResp,rTipo,"PRESENCIAL") -> 58 | Z19: =COUNTIFS(rEmpresa,"<>",rResp,critResp,rTipo,"ELETRÔNICA") -> 38 | AH19: =IFERROR(AVERAGEIFS(rIdade,rEmpresa,"<>",rResp,critResp),0) -> 83.28125 | AP19: =COUNTIFS(rEmpresa,"<>",rResp,critResp,rDataFisc,">="&DATE(FiltroAno,1,1),rDataFisc,"<"&DATE(FiltroAno+1,1,1)) -> 96
B21: =IFERROR(B19/$B$13,0) -> 0.64583333 | E21: do total | J21: =IFERROR(J19/$B$13,0) -> 0.35416667 | M21: do total | R21: =IFERROR(R19/$B$13,0) -> 0.60416667 | U21: do total | Z21: =IFERROR(Z19/$B$13,0) -> 0.39583333 | AC21: do total | AH21: dias desde a fiscalização | AP21: =IFERROR(AP19/(MetaMensal*12),0) -> 0.66666667 | AS21: da meta anual
B23: AGENDA — PRÓXIMOS VENCIMENTOS (TOP 10) | Z23: ÚLTIMAS FISCALIZAÇÕES REGISTRADAS (TOP 10)
B25: # | D25: EMPRESA | L25: RESPONSÁVEL | R25: PRAZO FINAL | V25: DIAS | Z25: # | AB25: EMPRESA | AJ25: RESPONSÁVEL | AP25: FISCALIZAÇÃO | AT25: NOTIF.
B26: =IF(CALC!$BJ$5="","",1) -> 1 | D26: =IF(CALC!$BJ$5="",IF(1=1,"✓ Nenhum prazo pendente",""),INDEX(rEmpresa,CALC!$BJ$5)) -> Clínica Estrela | L26: =IF(CALC!$BJ$5="","",INDEX(rResp,CALC!$BJ$5)) -> DIEGO RIBEIRO | R26: =IF(CALC!$BJ$5="","",INDEX(rPrazo,CALC!$BJ$5)) -> 46303 | V26: =IF(CALC!$BJ$5="","",INDEX(rDias,CALC!$BJ$5)) -> 0 | Z26: =IF(CALC!$BK$5="","",1) -> 1 | AB26: =IF(CALC!$BK$5="",IF(1=1,"Nenhuma fiscalização registrada",""),INDEX(rEmpresa,CALC!$BK$5)) -> Escola Vitória | AJ26: =IF(CALC!$BK$5="","",INDEX(rResp,CALC!$BK$5)) -> ANA PAULA SOUZA | AP26: =IF(CALC!$BK$5="","",INDEX(rDataFisc,CALC!$BK$5)) -> 46303 | AT26: =IF(CALC!$BK$5="","",IF(INDEX(rNotif,CALC!$BK$5)="NOTIFICAÇÃO DE CONSTATAÇÃO","CONST.","ESCLAR.")) -> ESCLAR.
B27: =IF(CALC!$BJ$6="","",2) -> 2 | D27: =IF(CALC!$BJ$6="",IF(2=1,"✓ Nenhum prazo pendente",""),INDEX(rEmpresa,CALC!$BJ$6)) -> Academia Central | L27: =IF(CALC!$BJ$6="","",INDEX(rResp,CALC!$BJ$6)) -> DIEGO RIBEIRO | R27: =IF(CALC!$BJ$6="","",INDEX(rPrazo,CALC!$BJ$6)) -> 46304 | V27: =IF(CALC!$BJ$6="","",INDEX(rDias,CALC!$BJ$6)) -> 1 | Z27: =IF(CALC!$BK$6="","",2) -> 2 | AB27: =IF(CALC!$BK$6="",IF(2=1,"Nenhuma fiscalização registrada",""),INDEX(rEmpresa,CALC!$BK$6)) -> Banco Aliança | AJ27: =IF(CALC!$BK$6="","",INDEX(rResp,CALC!$BK$6)) -> GABRIELA NUNES | AP27: =IF(CALC!$BK$6="","",INDEX(rDataFisc,CALC!$BK$6)) -> 46302 | AT27: =IF(CALC!$BK$6="","",IF(INDEX(rNotif,CALC!$BK$6)="NOTIFICAÇÃO DE CONSTATAÇÃO","CONST.","ESCLAR.")) -> ESCLAR.
B28: =IF(CALC!$BJ$7="","",3) -> 3 | D28: =IF(CALC!$BJ$7="",IF(3=1,"✓ Nenhum prazo pendente",""),INDEX(rEmpresa,CALC!$BJ$7)) -> Farmácia Horizonte | L28: =IF(CALC!$BJ$7="","",INDEX(rResp,CALC!$BJ$7)) -> CARLA MENDES | R28: =IF(CALC!$BJ$7="","",INDEX(rPrazo,CALC!$BJ$7)) -> 46306 | V28: =IF(CALC!$BJ$7="","",INDEX(rDias,CALC!$BJ$7)) -> 3 | Z28: =IF(CALC!$BK$7="","",3) -> 3 | AB28: =IF(CALC!$BK$7="",IF(3=1,"Nenhuma fiscalização registrada",""),INDEX(rEmpresa,CALC!$BK$7)) -> Financeira São Jorge Ltda | AJ28: =IF(CALC!$BK$7="","",INDEX(rResp,CALC!$BK$7)) -> GABRIELA NUNES | AP28: =IF(CALC!$BK$7="","",INDEX(rDataFisc,CALC!$BK$7)) -> 46302 | AT28: =IF(CALC!$BK$7="","",IF(INDEX(rNotif,CALC!$BK$7)="NOTIFICAÇÃO DE CONSTATAÇÃO","CONST.","ESCLAR.")) -> CONST.
B29: =IF(CALC!$BJ$8="","",4) -> 4 | D29: =IF(CALC!$BJ$8="",IF(4=1,"✓ Nenhum prazo pendente",""),INDEX(rEmpresa,CALC!$BJ$8)) -> Auto Center Central 24h | L29: =IF(CALC!$BJ$8="","",INDEX(rResp,CALC!$BJ$8)) -> DIEGO RIBEIRO | R29: =IF(CALC!$BJ$8="","",INDEX(rPrazo,CALC!$BJ$8)) -> 46307 | V29: =IF(CALC!$BJ$8="","",INDEX(rDias,CALC!$BJ$8)) -> 4 | Z29: =IF(CALC!$BK$8="","",4) -> 4 | AB29: =IF(CALC!$BK$8="",IF(4=1,"Nenhuma fiscalização registrada",""),INDEX(rEmpresa,CALC!$BK$8)) -> Boutique Aliança | AJ29: =IF(CALC!$BK$8="","",INDEX(rResp,CALC!$BK$8)) -> CARLA MENDES | AP29: =IF(CALC!$BK$8="","",INDEX(rDataFisc,CALC!$BK$8)) -> 46302 | AT29: =IF(CALC!$BK$8="","",IF(INDEX(rNotif,CALC!$BK$8)="NOTIFICAÇÃO DE CONSTATAÇÃO","CONST.","ESCLAR.")) -> ESCLAR.
B30: =IF(CALC!$BJ$9="","",5) -> 5 | D30: =IF(CALC!$BJ$9="",IF(5=1,"✓ Nenhum prazo pendente",""),INDEX(rEmpresa,CALC!$BJ$9)) -> Churrascaria Bela Vista | L30: =IF(CALC!$BJ$9="","",INDEX(rResp,CALC!$BJ$9)) -> DIEGO RIBEIRO | R30: =IF(CALC!$BJ$9="","",INDEX(rPrazo,CALC!$BJ$9)) -> 46308 | V30: =IF(CALC!$BJ$9="","",INDEX(rDias,CALC!$BJ$9)) -> 5 | Z30: =IF(CALC!$BK$9="","",5) -> 5 | AB30: =IF(CALC!$BK$9="",IF(5=1,"Nenhuma fiscalização registrada",""),INDEX(rEmpresa,CALC!$BK$9)) -> Escola Real | AJ30: =IF(CALC!$BK$9="","",INDEX(rResp,CALC!$BK$9)) -> DIEGO RIBEIRO | AP30: =IF(CALC!$BK$9="","",INDEX(rDataFisc,CALC!$BK$9)) -> 46299 | AT30: =IF(CALC!$BK$9="","",IF(INDEX(rNotif,CALC!$BK$9)="NOTIFICAÇÃO DE CONSTATAÇÃO","CONST.","ESCLAR.")) -> ESCLAR.
B31: =IF(CALC!$BJ$10="","",6) -> 6 | D31: =IF(CALC!$BJ$10="",IF(6=1,"✓ Nenhum prazo pendente",""),INDEX(rEmpresa,CALC!$BJ$10)) -> Magazine Central | L31: =IF(CALC!$BJ$10="","",INDEX(rResp,CALC!$BJ$10)) -> CARLA MENDES | R31: =IF(CALC!$BJ$10="","",INDEX(rPrazo,CALC!$BJ$10)) -> 46308 | V31: =IF(CALC!$BJ$10="","",INDEX(rDias,CALC!$BJ$10)) -> 5 | Z31: =IF(CALC!$BK$10="","",6) -> 6 | AB31: =IF(CALC!$BK$10="",IF(6=1,"Nenhuma fiscalização registrada",""),INDEX(rEmpresa,CALC!$BK$10)) -> Magazine Central | AJ31: =IF(CALC!$BK$10="","",INDEX(rResp,CALC!$BK$10)) -> CARLA MENDES | AP31: =IF(CALC!$BK$10="","",INDEX(rDataFisc,CALC!$BK$10)) -> 46298 | AT31: =IF(CALC!$BK$10="","",IF(INDEX(rNotif,CALC!$BK$10)="NOTIFICAÇÃO DE CONSTATAÇÃO","CONST.","ESCLAR.")) -> CONST.
B32: =IF(CALC!$BJ$11="","",7) -> 7 | D32: =IF(CALC!$BJ$11="",IF(7=1,"✓ Nenhum prazo pendente",""),INDEX(rEmpresa,CALC!$BJ$11)) -> Posto Real | L32: =IF(CALC!$BJ$11="","",INDEX(rResp,CALC!$BJ$11)) -> DIEGO RIBEIRO | R32: =IF(CALC!$BJ$11="","",INDEX(rPrazo,CALC!$BJ$11)) -> 46310 | V32: =IF(CALC!$BJ$11="","",INDEX(rDias,CALC!$BJ$11)) -> 7 | Z32: =IF(CALC!$BK$11="","",7) -> 7 | AB32: =IF(CALC!$BK$11="",IF(7=1,"Nenhuma fiscalização registrada",""),INDEX(rEmpresa,CALC!$BK$11)) -> Churrascaria Bela Vista | AJ32: =IF(CALC!$BK$11="","",INDEX(rResp,CALC!$BK$11)) -> DIEGO RIBEIRO | AP32: =IF(CALC!$BK$11="","",INDEX(rDataFisc,CALC!$BK$11)) -> 46298 | AT32: =IF(CALC!$BK$11="","",IF(INDEX(rNotif,CALC!$BK$11)="NOTIFICAÇÃO DE CONSTATAÇÃO","CONST.","ESCLAR.")) -> CONST.
B33: =IF(CALC!$BJ$12="","",8) -> 8 | D33: =IF(CALC!$BJ$12="",IF(8=1,"✓ Nenhum prazo pendente",""),INDEX(rEmpresa,CALC!$BJ$12)) -> Telecom Bela Vista | L33: =IF(CALC!$BJ$12="","",INDEX(rResp,CALC!$BJ$12)) -> BRUNO CARVALHO | R33: =IF(CALC!$BJ$12="","",INDEX(rPrazo,CALC!$BJ$12)) -> 46310 | V33: =IF(CALC!$BJ$12="","",INDEX(rDias,CALC!$BJ$12)) -> 7 | Z33: =IF(CALC!$BK$12="","",8) -> 8 | AB33: =IF(CALC!$BK$12="",IF(8=1,"Nenhuma fiscalização registrada",""),INDEX(rEmpresa,CALC!$BK$12)) -> Studio Fitness Vitória | AJ33: =IF(CALC!$BK$12="","",INDEX(rResp,CALC!$BK$12)) -> DIEGO RIBEIRO | AP33: =IF(CALC!$BK$12="","",INDEX(rDataFisc,CALC!$BK$12)) -> 46297 | AT33: =IF(CALC!$BK$12="","",IF(INDEX(rNotif,CALC!$BK$12)="NOTIFICAÇÃO DE CONSTATAÇÃO","CONST.","ESCLAR.")) -> ESCLAR.
B34: =IF(CALC!$BJ$13="","",9) -> 9 | D34: =IF(CALC!$BJ$13="",IF(9=1,"✓ Nenhum prazo pendente",""),INDEX(rEmpresa,CALC!$BJ$13)) -> Studio Fitness Vitória | L34: =IF(CALC!$BJ$13="","",INDEX(rResp,CALC!$BJ$13)) -> DIEGO RIBEIRO | R34: =IF(CALC!$BJ$13="","",INDEX(rPrazo,CALC!$BJ$13)) -> 46312 | V34: =IF(CALC!$BJ$13="","",INDEX(rDias,CALC!$BJ$13)) -> 9 | Z34: =IF(CALC!$BK$13="","",9) -> 9 | AB34: =IF(CALC!$BK$13="",IF(9=1,"Nenhuma fiscalização registrada",""),INDEX(rEmpresa,CALC!$BK$13)) -> Farmácia Horizonte | AJ34: =IF(CALC!$BK$13="","",INDEX(rResp,CALC!$BK$13)) -> CARLA MENDES | AP34: =IF(CALC!$BK$13="","",INDEX(rDataFisc,CALC!$BK$13)) -> 46296 | AT34: =IF(CALC!$BK$13="","",IF(INDEX(rNotif,CALC!$BK$13)="NOTIFICAÇÃO DE CONSTATAÇÃO","CONST.","ESCLAR.")) -> CONST.
B35: =IF(CALC!$BJ$14="","",10) -> 10 | D35: =IF(CALC!$BJ$14="",IF(10=1,"✓ Nenhum prazo pendente",""),INDEX(rEmpresa,CALC!$BJ$14)) -> Financeira São Jorge Ltda | L35: =IF(CALC!$BJ$14="","",INDEX(rResp,CALC!$BJ$14)) -> GABRIELA NUNES | R35: =IF(CALC!$BJ$14="","",INDEX(rPrazo,CALC!$BJ$14)) -> 46312 | V35: =IF(CALC!$BJ$14="","",INDEX(rDias,CALC!$BJ$14)) -> 9 | Z35: =IF(CALC!$BK$14="","",10) -> 10 | AB35: =IF(CALC!$BK$14="",IF(10=1,"Nenhuma fiscalização registrada",""),INDEX(rEmpresa,CALC!$BK$14)) -> Concessionária Avenida | AJ35: =IF(CALC!$BK$14="","",INDEX(rResp,CALC!$BK$14)) -> CARLA MENDES | AP35: =IF(CALC!$BK$14="","",INDEX(rDataFisc,CALC!$BK$14)) -> 46296 | AT35: =IF(CALC!$BK$14="","",IF(INDEX(rNotif,CALC!$BK$14)="NOTIFICAÇÃO DE CONSTATAÇÃO","CONST.","ESCLAR.")) -> ESCLAR.
B37: CARGA DE TRABALHO POR RESPONSÁVEL (EQUIPE) | Z37: DISTRIBUIÇÃO POR RAMO DE ATIVIDADE
B39: RESPONSÁVEL | I39: TOTAL | L39: PRAZO | O39: DECISÃO | R39: EM BREVE | U39: % EQUIPE | Z39: RAMO | AG39: TOTAL | AJ39: CONST. | AM39: ESCLAR. | AP39: PRAZO | AS39: % TOTAL
B40: =CALC!AF6 -> DIEGO RIBEIRO | I40: =CALC!AG6 -> 24 | L40: =CALC!AH6 -> 10 | O40: =CALC!AI6 -> 14 | R40: =CALC!AK6 -> 4 | U40: =CALC!AL6 -> 0.25 | Z40: =CALC!AW6 -> LOJA | AG40: =CALC!AX6 -> 14 | AJ40: =CALC!AY6 -> 7 | AM40: =CALC!AZ6 -> 7 | AP40: =CALC!BA6 -> 6 | AS40: =CALC!BB6 -> 0.14583333
B41: =CALC!AF7 -> BRUNO CARVALHO | I41: =CALC!AG7 -> 16 | L41: =CALC!AH7 -> 7 | O41: =CALC!AI7 -> 9 | R41: =CALC!AK7 -> 0 | U41: =CALC!AL7 -> 0.16666667 | Z41: =CALC!AW7 -> SAÚDE | AG41: =CALC!AX7 -> 14 | AJ41: =CALC!AY7 -> 10 | AM41: =CALC!AZ7 -> 4 | AP41: =CALC!BA7 -> 3 | AS41: =CALC!BB7 -> 0.14583333
B42: =CALC!AF8 -> CARLA MENDES | I42: =CALC!AG8 -> 15 | L42: =CALC!AH8 -> 3 | O42: =CALC!AI8 -> 12 | R42: =CALC!AK8 -> 2 | U42: =CALC!AL8 -> 0.15625 | Z42: =CALC!AW8 -> RESTAURANTE | AG42: =CALC!AX8 -> 11 | AJ42: =CALC!AY8 -> 9 | AM42: =CALC!AZ8 -> 2 | AP42: =CALC!BA8 -> 2 | AS42: =CALC!BB8 -> 0.11458333
B43: =CALC!AF9 -> EDUARDA LIMA | I43: =CALC!AG9 -> 13 | L43: =CALC!AH9 -> 4 | O43: =CALC!AI9 -> 9 | R43: =CALC!AK9 -> 0 | U43: =CALC!AL9 -> 0.13541667 | Z43: =CALC!AW9 -> SUPERMERCADO | AG43: =CALC!AX9 -> 10 | AJ43: =CALC!AY9 -> 6 | AM43: =CALC!AZ9 -> 4 | AP43: =CALC!BA9 -> 2 | AS43: =CALC!BB9 -> 0.10416667
B44: =CALC!AF10 -> ANA PAULA SOUZA | I44: =CALC!AG10 -> 10 | L44: =CALC!AH10 -> 2 | O44: =CALC!AI10 -> 8 | R44: =CALC!AK10 -> 0 | U44: =CALC!AL10 -> 0.10416667 | Z44: =CALC!AW10 -> POSTO DE COMBUSTÍVEL | AG44: =CALC!AX10 -> 8 | AJ44: =CALC!AY10 -> 4 | AM44: =CALC!AZ10 -> 4 | AP44: =CALC!BA10 -> 2 | AS44: =CALC!BB10 -> 0.083333333
B45: =CALC!AF11 -> FELIPE ARAÚJO | I45: =CALC!AG11 -> 8 | L45: =CALC!AH11 -> 1 | O45: =CALC!AI11 -> 7 | R45: =CALC!AK11 -> 0 | U45: =CALC!AL11 -> 0.083333333 | Z45: =CALC!AW11 -> BANCO | AG45: =CALC!AX11 -> 8 | AJ45: =CALC!AY11 -> 5 | AM45: =CALC!AZ11 -> 3 | AP45: =CALC!BA11 -> 2 | AS45: =CALC!BB11 -> 0.083333333
B46: =CALC!AF12 -> GABRIELA NUNES | I46: =CALC!AG12 -> 7 | L46: =CALC!AH12 -> 2 | O46: =CALC!AI12 -> 5 | R46: =CALC!AK12 -> 0 | U46: =CALC!AL12 -> 0.072916667 | Z46: =CALC!AW12 -> ACADEMIA | AG46: =CALC!AX12 -> 6 | AJ46: =CALC!AY12 -> 5 | AM46: =CALC!AZ12 -> 1 | AP46: =CALC!BA12 -> 2 | AS46: =CALC!BB12 -> 0.0625
B47: =CALC!AF13 -> HENRIQUE COSTA | I47: =CALC!AG13 -> 3 | L47: =CALC!AH13 -> 0 | O47: =CALC!AI13 -> 3 | R47: =CALC!AK13 -> 0 | U47: =CALC!AL13 -> 0.03125 | Z47: =CALC!AW13 -> FARMÁCIA | AG47: =CALC!AX13 -> 6 | AJ47: =CALC!AY13 -> 6 | AM47: =CALC!AZ13 -> 0 | AP47: =CALC!BA13 -> 3 | AS47: =CALC!BB13 -> 0.0625
B48: =CALC!AF14 | I48: =CALC!AG14 | L48: =CALC!AH14 | O48: =CALC!AI14 | R48: =CALC!AK14 | U48: =CALC!AL14 | Z48: =CALC!AW14 -> ESCOLA | AG48: =CALC!AX14 -> 6 | AJ48: =CALC!AY14 -> 3 | AM48: =CALC!AZ14 -> 3 | AP48: =CALC!BA14 -> 2 | AS48: =CALC!BB14 -> 0.0625
B49: =CALC!AF15 | I49: =CALC!AG15 | L49: =CALC!AH15 | O49: =CALC!AI15 | R49: =CALC!AK15 | U49: =CALC!AL15 | Z49: =CALC!AW15 -> CONCESSIONÁRIA | AG49: =CALC!AX15 -> 6 | AJ49: =CALC!AY15 -> 3 | AM49: =CALC!AZ15 -> 3 | AP49: =CALC!BA15 -> 2 | AS49: =CALC!BB15 -> 0.0625
B51: ="EVOLUÇÃO MENSAL — ANO "&FiltroAno -> EVOLUÇÃO MENSAL — ANO 2026
B53: INDICADOR | J53: JAN | M53: FEV | P53: MAR | S53: ABR | V53: MAI | Y53: JUN | AB53: JUL | AE53: AGO | AH53: SET | AK53: OUT | AN53: NOV | AQ53: DEZ | AT53: ANO
B54: Fiscalizações | J54: =CALC!N6 -> 1 | M54: =CALC!N7 -> 3 | P54: =CALC!N8 -> 4 | S54: =CALC!N9 -> 4 | V54: =CALC!N10 -> 13 | Y54: =CALC!N11 -> 9 | AB54: =CALC!N12 -> 16 | AE54: =CALC!N13 -> 13 | AH54: =CALC!N14 -> 23 | AK54: =CALC!N15 -> 10 | AN54: =CALC!N16 -> 0 | AQ54: =CALC!N17 -> 0 | AT54: =SUM(CALC!N6:N17) -> 96
B55: Notif. Constatação | J55: =CALC!O6 -> 1 | M55: =CALC!O7 -> 3 | P55: =CALC!O8 -> 4 | S55: =CALC!O9 -> 2 | V55: =CALC!O10 -> 9 | Y55: =CALC!O11 -> 6 | AB55: =CALC!O12 -> 11 | AE55: =CALC!O13 -> 7 | AH55: =CALC!O14 -> 15 | AK55: =CALC!O15 -> 4 | AN55: =CALC!O16 -> 0 | AQ55: =CALC!O17 -> 0 | AT55: =SUM(CALC!O6:O17) -> 62
B56: Notif. Esclarecimento | J56: =CALC!P6 -> 0 | M56: =CALC!P7 -> 0 | P56: =CALC!P8 -> 0 | S56: =CALC!P9 -> 2 | V56: =CALC!P10 -> 4 | Y56: =CALC!P11 -> 3 | AB56: =CALC!P12 -> 5 | AE56: =CALC!P13 -> 6 | AH56: =CALC!P14 -> 8 | AK56: =CALC!P15 -> 6 | AN56: =CALC!P16 -> 0 | AQ56: =CALC!P17 -> 0 | AT56: =SUM(CALC!P6:P17) -> 34
...

Sheet GRÁFICOS
B2: DASHBOARD ANALÍTICO | AF2: FILTROS ATIVOS (definidos no PAINEL)
AF3: ="Responsável: "&IF(FiltroResp="","TODOS",FiltroResp) -> Responsável: TODOS
B4: Gráficos de acompanhamento do fluxo de notificações | AF4: ="Ano de referência: "&FiltroAno -> Ano de referência: 2026
B7: TOTAL | F7: =PAINEL!B13 -> 96 | J7: PRAZO D.P | N7: =PAINEL!J13 -> 29 | R7: DECISÃO D.P | V7: =PAINEL!R13 -> 67 | Z7: NO PRAZO | AD7: =PAINEL!Z13 -> 6 | AH7: EM BREVE | AL7: =PAINEL!AH13 -> 6 | AP7: NO MÊS | AT7: =PAINEL!AP13 -> 10
AN8: ◂ VOLTAR AO PAINEL

Sheet PROCESSOS
A1: CONTROLE DE PROCESSOS — FLUXO DE NOTIFICAÇÕES
A2: ="Base oficial de registros • "&COUNTA(rEmpresa)&" processo(s) cadastrado(s) • Colunas A–K e P: preenchimento manual | Colunas L–O (dourado): cálculo automático" -> Base oficial de registros • 96 processo(s) cadastrado(s) • Colunas A–K e P: preenchimento manual | Colunas L–O (dourado): cálculo automático
A4: N° | B4: EMPRESA | C4: RAMO | D4: DATA DA FISCALIZAÇÃO | E4: NOTIFICAÇÃO | F4: TIPO | G4: STATUS | H4: RESPONSÁVEL | I4: N° NOTIFICAÇÃO | J4: PROCESSO ORIGEM | K4: DATA P. ORIGEM | L4: PRAZO FINAL | M4: DIAS RESTANTES | N4: SITUAÇÃO DO PRAZO | O4: DIAS DESDE A FISCALIZAÇÃO | P4: OBSERVAÇÕES
A5: 1 | B5: Laboratório Atlântico Ltda | C5: SAÚDE | D5: 46042 | E5: NOTIFICAÇÃO DE CONSTATAÇÃO | F5: PRESENCIAL | G5: PRAZO D.P | H5: DIEGO RIBEIRO | I5: 0587/2026 | J5: 2026.052547/07 | K5: 46032 | L5: =IF(OR(D5="",E5=""),"",D5+IF(E5="NOTIFICAÇÃO DE CONSTATAÇÃO",PrazoConst,PrazoEsc)) -> 46052 | M5: =IF(L5="","",L5-TODAY()) -> -251 | N5: =IF(B5="","",IF(G5="DECISÃO D.P","EM DECISÃO",IF(G5="","SEM STATUS",IF(M5="","SEM DATA",IF(M5<0,"VENCIDO",IF(M5<=DiasAlerta,"VENCE EM BREVE","NO PRAZO")))))) -> VENCIDO | O5: =IF(D5="","",TODAY()-D5) -> 261 | P5: Registro de exemplo — os dados de exemplo podem ser apagados (colunas A–K e P).
A6: 2 | B6: Boutique Planalto | C6: LOJA | D6: 46057 | E6: NOTIFICAÇÃO DE CONSTATAÇÃO | F6: PRESENCIAL | G6: DECISÃO D.P | H6: FELIPE ARAÚJO | I6: 0049/2026 | J6: 2025.024777/07 | K6: 46000 | L6: =IF(OR(D6="",E6=""),"",D6+IF(E6="NOTIFICAÇÃO DE CONSTATAÇÃO",PrazoConst,PrazoEsc)) -> 46067 | M6: =IF(L6="","",L6-TODAY()) -> -236 | N6: =IF(B6="","",IF(G6="DECISÃO D.P","EM DECISÃO",IF(G6="","SEM STATUS",IF(M6="","SEM DATA",IF(M6<0,"VENCIDO",IF(M6<=DiasAlerta,"VENCE EM BREVE","NO PRAZO")))))) -> EM DECISÃO | O6: =IF(D6="","",TODAY()-D6) -> 246
A7: 3 | B7: Mercado Bom Preço | C7: SUPERMERCADO | D7: 46071 | E7: NOTIFICAÇÃO DE CONSTATAÇÃO | F7: PRESENCIAL | G7: DECISÃO D.P | H7: GABRIELA NUNES | I7: 0130/2026 | J7: 2025.028692/13 | K7: 46001 | L7: =IF(OR(D7="",E7=""),"",D7+IF(E7="NOTIFICAÇÃO DE CONSTATAÇÃO",PrazoConst,PrazoEsc)) -> 46081 | M7: =IF(L7="","",L7-TODAY()) -> -222 | N7: =IF(B7="","",IF(G7="DECISÃO D.P","EM DECISÃO",IF(G7="","SEM STATUS",IF(M7="","SEM DATA",IF(M7<0,"VENCIDO",IF(M7<=DiasAlerta,"VENCE EM BREVE","NO PRAZO")))))) -> EM DECISÃO | O7: =IF(D7="","",TODAY()-D7) -> 232
A8: 4 | B8: Laboratório Horizonte | C8: SAÚDE | D8: 46076 | E8: NOTIFICAÇÃO DE CONSTATAÇÃO | F8: ELETRÔNICA | G8: DECISÃO D.P | H8: DIEGO RIBEIRO | I8: 0492/2026 | J8: 2025.047616/13 | K8: 46017 | L8: =IF(OR(D8="",E8=""),"",D8+IF(E8="NOTIFICAÇÃO DE CONSTATAÇÃO",PrazoConst,PrazoEsc)) -> 46086 | M8: =IF(L8="","",L8-TODAY()) -> -217 | N8: =IF(B8="","",IF(G8="DECISÃO D.P","EM DECISÃO",IF(G8="","SEM STATUS",IF(M8="","SEM DATA",IF(M8<0,"VENCIDO",IF(M8<=DiasAlerta,"VENCE EM BREVE","NO PRAZO")))))) -> EM DECISÃO | O8: =IF(D8="","",TODAY()-D8) -> 227
A9: 5 | B9: Posto Primavera | C9: POSTO DE COMBUSTÍVEL | D9: 46082 | E9: NOTIFICAÇÃO DE CONSTATAÇÃO | F9: PRESENCIAL | G9: DECISÃO D.P | H9: GABRIELA NUNES | I9: 0650/2026 | J9: 2026.038632/12 | K9: 46043 | L9: =IF(OR(D9="",E9=""),"",D9+IF(E9="NOTIFICAÇÃO DE CONSTATAÇÃO",PrazoConst,PrazoEsc)) -> 46092 | M9: =IF(L9="","",L9-TODAY()) -> -211 | N9: =IF(B9="","",IF(G9="DECISÃO D.P","EM DECISÃO",IF(G9="","SEM STATUS",IF(M9="","SEM DATA",IF(M9<0,"VENCIDO",IF(M9<=DiasAlerta,"VENCE EM BREVE","NO PRAZO")))))) -> EM DECISÃO | O9: =IF(D9="","",TODAY()-D9) -> 221
A10: 6 | B10: Colégio Vitória | C10: ESCOLA | D10: 46093 | E10: NOTIFICAÇÃO DE CONSTATAÇÃO | F10: ELETRÔNICA | G10: PRAZO D.P | H10: EDUARDA LIMA | I10: 0359/2026 | J10: 2026.099466/07 | K10: 46044 | L10: =IF(OR(D10="",E10=""),"",D10+IF(E10="NOTIFICAÇÃO DE CONSTATAÇÃO",PrazoConst,PrazoEsc)) -> 46103 | M10: =IF(L10="","",L10-TODAY()) -> -200 | N10: =IF(B10="","",IF(G10="DECISÃO D.P","EM DECISÃO",IF(G10="","SEM STATUS",IF(M10="","SEM DATA",IF(M10<0,"VENCIDO",IF(M10<=DiasAlerta,"VENCE EM BREVE","NO PRAZO")))))) -> VENCIDO | O10: =IF(D10="","",TODAY()-D10) -> 210
A11: 7 | B11: Banco Litoral | C11: BANCO | D11: 46101 | E11: NOTIFICAÇÃO DE CONSTATAÇÃO | F11: PRESENCIAL | G11: DECISÃO D.P | H11: DIEGO RIBEIRO | I11: 0152/2026 | J11: 2026.034037/01 | K11: 46044 | L11: =IF(OR(D11="",E11=""),"",D11+IF(E11="NOTIFICAÇÃO DE CONSTATAÇÃO",PrazoConst,PrazoEsc)) -> 46111 | M11: =IF(L11="","",L11-TODAY()) -> -192 | N11: =IF(B11="","",IF(G11="DECISÃO D.P","EM DECISÃO",IF(G11="","SEM STATUS",IF(M11="","SEM DATA",IF(M11<0,"VENCIDO",IF(M11<=DiasAlerta,"VENCE EM BREVE","NO PRAZO")))))) -> EM DECISÃO | O11: =IF(D11="","",TODAY()-D11) -> 202
A12: 8 | B12: Posto Nova Era | C12: POSTO DE COMBUSTÍVEL | D12: 46110 | E12: NOTIFICAÇÃO DE CONSTATAÇÃO | F12: PRESENCIAL | G12: PRAZO D.P | H12: BRUNO CARVALHO | I12: 0863/2026 | J12: 2026.094405/09 | K12: 46025 | L12: =IF(OR(D12="",E12=""),"",D12+IF(E12="NOTIFICAÇÃO DE CONSTATAÇÃO",PrazoConst,PrazoEsc)) -> 46120 | M12: =IF(L12="","",L12-TODAY()) -> -183 | N12: =IF(B12="","",IF(G12="DECISÃO D.P","EM DECISÃO",IF(G12="","SEM STATUS",IF(M12="","SEM DATA",IF(M12<0,"VENCIDO",IF(M12<=DiasAlerta,"VENCE EM BREVE","NO PRAZO")))))) -> VENCIDO | O12: =IF(D12="","",TODAY()-D12) -> 193
A13: 9 | B13: Clínica Jardim | C13: SAÚDE | D13: 46121 | E13: NOTIFICAÇÃO DE ESCLARECIMENTO | F13: PRESENCIAL | G13: DECISÃO D.P | H13: FELIPE ARAÚJO | I13: 0574/2026 | J13: 2026.048054/08 | K13: 46088 | L13: =IF(OR(D13="",E13=""),"",D13+IF(E13="NOTIFICAÇÃO DE CONSTATAÇÃO",PrazoConst,PrazoEsc)) -> 46136 | M13: =IF(L13="","",L13-TODAY()) -> -167 | N13: =IF(B13="","",IF(G13="DECISÃO D.P","EM DECISÃO",IF(G13="","SEM STATUS",IF(M13="","SEM DATA",IF(M13<0,"VENCIDO",IF(M13<=DiasAlerta,"VENCE EM BREVE","NO PRAZO")))))) -> EM DECISÃO | O13: =IF(D13="","",TODAY()-D13) -> 182
A14: 10 | B14: Auto Posto Primavera Ltda | C14: POSTO DE COMBUSTÍVEL | D14: 46124 | E14: NOTIFICAÇÃO DE ESCLARECIMENTO | F14: PRESENCIAL | G14: DECISÃO D.P | H14: GABRIELA NUNES | I14: 0687/2026 | J14: 2026.004563/06 | K14: 46096 | L14: =IF(OR(D14="",E14=""),"",D14+IF(E14="NOTIFICAÇÃO DE CONSTATAÇÃO",PrazoConst,PrazoEsc)) -> 46139 | M14: =IF(L14="","",L14-TODAY()) -> -164 | N14: =IF(B14="","",IF(G14="DECISÃO D.P","EM DECISÃO",IF(G14="","SEM STATUS",IF(M14="","SEM DATA",IF(M14<0,"VENCIDO",IF(M14<=DiasAlerta,"VENCE EM BREVE","NO PRAZO")))))) -> EM DECISÃO | O14: =IF(D14="","",TODAY()-D14) -> 179
A15: 11 | B15: Posto Boa Esperança 24h | C15: POSTO DE COMBUSTÍVEL | D15: 46124 | E15: NOTIFICAÇÃO DE CONSTATAÇÃO | F15: PRESENCIAL | G15: DECISÃO D.P | H15: FELIPE ARAÚJO | I15: 0938/2026 | J15: 2026.039920/13 | K15: 46104 | L15: =IF(OR(D15="",E15=""),"",D15+IF(E15="NOTIFICAÇÃO DE CONSTATAÇÃO",PrazoConst,PrazoEsc)) -> 46134 | M15: =IF(L15="","",L15-TODAY()) -> -169 | N15: =IF(B15="","",IF(G15="DECISÃO D.P","EM DECISÃO",IF(G15="","SEM STATUS",IF(M15="","SEM DATA",IF(M15<0,"VENCIDO",IF(M15<=DiasAlerta,"VENCE EM BREVE","NO PRAZO")))))) -> EM DECISÃO | O15: =IF(D15="","",TODAY()-D15) -> 179
A16: 12 | B16: Conecta Central | C16: TELEFONIA | D16: 46137 | E16: NOTIFICAÇÃO DE CONSTATAÇÃO | F16: ELETRÔNICA | G16: DECISÃO D.P | H16: EDUARDA LIMA | I16: 0553/2026 | J16: 2026.020921/10 | K16: 46108 | L16: =IF(OR(D16="",E16=""),"",D16+IF(E16="NOTIFICAÇÃO DE CONSTATAÇÃO",PrazoConst,PrazoEsc)) -> 46147 | M16: =IF(L16="","",L16-TODAY()) -> -156 | N16: =IF(B16="","",IF(G16="DECISÃO D.P","EM DECISÃO",IF(G16="","SEM STATUS",IF(M16="","SEM DATA",IF(M16<0,"VENCIDO",IF(M16<=DiasAlerta,"VENCE EM BREVE","NO PRAZO")))))) -> EM DECISÃO | O16: =IF(D16="","",TODAY()-D16) -> 166
A17: 13 | B17: Posto Horizonte Ltda | C17: POSTO DE COMBUSTÍVEL | D17: 46145 | E17: NOTIFICAÇÃO DE ESCLARECIMENTO | F17: ELETRÔNICA | G17: DECISÃO D.P | H17: DIEGO RIBEIRO | I17: 0546/2026 | J17: 2026.064254/10 | K17: 46102 | L17: =IF(OR(D17="",E17=""),"",D17+IF(E17="NOTIFICAÇÃO DE CONSTATAÇÃO",PrazoConst,PrazoEsc)) -> 46160 | M17: =IF(L17="","",L17-TODAY()) -> -143 | N17: =IF(B17="","",IF(G17="DECISÃO D.P","EM DECISÃO",IF(G17="","SEM STATUS",IF(M17="","SEM DATA",IF(M17<0,"VENCIDO",IF(M17<=DiasAlerta,"VENCE EM BREVE","NO PRAZO")))))) -> EM DECISÃO | O17: =IF(D17="","",TODAY()-D17) -> 158
... A100: 96 | B100: Escola Vitória | C100: ESCOLA | D100: 46303 | E100: NOTIFICAÇÃO DE ESCLARECIMENTO | F100: PRESENCIAL | G100: DECISÃO D.P | H100: ANA PAULA SOUZA | I100: 0706/2026 | J100: 2026.034925/08 | K100: 46233 | L100: =IF(OR(D100="",E100=""),"",D100+IF(E100="NOTIFICAÇÃO DE CONSTATAÇÃO",PrazoConst,PrazoEsc)) -> 46318 | M100: =IF(L100="","",L100-TODAY()) -> 15 | N100: =IF(B100="","",IF(G100="DECISÃO D.P","EM DECISÃO",IF(G100="","SEM STATUS",IF(M100="","SEM DATA",IF(M100<0,"VENCIDO",IF(M100<=DiasAlerta,"VENCE EM BREVE","NO PRAZO")))))) -> EM DECISÃO | O100: =IF(D100="","",TODAY()-D100) -> 0
L101: =IF(OR(D101="",E101=""),"",D101+IF(E101="NOTIFICAÇÃO DE CONSTATAÇÃO",PrazoConst,PrazoEsc)) | M101: =IF(L101="","",L101-TODAY()) | N101: =IF(B101="","",IF(G101="DECISÃO D.P","EM DECISÃO",IF(G101="","SEM STATUS",IF(M101="","SEM DATA",IF(M101<0,"VENCIDO",IF(M101<=DiasAlerta,"VENCE EM BREVE","NO PRAZO")))))) | O101: =IF(D101="","",TODAY()-D101)
L102: =IF(OR(D102="",E102=""),"",D102+IF(E102="NOTIFICAÇÃO DE CONSTATAÇÃO",PrazoConst,PrazoEsc)) | M102: =IF(L102="","",L102-TODAY()) | N102: =IF(B102="","",IF(G102="DECISÃO D.P","EM DECISÃO",IF(G102="","SEM STATUS",IF(M102="","SEM DATA",IF(M102<0,"VENCIDO",IF(M102<=DiasAlerta,"VENCE EM BREVE","NO PRAZO")))))) | O102: =IF(D102="","",TODAY()-D102)
L103: =IF(OR(D103="",E103=""),"",D103+IF(E103="NOTIFICAÇÃO DE CONSTATAÇÃO",PrazoConst,PrazoEsc)) | M103: =IF(L103="","",L103-TODAY()) | N103: =IF(B103="","",IF(G103="DECISÃO D.P","EM DECISÃO",IF(G103="","SEM STATUS",IF(M103="","SEM DATA",IF(M103<0,"VENCIDO",IF(M103<=DiasAlerta,"VENCE EM BREVE","NO PRAZO")))))) | O103: =IF(D103="","",TODAY()-D103)
L104: =IF(OR(D104="",E104=""),"",D104+IF(E104="NOTIFICAÇÃO DE CONSTATAÇÃO",PrazoConst,PrazoEsc)) | M104: =IF(L104="","",L104-TODAY()) | N104: =IF(B104="","",IF(G104="DECISÃO D.P","EM DECISÃO",IF(G104="","SEM STATUS",IF(M104="","SEM DATA",IF(M104<0,"VENCIDO",IF(M104<=DiasAlerta,"VENCE EM BREVE","NO PRAZO")))))) | O104: =IF(D104="","",TODAY()-D104)
L105: =IF(OR(D105="",E105=""),"",D105+IF(E105="NOTIFICAÇÃO DE CONSTATAÇÃO",PrazoConst,PrazoEsc)) | M105: =IF(L105="","",L105-TODAY()) | N105: =IF(B105="","",IF(G105="DECISÃO D.P","EM DECISÃO",IF(G105="","SEM STATUS",IF(M105="","SEM DATA",IF(M105<0,"VENCIDO",IF(M105<=DiasAlerta,"VENCE EM BREVE","NO PRAZO")))))) | O105: =IF(D105="","",TODAY()-D105)
L106: =IF(OR(D106="",E106=""),"",D106+IF(E106="NOTIFICAÇÃO DE CONSTATAÇÃO",PrazoConst,PrazoEsc)) | M106: =IF(L106="","",L106-TODAY()) | N106: =IF(B106="","",IF(G106="DECISÃO D.P","EM DECISÃO",IF(G106="","SEM STATUS",IF(M106="","SEM DATA",IF(M106<0,"VENCIDO",IF(M106<=DiasAlerta,"VENCE EM BREVE","NO PRAZO")))))) | O106: =IF(D106="","",TODAY()-D106)
L107: =IF(OR(D107="",E107=""),"",D107+IF(E107="NOTIFICAÇÃO DE CONSTATAÇÃO",PrazoConst,PrazoEsc)) | M107: =IF(L107="","",L107-TODAY()) | N107: =IF(B107="","",IF(G107="DECISÃO D.P","EM DECISÃO",IF(G107="","SEM STATUS",IF(M107="","SEM DATA",IF(M107<0,"VENCIDO",IF(M107<=DiasAlerta,"VENCE EM BREVE","NO PRAZO")))))) | O107: =IF(D107="","",TODAY()-D107)
L108: =IF(OR(D108="",E108=""),"",D108+IF(E108="NOTIFICAÇÃO DE CONSTATAÇÃO",PrazoConst,PrazoEsc)) | M108: =IF(L108="","",L108-TODAY()) | N108: =IF(B108="","",IF(G108="DECISÃO D.P","EM DECISÃO",IF(G108="","SEM STATUS",IF(M108="","SEM DATA",IF(M108<0,"VENCIDO",IF(M108<=DiasAlerta,"VENCE EM BREVE","NO PRAZO")))))) | O108: =IF(D108="","",TODAY()-D108)
L109: =IF(OR(D109="",E109=""),"",D109+IF(E109="NOTIFICAÇÃO DE CONSTATAÇÃO",PrazoConst,PrazoEsc)) | M109: =IF(L109="","",L109-TODAY()) | N109: =IF(B109="","",IF(G109="DECISÃO D.P","EM DECISÃO",IF(G109="","SEM STATUS",IF(M109="","SEM DATA",IF(M109<0,"VENCIDO",IF(M109<=DiasAlerta,"VENCE EM BREVE","NO PRAZO")))))) | O109: =IF(D109="","",TODAY()-D109)
L110: =IF(OR(D110="",E110=""),"",D110+IF(E110="NOTIFICAÇÃO DE CONSTATAÇÃO",PrazoConst,PrazoEsc)) | M110: =IF(L110="","",L110-TODAY()) | N110: =IF(B110="","",IF(G110="DECISÃO D.P","EM DECISÃO",IF(G110="","SEM STATUS",IF(M110="","SEM DATA",IF(M110<0,"VENCIDO",IF(M110<=DiasAlerta,"VENCE EM BREVE","NO PRAZO")))))) | O110: =IF(D110="","",TODAY()-D110)
L111: =IF(OR(D111="",E111=""),"",D111+IF(E111="NOTIFICAÇÃO DE CONSTATAÇÃO",PrazoConst,PrazoEsc)) | M111: =IF(L111="","",L111-TODAY()) | N111: =IF(B111="","",IF(G111="DECISÃO D.P","EM DECISÃO",IF(G111="","SEM STATUS",IF(M111="","SEM DATA",IF(M111<0,"VENCIDO",IF(M111<=DiasAlerta,"VENCE EM BREVE","NO PRAZO")))))) | O111: =IF(D111="","",TODAY()-D111)
L112: =IF(OR(D112="",E112=""),"",D112+IF(E112="NOTIFICAÇÃO DE CONSTATAÇÃO",PrazoConst,PrazoEsc)) | M112: =IF(L112="","",L112-TODAY()) | N112: =IF(B112="","",IF(G112="DECISÃO D.P","EM DECISÃO",IF(G112="","SEM STATUS",IF(M112="","SEM DATA",IF(M112<0,"VENCIDO",IF(M112<=DiasAlerta,"VENCE EM BREVE","NO PRAZO")))))) | O112: =IF(D112="","",TODAY()-D112)
... L1004: =IF(OR(D1004="",E1004=""),"",D1004+IF(E1004="NOTIFICAÇÃO DE CONSTATAÇÃO",PrazoConst,PrazoEsc)) | M1004: =IF(L1004="","",L1004-TODAY()) | N1004: =IF(B1004="","",IF(G1004="DECISÃO D.P","EM DECISÃO",IF(G1004="","SEM STATUS",IF(M1004="","SEM DATA",IF(M1004<0,"VENCIDO",IF(M1004<=DiasAlerta,"VENCE EM BREVE","NO PRAZO")))))) | O1004: =IF(D1004="","",TODAY()-D1004)

Sheet CADASTROS
B1: CADASTROS E PARÂMETROS
B2: Listas que alimentam os menus suspensos e regras de prazo usadas em todo o arquivo
B5: RAMOS DE ATIVIDADE | D5: RESPONSÁVEIS | F5: NOTIFICAÇÃO (fixo) | H5: TIPO (fixo) | J5: STATUS (fixo) | L5: PARÂMETROS DE PRAZO E METAS | M5: VALOR | O5: OBSERVAÇÃO
B6: LOJA | D6: ANA PAULA SOUZA | F6: NOTIFICAÇÃO DE CONSTATAÇÃO | H6: PRESENCIAL | J6: PRAZO D.P | L6: Prazo de resposta — Notificação de Constatação (dias corridos) | M6: 10 | O6: Premissa editável: prazo contado a partir da DATA DA FISCALIZAÇÃO.
B7: POSTO DE COMBUSTÍVEL | D7: BRUNO CARVALHO | F7: NOTIFICAÇÃO DE ESCLARECIMENTO | H7: ELETRÔNICA | J7: DECISÃO D.P | L7: Prazo de resposta — Notificação de Esclarecimento (dias corridos) | M7: 15 | O7: Premissa editável: prazo contado a partir da DATA DA FISCALIZAÇÃO.
B8: SAÚDE | D8: CARLA MENDES | L8: Antecedência para alerta 'VENCE EM BREVE' (dias) | M8: 5 | O8: Processos com prazo a vencer em até N dias recebem alerta.
B9: ACADEMIA | D9: DIEGO RIBEIRO | L9: Meta mensal de fiscalizações | M9: 12 | O9: Usada no painel e nos gráficos de atingimento de meta.
B10: SUPERMERCADO | D10: EDUARDA LIMA
B11: RESTAURANTE | D11: FELIPE ARAÚJO | L11: Células em dourado claro são editáveis.
B12: FARMÁCIA | D12: GABRIELA NUNES
B13: BANCO | D13: HENRIQUE COSTA
B14: ESCOLA
B15: TELEFONIA
B16: CONCESSIONÁRIA
B17: OUTROS
D22: ↑ Inclua novos responsáveis nas linhas em branco (até 15).
B37: ↑ Inclua novos ramos nas linhas em branco (até 30).

Sheet INSTRUÇÕES
A1: GUIA DE USO DA PLANILHA
A2: Como registrar processos e interpretar os indicadores
B5: 1. ESTRUTURA DAS ABAS
B6: ABA | C6: FINALIDADE | D6: DETALHES
B7: PAINEL | C7: Visão diária do Gerente | D7: Indicadores, alertas de prazo, carga da equipe, ramos e evolução mensal. Filtros por responsável e ano.
B8: GRÁFICOS | C8: Dashboard analítico | D8: 8 gráficos dinâmicos que acompanham os filtros definidos no PAINEL.
B9: PROCESSOS | C9: Base de registros | D9: Única aba onde os processos são cadastrados (até 1.000 linhas formatadas e validadas).
B10: CADASTROS | C10: Listas e parâmetros | D10: Ramos, responsáveis, prazos de resposta (dias), antecedência de alerta e meta mensal.
B11: INSTRUÇÕES | C11: Este guia | D11: Regras de preenchimento e definição de cada indicador.
B13: 2. COMO CADASTRAR UM PROCESSO (aba PROCESSOS)
B14: 1) Vá até a primeira linha vazia e informe o N° (inteiro, sequencial e sem repetição).
B15: 2) Preencha EMPRESA (nome fantasia — texto livre) e selecione o RAMO no menu suspenso.
B16: 3) Digite a DATA DA FISCALIZAÇÃO no formato DD/MM/AAAA.
B17: 4) Selecione NOTIFICAÇÃO, TIPO, STATUS e RESPONSÁVEL nos menus suspensos.
B18: 5) Informe N° NOTIFICAÇÃO, PROCESSO ORIGEM e DATA P. ORIGEM.
B19: 6) As colunas PRAZO FINAL, DIAS RESTANTES, SITUAÇÃO DO PRAZO e DIAS DESDE A FISCALIZAÇÃO são automáticas — não digite nelas.
B20: 7) Ao concluir a fase de prazo, altere o STATUS para DECISÃO D.P: o processo sai dos alertas de vencimento.
B22: 3. REGRAS DE VALIDAÇÃO (bloqueios de digitação)
B23: COLUNA | C23: TIPO DE CAMPO | D23: REGRA APLICADA
B24: N° | C24: Número inteiro | D24: Aceita apenas inteiros positivos; letras, decimais e números repetidos são bloqueados.
B25: EMPRESA | C25: Texto livre | D25: Sem bloqueio (aceita letras e números).
B26: RAMO | C26: Menu suspenso | D26: Lista da aba CADASTROS (pode ser ampliada).
B27: DATA DA FISCALIZAÇÃO | C27: Data | D27: Somente datas reais entre 01/01/2000 e 31/12/2099; textos são bloqueados.
B28: NOTIFICAÇÃO | C28: Menu suspenso | D28: NOTIFICAÇÃO DE CONSTATAÇÃO | NOTIFICAÇÃO DE ESCLARECIMENTO.
B29: TIPO | C29: Menu suspenso | D29: PRESENCIAL | ELETRÔNICA.
B30: STATUS | C30: Menu suspenso | D30: DECISÃO D.P | PRAZO D.P.
B31: RESPONSÁVEL | C31: Menu suspenso | D31: Lista da aba CADASTROS (pode ser ampliada).
B32: N° NOTIFICAÇÃO | C32: Números e "/" | D32: Qualquer outro caractere é bloqueado. Ex.: 0123/2026.
B33: PROCESSO ORIGEM | C33: Números, "/", "." e "-" | D33: Qualquer outro caractere é bloqueado. Ex.: 2026.004512-7/01.
B34: DATA P. ORIGEM | C34: Data | D34: Somente datas reais entre 01/01/2000 e 31/12/2099; textos são bloqueados.
B35: OBSERVAÇÕES | C35: Texto livre | D35: Campo opcional para anotações.
B37: 4. DEFINIÇÃO DOS INDICADORES
B38: INDICADOR | C38: CÁLCULO | D38: LEITURA
B39: Prazo final | C39: Data da fiscalização + prazo (CADASTROS) | D39: Constatação: 10 dias; Esclarecimento: 15 dias (premissas editáveis).
B40: Vence em breve | C40: Prazo final em até N dias (CADASTROS) | D40: Alerta preventivo para a equipe.
B41: Em decisão | C41: STATUS = DECISÃO D.P | D41: Processo aguardando decisão; fora do controle de prazo.
B42: Idade média | C42: Média de dias desde a fiscalização | D42: Mede o tempo de permanência dos processos na base.
B43: Atingimento da meta | C43: Fiscalizações do mês ÷ meta mensal | D43: Meta definida na aba CADASTROS.
B44: % equipe | C44: Processos do responsável ÷ total | D44: Equilíbrio da distribuição de carga.
B46: 5. OBSERVAÇÕES
...

Sheet CALC
A1: CÁLCULOS AUXILIARES — não editar (alimenta PAINEL e GRÁFICOS)
B3: Critério responsável | C3: =IF(OR(FiltroResp="",FiltroResp="TODOS"),"<>§§",FiltroResp) -> <>§§
E4: Lista filtro resp. | G4: Anos | BF4: chave próx. | BG4: chave últ. fiscalização | BI4: k | BJ4: idx próx. | BK4: idx últ.
E5: TODOS | G5: 2024 | I5: STATUS | L5: Nº | M5: Mês | N5: Fiscalizações | O5: Constatação | P5: Esclarecimento | Q5: Presencial | R5: Eletrônica | S5: Meta | T5: Realizado acumulado | U5: Meta acumulada | W5: Responsável | X5: Total | Y5: Prazo D.P | Z5: Decisão D.P | AA5: No prazo | AB5: Vence breve | AC5: Score | AE5: Pos. | AF5: Responsável | AG5: Total | AH5: Prazo D.P | AI5: Decisão D.P | AJ5: No prazo | AK5: Vence breve | AL5: % equipe | AM5: idx | AO5: Ramo | AP5: Total | AQ5: Constatação | AR5: Esclarecimento | AS5: Prazo D.P | AT5: Score | AV5: Pos. | AW5: Ramo | AX5: Total | AY5: Constatação | AZ5: Esclarecimento | BA5: Prazo D.P | BB5: % | BC5: idx | BF5: =IF(AND(OR(PROCESSOS!N5="NO PRAZO",PROCESSOS!N5="VENCE EM BREVE"),OR(FiltroResp="TODOS",FiltroResp="",PROCESSOS!H5=FiltroResp)),PROCESSOS!L5+ROW()/1000000,"") | BG5: =IF(AND(PROCESSOS!B5<>"",ISNUMBER(PROCESSOS!D5),OR(FiltroResp="TODOS",FiltroResp="",PROCESSOS!H5=FiltroResp)),PROCESSOS!D5+ROW()/1000000,"") -> 46042 | BI5: 1 | BJ5: =IFERROR(MATCH(SMALL(hProx,BI5),hProx,0),"") -> 83 | BK5: =IFERROR(MATCH(LARGE(hUlt,BI5),hUlt,0),"") -> 96
E6: =IF(CADASTROS!$D$6="","",CADASTROS!$D$6) -> ANA PAULA SOUZA | G6: 2025 | I6: Prazo D.P | J6: =COUNTIFS(rEmpresa,"<>",rResp,critResp,rStatus,"PRAZO D.P") -> 29 | L6: 1 | M6: JAN | N6: =COUNTIFS(rEmpresa,"<>",rResp,critResp,rDataFisc,">="&DATE(FiltroAno,L6,1),rDataFisc,"<"&DATE(FiltroAno,L6+1,1)) -> 1 | O6: =COUNTIFS(rEmpresa,"<>",rResp,critResp,rDataFisc,">="&DATE(FiltroAno,L6,1),rDataFisc,"<"&DATE(FiltroAno,L6+1,1),rNotif,"NOTIFICAÇÃO DE CONSTATAÇÃO") -> 1 | P6: =COUNTIFS(rEmpresa,"<>",rResp,critResp,rDataFisc,">="&DATE(FiltroAno,L6,1),rDataFisc,"<"&DATE(FiltroAno,L6+1,1),rNotif,"NOTIFICAÇÃO DE ESCLARECIMENTO") -> 0 | Q6: =COUNTIFS(rEmpresa,"<>",rResp,critResp,rDataFisc,">="&DATE(FiltroAno,L6,1),rDataFisc,"<"&DATE(FiltroAno,L6+1,1),rTipo,"PRESENCIAL") -> 1 | R6: =COUNTIFS(rEmpresa,"<>",rResp,critResp,rDataFisc,">="&DATE(FiltroAno,L6,1),rDataFisc,"<"&DATE(FiltroAno,L6+1,1),rTipo,"ELETRÔNICA") -> 0 | S6: =MetaMensal -> 12 | T6: =SUM($N$6:N6) -> 1 | U6: =SUM($S$6:S6) -> 12 | W6: =IF(CADASTROS!$D$6="","",CADASTROS!$D$6) -> ANA PAULA SOUZA | X6: =IF(W6="",0,COUNTIFS(rResp,W6,rEmpresa,"<>")) -> 10 | Y6: =IF(W6="",0,COUNTIFS(rResp,W6,rEmpresa,"<>",rStatus,"PRAZO D.P")) -> 2 | Z6: =IF(W6="",0,COUNTIFS(rResp,W6,rEmpresa,"<>",rStatus,"DECISÃO D.P")) -> 8 | AA6: =IF(W6="",0,COUNTIFS(rResp,W6,rEmpresa,"<>",rSit,"NO PRAZO")) -> 0 | AB6: =IF(W6="",0,COUNTIFS(rResp,W6,rEmpresa,"<>",rSit,"VENCE EM BREVE")) -> 0 | AC6: =IF(W6="",-1,X6+(100-ROW())/1000) -> 10.094 | AE6: 1 | AF6: =IF(AM6="","",INDEX($W$6:$W$20,AM6)) -> DIEGO RIBEIRO | AG6: =IF(AM6="","",INDEX($X$6:$X$20,AM6)) -> 24 | AH6: =IF(AM6="","",INDEX($Y$6:$Y$20,AM6)) -> 10 | AI6: =IF(AM6="","",INDEX($Z$6:$Z$20,AM6)) -> 14 | AJ6: =IF(AM6="","",INDEX($AA$6:$AA$20,AM6)) -> 2 | AK6: =IF(AM6="","",INDEX($AB$6:$AB$20,AM6)) -> 4 | AL6: =IF(AM6="","",IFERROR(AG6/SUM($X$6:$X$20),0)) -> 0.25 | AM6: =IF(LARGE($AC$6:$AC$20,AE6)<0,"",MATCH(LARGE($AC$6:$AC$20,AE6),$AC$6:$AC$20,0)) -> 4 | AO6: =IF(CADASTROS!$B$6="","",CADASTROS!$B$6) -> LOJA | AP6: =IF(AO6="",0,COUNTIFS(rEmpresa,"<>",rResp,critResp,rRamo,AO6)) -> 14 | AQ6: =IF(AO6="",0,COUNTIFS(rEmpresa,"<>",rResp,critResp,rRamo,AO6,rNotif,"NOTIFICAÇÃO DE CONSTATAÇÃO")) -> 7 | AR6: =IF(AO6="",0,COUNTIFS(rEmpresa,"<>",rResp,critResp,rRamo,AO6,rNotif,"NOTIFICAÇÃO DE ESCLARECIMENTO")) -> 7 | AS6: =IF(AO6="",0,COUNTIFS(rEmpresa,"<>",rResp,critResp,rRamo,AO6,rStatus,"PRAZO D.P")) -> 6 | AT6: =IF(AO6="",-1,AP6+(100-ROW())/1000) -> 14.094 | AV6: 1 | AW6: =IF(BC6="","",INDEX($AO$6:$AO$35,BC6)) -> LOJA | AX6: =IF(BC6="","",INDEX($AP$6:$AP$35,BC6)) -> 14 | AY6: =IF(BC6="","",INDEX($AQ$6:$AQ$35,BC6)) -> 7 | AZ6: =IF(BC6="","",INDEX($AR$6:$AR$35,BC6)) -> 7 | BA6: =IF(BC6="","",INDEX($AS$6:$AS$35,BC6)) -> 6 | BB6: =IF(BC6="","",IFERROR(AX6/SUM($AP$6:$AP$35),0)) -> 0.14583333 | BC6: =IF(LARGE($AT$6:$AT$35,AV6)<0,"",MATCH(LARGE($AT$6:$AT$35,AV6),$AT$6:$AT$35,0)) -> 1 | BF6: =IF(AND(OR(PROCESSOS!N6="NO PRAZO",PROCESSOS!N6="VENCE EM BREVE"),OR(FiltroResp="TODOS",FiltroResp="",PROCESSOS!H6=FiltroResp)),PROCESSOS!L6+ROW()/1000000,"") | BG6: =IF(AND(PROCESSOS!B6<>"",ISNUMBER(PROCESSOS!D6),OR(FiltroResp="TODOS",FiltroResp="",PROCESSOS!H6=FiltroResp)),PROCESSOS!D6+ROW()/1000000,"") -> 46057 | BI6: 2 | BJ6: =IFERROR(MATCH(SMALL(hProx,BI6),hProx,0),"") -> 84 | BK6: =IFERROR(MATCH(LARGE(hUlt,BI6),hUlt,0),"") -> 95
E7: =IF(CADASTROS!$D$7="","",CADASTROS!$D$7) -> BRUNO CARVALHO | G7: 2026 | I7: Decisão D.P | J7: =COUNTIFS(rEmpresa,"<>",rResp,critResp,rStatus,"DECISÃO D.P") -> 67 | L7: 2 | M7: FEV | N7: =COUNTIFS(rEmpresa,"<>",rResp,critResp,rDataFisc,">="&DATE(FiltroAno,L7,1),rDataFisc,"<"&DATE(FiltroAno,L7+1,1)) -> 3 | O7: =COUNTIFS(rEmpresa,"<>",rResp,critResp,rDataFisc,">="&DATE(FiltroAno,L7,1),rDataFisc,"<"&DATE(FiltroAno,L7+1,1),rNotif,"NOTIFICAÇÃO DE CONSTATAÇÃO") -> 3 | P7: =COUNTIFS(rEmpresa,"<>",rResp,critResp,rDataFisc,">="&DATE(FiltroAno,L7,1),rDataFisc,"<"&DATE(FiltroAno,L7+1,1),rNotif,"NOTIFICAÇÃO DE ESCLARECIMENTO") -> 0 | Q7: =COUNTIFS(rEmpresa,"<>",rResp,critResp,rDataFisc,">="&DATE(FiltroAno,L7,1),rDataFisc,"<"&DATE(FiltroAno,L7+1,1),rTipo,"PRESENCIAL") -> 2 | R7: =COUNTIFS(rEmpresa,"<>",rResp,critResp,rDataFisc,">="&DATE(FiltroAno,L7,1),rDataFisc,"<"&DATE(FiltroAno,L7+1,1),rTipo,"ELETRÔNICA") -> 1 | S7: =MetaMensal -> 12 | T7: =SUM($N$6:N7) -> 4 | U7: =SUM($S$6:S7) -> 24 | W7: =IF(CADASTROS!$D$7="","",CADASTROS!$D$7) -> BRUNO CARVALHO | X7: =IF(W7="",0,COUNTIFS(rResp,W7,rEmpresa,"<>")) -> 16 | Y7: =IF(W7="",0,COUNTIFS(rResp,W7,rEmpresa,"<>",rStatus,"PRAZO D.P")) -> 7 | Z7: =IF(W7="",0,COUNTIFS(rResp,W7,rEmpresa,"<>",rStatus,"DECISÃO D.P")) -> 9 | AA7: =IF(W7="",0,COUNTIFS(rResp,W7,rEmpresa,"<>",rSit,"NO PRAZO")) -> 1 | AB7: =IF(W7="",0,COUNTIFS(rResp,W7,rEmpresa,"<>",rSit,"VENCE EM BREVE")) -> 0 | AC7: =IF(W7="",-1,X7+(100-ROW())/1000) -> 16.093 | AE7: 2 | AF7: =IF(AM7="","",INDEX($W$6:$W$20,AM7)) -> BRUNO CARVALHO | AG7: =IF(AM7="","",INDEX($X$6:$X$20,AM7)) -> 16 | AH7: =IF(AM7="","",INDEX($Y$6:$Y$20,AM7)) -> 7 | AI7: =IF(AM7="","",INDEX($Z$6:$Z$20,AM7)) -> 9 | AJ7: =IF(AM7="","",INDEX($AA$6:$AA$20,AM7)) -> 1 | AK7: =IF(AM7="","",INDEX($AB$6:$AB$20,AM7)) -> 0 | AL7: =IF(AM7="","",IFERROR(AG7/SUM($X$6:$X$20),0)) -> 0.16666667 | AM7: =IF(LARGE($AC$6:$AC$20,AE7)<0,"",MATCH(LARGE($AC$6:$AC$20,AE7),$AC$6:$AC$20,0)) -> 2 | AO7: =IF(CADASTROS!$B$7="","",CADASTROS!$B$7) -> POSTO DE COMBUSTÍVEL | AP7: =IF(AO7="",0,COUNTIFS(rEmpresa,"<>",rResp,critResp,rRamo,AO7)) -> 8 | AQ7: =IF(AO7="",0,COUNTIFS(rEmpresa,"<>",rResp,critResp,rRamo,AO7,rNotif,"NOTIFICAÇÃO DE CONSTATAÇÃO")) -> 4 | AR7: =IF(AO7="",0,COUNTIFS(rEmpresa,"<>",rResp,critResp,rRamo,AO7,rNotif,"NOTIFICAÇÃO DE ESCLARECIMENTO")) -> 4 | AS7: =IF(AO7="",0,COUNTIFS(rEmpresa,"<>",rResp,critResp,rRamo,AO7,rStatus,"PRAZO D.P")) -> 2 | AT7: =IF(AO7="",-1,AP7+(100-ROW())/1000) -> 8.093 | AV7: 2 | AW7: =IF(BC7="","",INDEX($AO$6:$AO$35,BC7)) -> SAÚDE | AX7: =IF(BC7="","",INDEX($AP$6:$AP$35,BC7)) -> 14 | AY7: =IF(BC7="","",INDEX($AQ$6:$AQ$35,BC7)) -> 10 | AZ7: =IF(BC7="","",INDEX($AR$6:$AR$35,BC7)) -> 4 | BA7: =IF(BC7="","",INDEX($AS$6:$AS$35,BC7)) -> 3 | BB7: =IF(BC7="","",IFERROR(AX7/SUM($AP$6:$AP$35),0)) -> 0.14583333 | BC7: =IF(LARGE($AT$6:$AT$35,AV7)<0,"",MATCH(LARGE($AT$6:$AT$35,AV7),$AT$6:$AT$35,0)) -> 3 | BF7: =IF(AND(OR(PROCESSOS!N7="NO PRAZO",PROCESSOS!N7="VENCE EM BREVE"),OR(FiltroResp="TODOS",FiltroResp="",PROCESSOS!H7=FiltroResp)),PROCESSOS!L7+ROW()/1000000,"") | BG7: =IF(AND(PROCESSOS!B7<>"",ISNUMBER(PROCESSOS!D7),OR(FiltroResp="TODOS",FiltroResp="",PROCESSOS!H7=FiltroResp)),PROCESSOS!D7+ROW()/1000000,"") -> 46071 | BI7: 3 | BJ7: =IFERROR(MATCH(SMALL(hProx,BI7),hProx,0),"") -> 88 | BK7: =IFERROR(MATCH(LARGE(hUlt,BI7),hUlt,0),"") -> 94
E8: =IF(CADASTROS!$D$8="","",CADASTROS!$D$8) -> CARLA MENDES | G8: 2027 | L8: 3 | M8: MAR | N8: =COUNTIFS(rEmpresa,"<>",rResp,critResp,rDataFisc,">="&DATE(FiltroAno,L8,1),rDataFisc,"<"&DATE(FiltroAno,L8+1,1)) -> 4 | O8: =COUNTIFS(rEmpresa,"<>",rResp,critResp,rDataFisc,">="&DATE(FiltroAno,L8,1),rDataFisc,"<"&DATE(FiltroAno,L8+1,1),rNotif,"NOTIFICAÇÃO DE CONSTATAÇÃO") -> 4 | P8: =COUNTIFS(rEmpresa,"<>",rResp,critResp,rDataFisc,">="&DATE(FiltroAno,L8,1),rDataFisc,"<"&DATE(FiltroAno,L8+1,1),rNotif,"NOTIFICAÇÃO DE ESCLARECIMENTO") -> 0 | Q8: =COUNTIFS(rEmpresa,"<>",rResp,critResp,rDataFisc,">="&DATE(FiltroAno,L8,1),rDataFisc,"<"&DATE(FiltroAno,L8+1,1),rTipo,"PRESENCIAL") -> 3 | R8: =COUNTIFS(rEmpresa,"<>",rResp,critResp,rDataFisc,">="&DATE(FiltroAno,L8,1),rDataFisc,"<"&DATE(FiltroAno,L8+1,1),rTipo,"ELETRÔNICA") -> 1 | S8: =MetaMensal -> 12 | T8: =SUM($N$6:N8) -> 8 | U8: =SUM($S$6:S8) -> 36 | W8: =IF(CADASTROS!$D$8="","",CADASTROS!$D$8) -> CARLA MENDES | X8: =IF(W8="",0,COUNTIFS(rResp,W8,rEmpresa,"<>")) -> 15 | Y8: =IF(W8="",0,COUNTIFS(rResp,W8,rEmpresa,"<>",rStatus,"PRAZO D.P")) -> 3 | Z8: =IF(W8="",0,COUNTIFS(rResp,W8,rEmpresa,"<>",rStatus,"DECISÃO D.P")) -> 12 | AA8: =IF(W8="",0,COUNTIFS(rResp,W8,rEmpresa,"<>",rSit,"NO PRAZO")) -> 1 | AB8: =IF(W8="",0,COUNTIFS(rResp,W8,rEmpresa,"<>",rSit,"VENCE EM BREVE")) -> 2 | AC8: =IF(W8="",-1,X8+(100-ROW())/1000) -> 15.092 | AE8: 3 | AF8: =IF(AM8="","",INDEX($W$6:$W$20,AM8)) -> CARLA MENDES | AG8: =IF(AM8="","",INDEX($X$6:$X$20,AM8)) -> 15 | AH8: =IF(AM8="","",INDEX($Y$6:$Y$20,AM8)) -> 3 | AI8: =IF(AM8="","",INDEX($Z$6:$Z$20,AM8)) -> 12 | AJ8: =IF(AM8="","",INDEX($AA$6:$AA$20,AM8)) -> 1 | AK8: =IF(AM8="","",INDEX($AB$6:$AB$20,AM8)) -> 2 | AL8: =IF(AM8="","",IFERROR(AG8/SUM($X$6:$X$20),0)) -> 0.15625 | AM8: =IF(LARGE($AC$6:$AC$20,AE8)<0,"",MATCH(LARGE($AC$6:$AC$20,AE8),$AC$6:$AC$20,0)) -> 3 | AO8: =IF(CADASTROS!$B$8="","",CADASTROS!$B$8) -> SAÚDE | AP8: =IF(AO8="",0,COUNTIFS(rEmpresa,"<>",rResp,critResp,rRamo,AO8)) -> 14 | AQ8: =IF(AO8="",0,COUNTIFS(rEmpresa,"<>",rResp,critResp,rRamo,AO8,rNotif,"NOTIFICAÇÃO DE CONSTATAÇÃO")) -> 10 | AR8: =IF(AO8="",0,COUNTIFS(rEmpresa,"<>",rResp,critResp,rRamo,AO8,rNotif,"NOTIFICAÇÃO DE ESCLARECIMENTO")) -> 4 | AS8: =IF(AO8="",0,COUNTIFS(rEmpresa,"<>",rResp,critResp,rRamo,AO8,rStatus,"PRAZO D.P")) -> 3 | AT8: =IF(AO8="",-1,AP8+(100-ROW())/1000) -> 14.092 | AV8: 3 | AW8: =IF(BC8="","",INDEX($AO$6:$AO$35,BC8)) -> RESTAURANTE | AX8: =IF(BC8="","",INDEX($AP$6:$AP$35,BC8)) -> 11 | AY8: =IF(BC8="","",INDEX($AQ$6:$AQ$35,BC8)) -> 9 | AZ8: =IF(BC8="","",INDEX($AR$6:$AR$35,BC8)) -> 2 | BA8: =IF(BC8="","",INDEX($AS$6:$AS$35,BC8)) -> 2 | BB8: =IF(BC8="","",IFERROR(AX8/SUM($AP$6:$AP$35),0)) -> 0.11458333 | BC8: =IF(LARGE($AT$6:$AT$35,AV8)<0,"",MATCH(LARGE($AT$6:$AT$35,AV8),$AT$6:$AT$35,0)) -> 6 | BF8: =IF(AND(OR(PROCESSOS!N8="NO PRAZO",PROCESSOS!N8="VENCE EM BREVE"),OR(FiltroResp="TODOS",FiltroResp="",PROCESSOS!H8=FiltroResp)),PROCESSOS!L8+ROW()/1000000,"") | BG8: =IF(AND(PROCESSOS!B8<>"",ISNUMBER(PROCESSOS!D8),OR(FiltroResp="TODOS",FiltroResp="",PROCESSOS!H8=FiltroResp)),PROCESSOS!D8+ROW()/1000000,"") -> 46076 | BI8: 4 | BJ8: =IFERROR(MATCH(SMALL(hProx,BI8),hProx,0),"") -> 82 | BK8: =IFERROR(MATCH(LARGE(hUlt,BI8),hUlt,0),"") -> 93
E9: =IF(CADASTROS!$D$9="","",CADASTROS!$D$9) -> DIEGO RIBEIRO | G9: 2028 | L9: 4 | M9: ABR | N9: =COUNTIFS(rEmpresa,"<>",rResp,critResp,rDataFisc,">="&DATE(FiltroAno,L9,1),rDataFisc,"<"&DATE(FiltroAno,L9+1,1)) -> 4 | O9: =COUNTIFS(rEmpresa,"<>",rResp,critResp,rDataFisc,">="&DATE(FiltroAno,L9,1),rDataFisc,"<"&DATE(FiltroAno,L9+1,1),rNotif,"NOTIFICAÇÃO DE CONSTATAÇÃO") -> 2 | P9: =COUNTIFS(rEmpresa,"<>",rResp,critResp,rDataFisc,">="&DATE(FiltroAno,L9,1),rDataFisc,"<"&DATE(FiltroAno,L9+1,1),rNotif,"NOTIFICAÇÃO DE ESCLARECIMENTO") -> 2 | Q9: =COUNTIFS(rEmpresa,"<>",rResp,critResp,rDataFisc,">="&DATE(FiltroAno,L9,1),rDataFisc,"<"&DATE(FiltroAno,L9+1,1),rTipo,"PRESENCIAL") -> 3 | R9: =COUNTIFS(rEmpresa,"<>",rResp,critResp,rDataFisc,">="&DATE(FiltroAno,L9,1),rDataFisc,"<"&DATE(FiltroAno,L9+1,1),rTipo,"ELETRÔNICA") -> 1 | S9: =MetaMensal -> 12 | T9: =SUM($N$6:N9) -> 12 | U9: =SUM($S$6:S9) -> 48 | W9: =IF(CADASTROS!$D$9="","",CADASTROS!$D$9) -> DIEGO RIBEIRO | X9: =IF(W9="",0,COUNTIFS(rResp,W9,rEmpresa,"<>")) -> 24 | Y9: =IF(W9="",0,COUNTIFS(rResp,W9,rEmpresa,"<>",rStatus,"PRAZO D.P")) -> 10 | Z9: =IF(W9="",0,COUNTIFS(rResp,W9,rEmpresa,"<>",rStatus,"DECISÃO D.P")) -> 14 | AA9: =IF(W9="",0,COUNTIFS(rResp,W9,rEmpresa,"<>",rSit,"NO PRAZO")) -> 2 | AB9: =IF(W9="",0,COUNTIFS(rResp,W9,rEmpresa,"<>",rSit,"VENCE EM BREVE")) -> 4 | AC9: =IF(W9="",-1,X9+(100-ROW())/1000) -> 24.091 | AE9: 4 | AF9: =IF(AM9="","",INDEX($W$6:$W$20,AM9)) -> EDUARDA LIMA | AG9: =IF(AM9="","",INDEX($X$6:$X$20,AM9)) -> 13 | AH9: =IF(AM9="","",INDEX($Y$6:$Y$20,AM9)) -> 4 | AI9: =IF(AM9="","",INDEX($Z$6:$Z$20,AM9)) -> 9 | AJ9: =IF(AM9="","",INDEX($AA$6:$AA$20,AM9)) -> 0 | AK9: =IF(AM9="","",INDEX($AB$6:$AB$20,AM9)) -> 0 | AL9: =IF(AM9="","",IFERROR(AG9/SUM($X$6:$X$20),0)) -> 0.13541667 | AM9: =IF(LARGE($AC$6:$AC$20,AE9)<0,"",MATCH(LARGE($AC$6:$AC$20,AE9),$AC$6:$AC$20,0)) -> 5 | AO9: =IF(CADASTROS!$B$9="","",CADASTROS!$B$9) -> ACADEMIA | AP9: =IF(AO9="",0,COUNTIFS(rEmpresa,"<>",rResp,critResp,rRamo,AO9)) -> 6 | AQ9: =IF(AO9="",0,COUNTIFS(rEmpresa,"<>",rResp,critResp,rRamo,AO9,rNotif,"NOTIFICAÇÃO DE CONSTATAÇÃO")) -> 5 | AR9: =IF(AO9="",0,COUNTIFS(rEmpresa,"<>",rResp,critResp,rRamo,AO9,rNotif,"NOTIFICAÇÃO DE ESCLARECIMENTO")) -> 1 | AS9: =IF(AO9="",0,COUNTIFS(rEmpresa,"<>",rResp,critResp,rRamo,AO9,rStatus,"PRAZO D.P")) -> 2 | AT9: =IF(AO9="",-1,AP9+(100-ROW())/1000) -> 6.091 | AV9: 4 | AW9: =IF(BC9="","",INDEX($AO$6:$AO$35,BC9)) -> SUPERMERCADO | AX9: =IF(BC9="","",INDEX($AP$6:$AP$35,BC9)) -> 10 | AY9: =IF(BC9="","",INDEX($AQ$6:$AQ$35,BC9)) -> 6 | AZ9: =IF(BC9="","",INDEX($AR$6:$AR$35,BC9)) -> 4 | BA9: =IF(BC9="","",INDEX($AS$6:$AS$35,BC9)) -> 2 | BB9: =IF(BC9="","",IFERROR(AX9/SUM($AP$6:$AP$35),0)) -> 0.10416667 | BC9: =IF(LARGE($AT$6:$AT$35,AV9)<0,"",MATCH(LARGE($AT$6:$AT$35,AV9),$AT$6:$AT$35,0)) -> 5 | BF9: =IF(AND(OR(PROCESSOS!N9="NO PRAZO",PROCESSOS!N9="VENCE EM BREVE"),OR(FiltroResp="TODOS",FiltroResp="",PROCESSOS!H9=FiltroResp)),PROCESSOS!L9+ROW()/1000000,"") | BG9: =IF(AND(PROCESSOS!B9<>"",ISNUMBER(PROCESSOS!D9),OR(FiltroResp="TODOS",FiltroResp="",PROCESSOS!H9=FiltroResp)),PROCESSOS!D9+ROW()/1000000,"") -> 46082 | BI9: 5 | BJ9: =IFERROR(MATCH(SMALL(hProx,BI9),hProx,0),"") -> 90 | BK9: =IFERROR(MATCH(LARGE(hUlt,BI9),hUlt,0),"") -> 92
E10: =IF(CADASTROS!$D$10="","",CADASTROS!$D$10) -> EDUARDA LIMA | G10: 2029 | I10: SITUAÇÃO | L10: 5 | M10: MAI | N10: =COUNTIFS(rEmpresa,"<>",rResp,critResp,rDataFisc,">="&DATE(FiltroAno,L10,1),rDataFisc,"<"&DATE(FiltroAno,L10+1,1)) -> 13 | O10: =COUNTIFS(rEmpresa,"<>",rResp,critResp,rDataFisc,">="&DATE(FiltroAno,L10,1),rDataFisc,"<"&DATE(FiltroAno,L10+1,1),rNotif,"NOTIFICAÇÃO DE CONSTATAÇÃO") -> 9 | P10: =COUNTIFS(rEmpresa,"<>",rResp,critResp,rDataFisc,">="&DATE(FiltroAno,L10,1),rDataFisc,"<"&DATE(FiltroAno,L10+1,1),rNotif,"NOTIFICAÇÃO DE ESCLARECIMENTO") -> 4 | Q10: =COUNTIFS(rEmpresa,"<>",rResp,critResp,rDataFisc,">="&DATE(FiltroAno,L10,1),rDataFisc,"<"&DATE(FiltroAno,L10+1,1),rTipo,"PRESENCIAL") -> 9 | R10: =COUNTIFS(rEmpresa,"<>",rResp,critResp,rDataFisc,">="&DATE(FiltroAno,L10,1),rDataFisc,"<"&DATE(FiltroAno,L10+1,1),rTipo,"ELETRÔNICA") -> 4 | S10: =MetaMensal -> 12 | T10: =SUM($N$6:N10) -> 25 | U10: =SUM($S$6:S10) -> 60 | W10: =IF(CADASTROS!$D$10="","",CADASTROS!$D$10) -> EDUARDA LIMA | X10: =IF(W10="",0,COUNTIFS(rResp,W10,rEmpresa,"<>")) -> 13 | Y10: =IF(W10="",0,COUNTIFS(rResp,W10,rEmpresa,"<>",rStatus,"PRAZO D.P")) -> 4 | Z10: =IF(W10="",0,COUNTIFS(rResp,W10,rEmpresa,"<>",rStatus,"DECISÃO D.P")) -> 9 | AA10: =IF(W10="",0,COUNTIFS(rResp,W10,rEmpresa,"<>",rSit,"NO PRAZO")) -> 0 | AB10: =IF(W10="",0,COUNTIFS(rResp,W10,rEmpresa,"<>",rSit,"VENCE EM BREVE")) -> 0 | AC10: =IF(W10="",-1,X10+(100-ROW())/1000) -> 13.09 | AE10: 5 | AF10: =IF(AM10="","",INDEX($W$6:$W$20,AM10)) -> ANA PAULA SOUZA | AG10: =IF(AM10="","",INDEX($X$6:$X$20,AM10)) -> 10 | AH10: =IF(AM10="","",INDEX($Y$6:$Y$20,AM10)) -> 2 | AI10: =IF(AM10="","",INDEX($Z$6:$Z$20,AM10)) -> 8 | AJ10: =IF(AM10="","",INDEX($AA$6:$AA$20,AM10)) -> 0 | AK10: =IF(AM10="","",INDEX($AB$6:$AB$20,AM10)) -> 0 | AL10: =IF(AM10="","",IFERROR(AG10/SUM($X$6:$X$20),0)) -> 0.10416667 | AM10: =IF(LARGE($AC$6:$AC$20,AE10)<0,"",MATCH(LARGE($AC$6:$AC$20,AE10),$AC$6:$AC$20,0)) -> 1 | AO10: =IF(CADASTROS!$B$10="","",CADASTROS!$B$10) -> SUPERMERCADO | AP10: =IF(AO10="",0,COUNTIFS(rEmpresa,"<>",rResp,critResp,rRamo,AO10)) -> 10 | AQ10: =IF(AO10="",0,COUNTIFS(rEmpresa,"<>",rResp,critResp,rRamo,AO10,rNotif,"NOTIFICAÇÃO DE CONSTATAÇÃO")) -> 6 | AR10: =IF(AO10="",0,COUNTIFS(rEmpresa,"<>",rResp,critResp,rRamo,AO10,rNotif,"NOTIFICAÇÃO DE ESCLARECIMENTO")) -> 4 | AS10: =IF(AO10="",0,COUNTIFS(rEmpresa,"<>",rResp,critResp,rRamo,AO10,rStatus,"PRAZO D.P")) -> 2 | AT10: =IF(AO10="",-1,AP10+(100-ROW())/1000) -> 10.09 | AV10: 5 | AW10: =IF(BC10="","",INDEX($AO$6:$AO$35,BC10)) -> POSTO DE COMBUSTÍVEL | AX10: =IF(BC10="","",INDEX($AP$6:$AP$35,BC10)) -> 8 | AY10: =IF(BC10="","",INDEX($AQ$6:$AQ$35,BC10)) -> 4 | AZ10: =IF(BC10="","",INDEX($AR$6:$AR$35,BC10)) -> 4 | BA10: =IF(BC10="","",INDEX($AS$6:$AS$35,BC10)) -> 2 | BB10: =IF(BC10="","",IFERROR(AX10/SUM($AP$6:$AP$35),0)) -> 0.083333333 | BC10: =IF(LARGE($AT$6:$AT$35,AV10)<0,"",MATCH(LARGE($AT$6:$AT$35,AV10),$AT$6:$AT$35,0)) -> 2 | BF10: =IF(AND(OR(PROCESSOS!N10="NO PRAZO",PROCESSOS!N10="VENCE EM BREVE"),OR(FiltroResp="TODOS",FiltroResp="",PROCESSOS!H10=FiltroResp)),PROCESSOS!L10+ROW()/1000000,"") | BG10: =IF(AND(PROCESSOS!B10<>"",ISNUMBER(PROCESSOS!D10),OR(FiltroResp="TODOS",FiltroResp="",PROCESSOS!H10=FiltroResp)),PROCESSOS!D10+ROW()/1000000,"") -> 46093 | BI10: 6 | BJ10: =IFERROR(MATCH(SMALL(hProx,BI10),hProx,0),"") -> 91 | BK10: =IFERROR(MATCH(LARGE(hUlt,BI10),hUlt,0),"") -> 91
E11: =IF(CADASTROS!$D$11="","",CADASTROS!$D$11) -> FELIPE ARAÚJO | G11: 2030 | I11: No prazo | J11: =COUNTIFS(rEmpresa,"<>",rResp,critResp,rSit,"NO PRAZO") -> 6 | L11: 6 | M11: JUN | N11: =COUNTIFS(rEmpresa,"<>",rResp,critResp,rDataFisc,">="&DATE(FiltroAno,L11,1),rDataFisc,"<"&DATE(FiltroAno,L11+1,1)) -> 9 | O11: =COUNTIFS(rEmpresa,"<>",rResp,critResp,rDataFisc,">="&DATE(FiltroAno,L11,1),rDataFisc,"<"&DATE(FiltroAno,L11+1,1),rNotif,"NOTIFICAÇÃO DE CONSTATAÇÃO") -> 6 | P11: =COUNTIFS(rEmpresa,"<>",rResp,critResp,rDataFisc,">="&DATE(FiltroAno,L11,1),rDataFisc,"<"&DATE(FiltroAno,L11+1,1),rNotif,"NOTIFICAÇÃO DE ESCLARECIMENTO") -> 3 | Q11: =COUNTIFS(rEmpresa,"<>",rResp,critResp,rDataFisc,">="&DATE(FiltroAno,L11,1),rDataFisc,"<"&DATE(FiltroAno,L11+1,1),rTipo,"PRESENCIAL") -> 6 | R11: =COUNTIFS(rEmpresa,"<>",rResp,critResp,rDataFisc,">="&DATE(FiltroAno,L11,1),rDataFisc,"<"&DATE(FiltroAno,L11+1,1),rTipo,"ELETRÔNICA") -> 3 | S11: =MetaMensal -> 12 | T11: =SUM($N$6:N11) -> 34 | U11: =SUM($S$6:S11) -> 72 | W11: =IF(CADASTROS!$D$11="","",CADASTROS!$D$11) -> FELIPE ARAÚJO | X11: =IF(W11="",0,COUNTIFS(rResp,W11,rEmpresa,"<>")) -> 8 | Y11: =IF(W11="",0,COUNTIFS(rResp,W11,rEmpresa,"<>",rStatus,"PRAZO D.P")) -> 1 | Z11: =IF(W11="",0,COUNTIFS(rResp,W11,rEmpresa,"<>",rStatus,"DECISÃO D.P")) -> 7 | AA11: =IF(W11="",0,COUNTIFS(rResp,W11,rEmpresa,"<>",rSit,"NO PRAZO")) -> 0 | AB11: =IF(W11="",0,COUNTIFS(rResp,W11,rEmpresa,"<>",rSit,"VENCE EM BREVE")) -> 0 | AC11: =IF(W11="",-1,X11+(100-ROW())/1000) -> 8.089 | AE11: 6 | AF11: =IF(AM11="","",INDEX($W$6:$W$20,AM11)) -> FELIPE ARAÚJO | AG11: =IF(AM11="","",INDEX($X$6:$X$20,AM11)) -> 8 | AH11: =IF(AM11="","",INDEX($Y$6:$Y$20,AM11)) -> 1 | AI11: =IF(AM11="","",INDEX($Z$6:$Z$20,AM11)) -> 7 | AJ11: =IF(AM11="","",INDEX($AA$6:$AA$20,AM11)) -> 0 | AK11: =IF(AM11="","",INDEX($AB$6:$AB$20,AM11)) -> 0 | AL11: =IF(AM11="","",IFERROR(AG11/SUM($X$6:$X$20),0)) -> 0.083333333 | AM11: =IF(LARGE($AC$6:$AC$20,AE11)<0,"",MATCH(LARGE($AC$6:$AC$20,AE11),$AC$6:$AC$20,0)) -> 6 | AO11: =IF(CADASTROS!$B$11="","",CADASTROS!$B$11) -> RESTAURANTE | AP11: =IF(AO11="",0,COUNTIFS(rEmpresa,"<>",rResp,critResp,rRamo,AO11)) -> 11 | AQ11: =IF(AO11="",0,COUNTIFS(rEmpresa,"<>",rResp,critResp,rRamo,AO11,rNotif,"NOTIFICAÇÃO DE CONSTATAÇÃO")) -> 9 | AR11: =IF(AO11="",0,COUNTIFS(rEmpresa,"<>",rResp,critResp,rRamo,AO11,rNotif,"NOTIFICAÇÃO DE ESCLARECIMENTO")) -> 2 | AS11: =IF(AO11="",0,COUNTIFS(rEmpresa,"<>",rResp,critResp,rRamo,AO11,rStatus,"PRAZO D.P")) -> 2 | AT11: =IF(AO11="",-1,AP11+(100-ROW())/1000) -> 11.089 | AV11: 6 | AW11: =IF(BC11="","",INDEX($AO$6:$AO$35,BC11)) -> BANCO | AX11: =IF(BC11="","",INDEX($AP$6:$AP$35,BC11)) -> 8 | AY11: =IF(BC11="","",INDEX($AQ$6:$AQ$35,BC11)) -> 5 | AZ11: =IF(BC11="","",INDEX($AR$6:$AR$35,BC11)) -> 3 | BA11: =IF(BC11="","",INDEX($AS$6:$AS$35,BC11)) -> 2 | BB11: =IF(BC11="","",IFERROR(AX11/SUM($AP$6:$AP$35),0)) -> 0.083333333 | BC11: =IF(LARGE($AT$6:$AT$35,AV11)<0,"",MATCH(LARGE($AT$6:$AT$35,AV11),$AT$6:$AT$35,0)) -> 8 | BF11: =IF(AND(OR(PROCESSOS!N11="NO PRAZO",PROCESSOS!N11="VENCE EM BREVE"),OR(FiltroResp="TODOS",FiltroResp="",PROCESSOS!H11=FiltroResp)),PROCESSOS!L11+ROW()/1000000,"") | BG11: =IF(AND(PROCESSOS!B11<>"",ISNUMBER(PROCESSOS!D11),OR(FiltroResp="TODOS",FiltroResp="",PROCESSOS!H11=FiltroResp)),PROCESSOS!D11+ROW()/1000000,"") -> 46101 | BI11: 7 | BJ11: =IFERROR(MATCH(SMALL(hProx,BI11),hProx,0),"") -> 85 | BK11: =IFERROR(MATCH(LARGE(hUlt,BI11),hUlt,0),"") -> 90
E12: =IF(CADASTROS!$D$12="","",CADASTROS!$D$12) -> GABRIELA NUNES | G12: 2031 | I12: Vence em breve | J12: =COUNTIFS(rEmpresa,"<>",rResp,critResp,rSit,"VENCE EM BREVE") -> 6 | L12: 7 | M12: JUL | N12: =COUNTIFS(rEmpresa,"<>",rResp,critResp,rDataFisc,">="&DATE(FiltroAno,L12,1),rDataFisc,"<"&DATE(FiltroAno,L12+1,1)) -> 16 | O12: =COUNTIFS(rEmpresa,"<>",rResp,critResp,rDataFisc,">="&DATE(FiltroAno,L12,1),rDataFisc,"<"&DATE(FiltroAno,L12+1,1),rNotif,"NOTIFICAÇÃO DE CONSTATAÇÃO") -> 11 | P12: =COUNTIFS(rEmpresa,"<>",rResp,critResp,rDataFisc,">="&DATE(FiltroAno,L12,1),rDataFisc,"<"&DATE(FiltroAno,L12+1,1),rNotif,"NOTIFICAÇÃO DE ESCLARECIMENTO") -> 5 | Q12: =COUNTIFS(rEmpresa,"<>",rResp,critResp,rDataFisc,">="&DATE(FiltroAno,L12,1),rDataFisc,"<"&DATE(FiltroAno,L12+1,1),rTipo,"PRESENCIAL") -> 7 | R12: =COUNTIFS(rEmpresa,"<>",rResp,critResp,rDataFisc,">="&DATE(FiltroAno,L12,1),rDataFisc,"<"&DATE(FiltroAno,L12+1,1),rTipo,"ELETRÔNICA") -> 9 | S12: =MetaMensal -> 12 | T12: =SUM($N$6:N12) -> 50 | U12: =SUM($S$6:S12) -> 84 | W12: =IF(CADASTROS!$D$12="","",CADASTROS!$D$12) -> GABRIELA NUNES | X12: =IF(W12="",0,COUNTIFS(rResp,W12,rEmpresa,"<>")) -> 7 | Y12: =IF(W12="",0,COUNTIFS(rResp,W12,rEmpresa,"<>",rStatus,"PRAZO D.P")) -> 2 | Z12: =IF(W12="",0,COUNTIFS(rResp,W12,rEmpresa,"<>",rStatus,"DECISÃO D.P")) -> 5 | AA12: =IF(W12="",0,COUNTIFS(rResp,W12,rEmpresa,"<>",rSit,"NO PRAZO")) -> 2 | AB12: =IF(W12="",0,COUNTIFS(rResp,W12,rEmpresa,"<>",rSit,"VENCE EM BREVE")) -> 0 | AC12: =IF(W12="",-1,X12+(100-ROW())/1000) -> 7.088 | AE12: 7 | AF12: =IF(AM12="","",INDEX($W$6:$W$20,AM12)) -> GABRIELA NUNES | AG12: =IF(AM12="","",INDEX($X$6:$X$20,AM12)) -> 7 | AH12: =IF(AM12="","",INDEX($Y$6:$Y$20,AM12)) -> 2 | AI12: =IF(AM12="","",INDEX($Z$6:$Z$20,AM12)) -> 5 | AJ12: =IF(AM12="","",INDEX($AA$6:$AA$20,AM12)) -> 2 | AK12: =IF(AM12="","",INDEX($AB$6:$AB$20,AM12)) -> 0 | AL12: =IF(AM12="","",IFERROR(AG12/SUM($X$6:$X$20),0)) -> 0.072916667 | AM12: =IF(LARGE($AC$6:$AC$20,AE12)<0,"",MATCH(LARGE($AC$6:$AC$20,AE12),$AC$6:$AC$20,0)) -> 7 | AO12: =IF(CADASTROS!$B$12="","",CADASTROS!$B$12) -> FARMÁCIA | AP12: =IF(AO12="",0,COUNTIFS(rEmpresa,"<>",rResp,critResp,rRamo,AO12)) -> 6 | AQ12: =IF(AO12="",0,COUNTIFS(rEmpresa,"<>",rResp,critResp,rRamo,AO12,rNotif,"NOTIFICAÇÃO DE CONSTATAÇÃO")) -> 6 | AR12: =IF(AO12="",0,COUNTIFS(rEmpresa,"<>",rResp,critResp,rRamo,AO12,rNotif,"NOTIFICAÇÃO DE ESCLARECIMENTO")) -> 0 | AS12: =IF(AO12="",0,COUNTIFS(rEmpresa,"<>",rResp,critResp,rRamo,AO12,rStatus,"PRAZO D.P")) -> 3 | AT12: =IF(AO12="",-1,AP12+(100-ROW())/1000) -> 6.088 | AV12: 7 | AW12: =IF(BC12="","",INDEX($AO$6:$AO$35,BC12)) -> ACADEMIA | AX12: =IF(BC12="","",INDEX($AP$6:$AP$35,BC12)) -> 6 | AY12: =IF(BC12="","",INDEX($AQ$6:$AQ$35,BC12)) -> 5 | AZ12: =IF(BC12="","",INDEX($AR$6:$AR$35,BC12)) -> 1 | BA12: =IF(BC12="","",INDEX($AS$6:$AS$35,BC12)) -> 2 | BB12: =IF(BC12="","",IFERROR(AX12/SUM($AP$6:$AP$35),0)) -> 0.0625 | BC12: =IF(LARGE($AT$6:$AT$35,AV12)<0,"",MATCH(LARGE($AT$6:$AT$35,AV12),$AT$6:$AT$35,0)) -> 4 | BF12: =IF(AND(OR(PROCESSOS!N12="NO PRAZO",PROCESSOS!N12="VENCE EM BREVE"),OR(FiltroResp="TODOS",FiltroResp="",PROCESSOS!H12=FiltroResp)),PROCESSOS!L12+ROW()/1000000,"") | BG12: =IF(AND(PROCESSOS!B12<>"",ISNUMBER(PROCESSOS!D12),OR(FiltroResp="TODOS",FiltroResp="",PROCESSOS!H12=FiltroResp)),PROCESSOS!D12+ROW()/1000000,"") -> 46110 | BI12: 8 | BJ12: =IFERROR(MATCH(SMALL(hProx,BI12),hProx,0),"") -> 86 | BK12: =IFERROR(MATCH(LARGE(hUlt,BI12),hUlt,0),"") -> 89
