Workbook

Sheet PAINEL
B2: PAINEL DE CONTROLE — FOLGAS E FÉRIAS
B3: ="Hoje é "&CHOOSE(WEEKDAY(TODAY()),"Domingo","Segunda","Terça","Quarta","Quinta","Sexta","Sábado")&", "&TEXT(DAY(TODAY()),"00")&"/"&TEXT(MONTH(TODAY()),"00")&"/"&YEAR(TODAY())&" • atualiza sozinho ao abrir a planilha" -> Hoje é Terça, 06/10/2026 • atualiza sozinho ao abrir a planilha
B5: =IF(B8+E8=0,"✔ Nenhum funcionário de folga ou de férias hoje.","⚠ ATENÇÃO: hoje há "&B8&" funcionário(s) de FOLGA e "&E8&" em FÉRIAS — veja a lista abaixo.") -> ✔ Nenhum funcionário de folga ou de férias hoje.
B7: De folga hoje (inclui Natal/Ano Novo) | E7: Em férias hoje | G7: Folgas nos próx. 7 dias | H7: Férias começando em 30 dias
B8: =COUNT(AUX!$G$2:$G$901) -> 0 | E8: =COUNTIFS(FÉRIAS!$C$2:$C$301,"<="&TODAY(),FÉRIAS!$D$2:$D$301,">="&TODAY()) -> 0 | G8: =COUNT(AUX!$H$2:$H$901) -> 0 | H8: =COUNT(FÉRIAS!$L$2:$L$301) -> 2
B10: Férias sem data definida | E10: Alertas em todas as abas | G10: Natal | H10: Ano Novo
B11: =COUNTIFS(FÉRIAS!$A$2:$A$301,"?*",FÉRIAS!$H$2:$H$301,"Sem data definida") -> 2 | E11: =COUNTIF(FOLGAS!$G$2:$G$301,"⚠*")+COUNTIF(FÉRIAS!$I$2:$I$301,"⚠*")+COUNTIF(FÉRIAS!$H$2:$H$301,"⚠*")+COUNTIF(NATAL!$F$2:$F$301,"⚠*")+COUNTIF('ANO NOVO'!$F$2:$F$301,"⚠*") -> 2 | G11: =COUNTIF(NATAL!$D$2:$D$301,"FOLGA")&" folga / "&COUNTIF(NATAL!$D$2:$D$301,"TRABALHA")&" trab."&IF(COUNTIFS(NATAL!$A$2:$A$301,"?*",NATAL!$D$2:$D$301,"")>0," / "&COUNTIFS(NATAL!$A$2:$A$301,"?*",NATAL!$D$2:$D$301,"")&" pend.","") -> 0 folga / 0 trab. | H11: =COUNTIF('ANO NOVO'!$D$2:$D$301,"FOLGA")&" folga / "&COUNTIF('ANO NOVO'!$D$2:$D$301,"TRABALHA")&" trab."&IF(COUNTIFS('ANO NOVO'!$A$2:$A$301,"?*",'ANO NOVO'!$D$2:$D$301,"")>0," / "&COUNTIFS('ANO NOVO'!$A$2:$A$301,"?*",'ANO NOVO'!$D$2:$D$301,"")&" pend.","") -> 0 folga / 0 trab.
B13: DE FOLGA HOJE
B14: # | C14: Nome | D14: Setor | E14: Origem | F14: Observação
B15: =IF(L15="","",1) | C15: =IF($L15="","",INDEX(AUX!$B:$B,$L15)&"") | D15: =IF($L15="","",INDEX(AUX!$C:$C,$L15)&"") | E15: =IF($L15="","",INDEX(AUX!$A:$A,$L15)&"") | F15: =IF($L15="","",INDEX(AUX!$E:$E,$L15)&"") | L15: =IFERROR(ROUND(MOD(SMALL(AUX!$G$2:$G$901,1),1)*100000,0),"")
B16: =IF(L16="","",2) | C16: =IF($L16="","",INDEX(AUX!$B:$B,$L16)&"") | D16: =IF($L16="","",INDEX(AUX!$C:$C,$L16)&"") | E16: =IF($L16="","",INDEX(AUX!$A:$A,$L16)&"") | F16: =IF($L16="","",INDEX(AUX!$E:$E,$L16)&"") | L16: =IFERROR(ROUND(MOD(SMALL(AUX!$G$2:$G$901,2),1)*100000,0),"")
B17: =IF(L17="","",3) | C17: =IF($L17="","",INDEX(AUX!$B:$B,$L17)&"") | D17: =IF($L17="","",INDEX(AUX!$C:$C,$L17)&"") | E17: =IF($L17="","",INDEX(AUX!$A:$A,$L17)&"") | F17: =IF($L17="","",INDEX(AUX!$E:$E,$L17)&"") | L17: =IFERROR(ROUND(MOD(SMALL(AUX!$G$2:$G$901,3),1)*100000,0),"")
B18: =IF(L18="","",4) | C18: =IF($L18="","",INDEX(AUX!$B:$B,$L18)&"") | D18: =IF($L18="","",INDEX(AUX!$C:$C,$L18)&"") | E18: =IF($L18="","",INDEX(AUX!$A:$A,$L18)&"") | F18: =IF($L18="","",INDEX(AUX!$E:$E,$L18)&"") | L18: =IFERROR(ROUND(MOD(SMALL(AUX!$G$2:$G$901,4),1)*100000,0),"")
B19: =IF(L19="","",5) | C19: =IF($L19="","",INDEX(AUX!$B:$B,$L19)&"") | D19: =IF($L19="","",INDEX(AUX!$C:$C,$L19)&"") | E19: =IF($L19="","",INDEX(AUX!$A:$A,$L19)&"") | F19: =IF($L19="","",INDEX(AUX!$E:$E,$L19)&"") | L19: =IFERROR(ROUND(MOD(SMALL(AUX!$G$2:$G$901,5),1)*100000,0),"")
B20: =IF(L20="","",6) | C20: =IF($L20="","",INDEX(AUX!$B:$B,$L20)&"") | D20: =IF($L20="","",INDEX(AUX!$C:$C,$L20)&"") | E20: =IF($L20="","",INDEX(AUX!$A:$A,$L20)&"") | F20: =IF($L20="","",INDEX(AUX!$E:$E,$L20)&"") | L20: =IFERROR(ROUND(MOD(SMALL(AUX!$G$2:$G$901,6),1)*100000,0),"")
B21: =IF(L21="","",7) | C21: =IF($L21="","",INDEX(AUX!$B:$B,$L21)&"") | D21: =IF($L21="","",INDEX(AUX!$C:$C,$L21)&"") | E21: =IF($L21="","",INDEX(AUX!$A:$A,$L21)&"") | F21: =IF($L21="","",INDEX(AUX!$E:$E,$L21)&"") | L21: =IFERROR(ROUND(MOD(SMALL(AUX!$G$2:$G$901,7),1)*100000,0),"")
B22: =IF(L22="","",8) | C22: =IF($L22="","",INDEX(AUX!$B:$B,$L22)&"") | D22: =IF($L22="","",INDEX(AUX!$C:$C,$L22)&"") | E22: =IF($L22="","",INDEX(AUX!$A:$A,$L22)&"") | F22: =IF($L22="","",INDEX(AUX!$E:$E,$L22)&"") | L22: =IFERROR(ROUND(MOD(SMALL(AUX!$G$2:$G$901,8),1)*100000,0),"")
B23: =IF(L23="","",9) | C23: =IF($L23="","",INDEX(AUX!$B:$B,$L23)&"") | D23: =IF($L23="","",INDEX(AUX!$C:$C,$L23)&"") | E23: =IF($L23="","",INDEX(AUX!$A:$A,$L23)&"") | F23: =IF($L23="","",INDEX(AUX!$E:$E,$L23)&"") | L23: =IFERROR(ROUND(MOD(SMALL(AUX!$G$2:$G$901,9),1)*100000,0),"")
B24: =IF(L24="","",10) | C24: =IF($L24="","",INDEX(AUX!$B:$B,$L24)&"") | D24: =IF($L24="","",INDEX(AUX!$C:$C,$L24)&"") | E24: =IF($L24="","",INDEX(AUX!$A:$A,$L24)&"") | F24: =IF($L24="","",INDEX(AUX!$E:$E,$L24)&"") | L24: =IFERROR(ROUND(MOD(SMALL(AUX!$G$2:$G$901,10),1)*100000,0),"")
B25: =IF($B$8=0,"Ninguém nesta lista.",IF($B$8>10,"... e mais "&($B$8-10)&" — veja a aba FOLGAS / NATAL / ANO NOVO.","")) -> Ninguém nesta lista.
B27: EM FÉRIAS HOJE
B28: # | C28: Nome | D28: Setor | E28: Início | F28: Fim | G28: Retorno | H28: Dias restantes | I28: Status
B29: =IF(L29="","",1) | C29: =IF($L29="","",INDEX(FÉRIAS!$A:$A,$L29)&"") | D29: =IF($L29="","",INDEX(FÉRIAS!$B:$B,$L29)&"") | E29: =IF($L29="","",INDEX(FÉRIAS!$C:$C,$L29)) | F29: =IF($L29="","",INDEX(FÉRIAS!$D:$D,$L29)) | G29: =IF($L29="","",INDEX(FÉRIAS!$G:$G,$L29)) | H29: =IF($L29="","",INDEX(FÉRIAS!$D:$D,$L29)-TODAY()) | I29: =IF($L29="","",INDEX(FÉRIAS!$H:$H,$L29)&"") | L29: =IFERROR(ROUND(MOD(SMALL(FÉRIAS!$K$2:$K$301,1),1)*100000,0),"")
B30: =IF(L30="","",2) | C30: =IF($L30="","",INDEX(FÉRIAS!$A:$A,$L30)&"") | D30: =IF($L30="","",INDEX(FÉRIAS!$B:$B,$L30)&"") | E30: =IF($L30="","",INDEX(FÉRIAS!$C:$C,$L30)) | F30: =IF($L30="","",INDEX(FÉRIAS!$D:$D,$L30)) | G30: =IF($L30="","",INDEX(FÉRIAS!$G:$G,$L30)) | H30: =IF($L30="","",INDEX(FÉRIAS!$D:$D,$L30)-TODAY()) | I30: =IF($L30="","",INDEX(FÉRIAS!$H:$H,$L30)&"") | L30: =IFERROR(ROUND(MOD(SMALL(FÉRIAS!$K$2:$K$301,2),1)*100000,0),"")
B31: =IF(L31="","",3) | C31: =IF($L31="","",INDEX(FÉRIAS!$A:$A,$L31)&"") | D31: =IF($L31="","",INDEX(FÉRIAS!$B:$B,$L31)&"") | E31: =IF($L31="","",INDEX(FÉRIAS!$C:$C,$L31)) | F31: =IF($L31="","",INDEX(FÉRIAS!$D:$D,$L31)) | G31: =IF($L31="","",INDEX(FÉRIAS!$G:$G,$L31)) | H31: =IF($L31="","",INDEX(FÉRIAS!$D:$D,$L31)-TODAY()) | I31: =IF($L31="","",INDEX(FÉRIAS!$H:$H,$L31)&"") | L31: =IFERROR(ROUND(MOD(SMALL(FÉRIAS!$K$2:$K$301,3),1)*100000,0),"")
B32: =IF(L32="","",4) | C32: =IF($L32="","",INDEX(FÉRIAS!$A:$A,$L32)&"") | D32: =IF($L32="","",INDEX(FÉRIAS!$B:$B,$L32)&"") | E32: =IF($L32="","",INDEX(FÉRIAS!$C:$C,$L32)) | F32: =IF($L32="","",INDEX(FÉRIAS!$D:$D,$L32)) | G32: =IF($L32="","",INDEX(FÉRIAS!$G:$G,$L32)) | H32: =IF($L32="","",INDEX(FÉRIAS!$D:$D,$L32)-TODAY()) | I32: =IF($L32="","",INDEX(FÉRIAS!$H:$H,$L32)&"") | L32: =IFERROR(ROUND(MOD(SMALL(FÉRIAS!$K$2:$K$301,4),1)*100000,0),"")
B33: =IF(L33="","",5) | C33: =IF($L33="","",INDEX(FÉRIAS!$A:$A,$L33)&"") | D33: =IF($L33="","",INDEX(FÉRIAS!$B:$B,$L33)&"") | E33: =IF($L33="","",INDEX(FÉRIAS!$C:$C,$L33)) | F33: =IF($L33="","",INDEX(FÉRIAS!$D:$D,$L33)) | G33: =IF($L33="","",INDEX(FÉRIAS!$G:$G,$L33)) | H33: =IF($L33="","",INDEX(FÉRIAS!$D:$D,$L33)-TODAY()) | I33: =IF($L33="","",INDEX(FÉRIAS!$H:$H,$L33)&"") | L33: =IFERROR(ROUND(MOD(SMALL(FÉRIAS!$K$2:$K$301,5),1)*100000,0),"")
B34: =IF(L34="","",6) | C34: =IF($L34="","",INDEX(FÉRIAS!$A:$A,$L34)&"") | D34: =IF($L34="","",INDEX(FÉRIAS!$B:$B,$L34)&"") | E34: =IF($L34="","",INDEX(FÉRIAS!$C:$C,$L34)) | F34: =IF($L34="","",INDEX(FÉRIAS!$D:$D,$L34)) | G34: =IF($L34="","",INDEX(FÉRIAS!$G:$G,$L34)) | H34: =IF($L34="","",INDEX(FÉRIAS!$D:$D,$L34)-TODAY()) | I34: =IF($L34="","",INDEX(FÉRIAS!$H:$H,$L34)&"") | L34: =IFERROR(ROUND(MOD(SMALL(FÉRIAS!$K$2:$K$301,6),1)*100000,0),"")
B35: =IF(L35="","",7) | C35: =IF($L35="","",INDEX(FÉRIAS!$A:$A,$L35)&"") | D35: =IF($L35="","",INDEX(FÉRIAS!$B:$B,$L35)&"") | E35: =IF($L35="","",INDEX(FÉRIAS!$C:$C,$L35)) | F35: =IF($L35="","",INDEX(FÉRIAS!$D:$D,$L35)) | G35: =IF($L35="","",INDEX(FÉRIAS!$G:$G,$L35)) | H35: =IF($L35="","",INDEX(FÉRIAS!$D:$D,$L35)-TODAY()) | I35: =IF($L35="","",INDEX(FÉRIAS!$H:$H,$L35)&"") | L35: =IFERROR(ROUND(MOD(SMALL(FÉRIAS!$K$2:$K$301,7),1)*100000,0),"")
B36: =IF(L36="","",8) | C36: =IF($L36="","",INDEX(FÉRIAS!$A:$A,$L36)&"") | D36: =IF($L36="","",INDEX(FÉRIAS!$B:$B,$L36)&"") | E36: =IF($L36="","",INDEX(FÉRIAS!$C:$C,$L36)) | F36: =IF($L36="","",INDEX(FÉRIAS!$D:$D,$L36)) | G36: =IF($L36="","",INDEX(FÉRIAS!$G:$G,$L36)) | H36: =IF($L36="","",INDEX(FÉRIAS!$D:$D,$L36)-TODAY()) | I36: =IF($L36="","",INDEX(FÉRIAS!$H:$H,$L36)&"") | L36: =IFERROR(ROUND(MOD(SMALL(FÉRIAS!$K$2:$K$301,8),1)*100000,0),"")
B37: =IF(L37="","",9) | C37: =IF($L37="","",INDEX(FÉRIAS!$A:$A,$L37)&"") | D37: =IF($L37="","",INDEX(FÉRIAS!$B:$B,$L37)&"") | E37: =IF($L37="","",INDEX(FÉRIAS!$C:$C,$L37)) | F37: =IF($L37="","",INDEX(FÉRIAS!$D:$D,$L37)) | G37: =IF($L37="","",INDEX(FÉRIAS!$G:$G,$L37)) | H37: =IF($L37="","",INDEX(FÉRIAS!$D:$D,$L37)-TODAY()) | I37: =IF($L37="","",INDEX(FÉRIAS!$H:$H,$L37)&"") | L37: =IFERROR(ROUND(MOD(SMALL(FÉRIAS!$K$2:$K$301,9),1)*100000,0),"")
B38: =IF(L38="","",10) | C38: =IF($L38="","",INDEX(FÉRIAS!$A:$A,$L38)&"") | D38: =IF($L38="","",INDEX(FÉRIAS!$B:$B,$L38)&"") | E38: =IF($L38="","",INDEX(FÉRIAS!$C:$C,$L38)) | F38: =IF($L38="","",INDEX(FÉRIAS!$D:$D,$L38)) | G38: =IF($L38="","",INDEX(FÉRIAS!$G:$G,$L38)) | H38: =IF($L38="","",INDEX(FÉRIAS!$D:$D,$L38)-TODAY()) | I38: =IF($L38="","",INDEX(FÉRIAS!$H:$H,$L38)&"") | L38: =IFERROR(ROUND(MOD(SMALL(FÉRIAS!$K$2:$K$301,10),1)*100000,0),"")
B39: =IF($E$8=0,"Ninguém nesta lista.",IF($E$8>10,"... e mais "&($E$8-10)&" — veja a aba FÉRIAS.","")) -> Ninguém nesta lista.
B41: PRÓXIMAS FOLGAS (PRÓXIMOS 7 DIAS)
B42: # | C42: Nome | D42: Setor | E42: Data | F42: Dia | G42: Faltam (dias) | H42: Origem | I42: Alerta
B43: =IF(L43="","",1) | C43: =IF($L43="","",INDEX(AUX!$B:$B,$L43)&"") | D43: =IF($L43="","",INDEX(AUX!$C:$C,$L43)&"") | E43: =IF($L43="","",INDEX(AUX!$D:$D,$L43)) | F43: =IF($L43="","",INDEX(AUX!$J:$J,$L43)&"") | G43: =IF($L43="","",INDEX(AUX!$D:$D,$L43)-TODAY()) | H43: =IF($L43="","",INDEX(AUX!$A:$A,$L43)&"") | I43: =IF($L43="","",INDEX(AUX!$F:$F,$L43)&"") | L43: =IFERROR(ROUND(MOD(SMALL(AUX!$H$2:$H$901,1),1)*100000,0),"")
B44: =IF(L44="","",2) | C44: =IF($L44="","",INDEX(AUX!$B:$B,$L44)&"") | D44: =IF($L44="","",INDEX(AUX!$C:$C,$L44)&"") | E44: =IF($L44="","",INDEX(AUX!$D:$D,$L44)) | F44: =IF($L44="","",INDEX(AUX!$J:$J,$L44)&"") | G44: =IF($L44="","",INDEX(AUX!$D:$D,$L44)-TODAY()) | H44: =IF($L44="","",INDEX(AUX!$A:$A,$L44)&"") | I44: =IF($L44="","",INDEX(AUX!$F:$F,$L44)&"") | L44: =IFERROR(ROUND(MOD(SMALL(AUX!$H$2:$H$901,2),1)*100000,0),"")
B45: =IF(L45="","",3) | C45: =IF($L45="","",INDEX(AUX!$B:$B,$L45)&"") | D45: =IF($L45="","",INDEX(AUX!$C:$C,$L45)&"") | E45: =IF($L45="","",INDEX(AUX!$D:$D,$L45)) | F45: =IF($L45="","",INDEX(AUX!$J:$J,$L45)&"") | G45: =IF($L45="","",INDEX(AUX!$D:$D,$L45)-TODAY()) | H45: =IF($L45="","",INDEX(AUX!$A:$A,$L45)&"") | I45: =IF($L45="","",INDEX(AUX!$F:$F,$L45)&"") | L45: =IFERROR(ROUND(MOD(SMALL(AUX!$H$2:$H$901,3),1)*100000,0),"")
B46: =IF(L46="","",4) | C46: =IF($L46="","",INDEX(AUX!$B:$B,$L46)&"") | D46: =IF($L46="","",INDEX(AUX!$C:$C,$L46)&"") | E46: =IF($L46="","",INDEX(AUX!$D:$D,$L46)) | F46: =IF($L46="","",INDEX(AUX!$J:$J,$L46)&"") | G46: =IF($L46="","",INDEX(AUX!$D:$D,$L46)-TODAY()) | H46: =IF($L46="","",INDEX(AUX!$A:$A,$L46)&"") | I46: =IF($L46="","",INDEX(AUX!$F:$F,$L46)&"") | L46: =IFERROR(ROUND(MOD(SMALL(AUX!$H$2:$H$901,4),1)*100000,0),"")
B47: =IF(L47="","",5) | C47: =IF($L47="","",INDEX(AUX!$B:$B,$L47)&"") | D47: =IF($L47="","",INDEX(AUX!$C:$C,$L47)&"") | E47: =IF($L47="","",INDEX(AUX!$D:$D,$L47)) | F47: =IF($L47="","",INDEX(AUX!$J:$J,$L47)&"") | G47: =IF($L47="","",INDEX(AUX!$D:$D,$L47)-TODAY()) | H47: =IF($L47="","",INDEX(AUX!$A:$A,$L47)&"") | I47: =IF($L47="","",INDEX(AUX!$F:$F,$L47)&"") | L47: =IFERROR(ROUND(MOD(SMALL(AUX!$H$2:$H$901,5),1)*100000,0),"")
...

Sheet CALENDÁRIO
B2: CALENDÁRIO DE AUSÊNCIAS | J2: QUEM ESTÁ AUSENTE NO DIA?
O3: =IF(AND(ISNUMBER(F4),F4>=1900),F4,YEAR(TODAY())) -> 2026
B4: Mês: | C4: =INDEX(LISTAS!$D$2:$D$13,MONTH(TODAY())) -> Outubro | E4: Ano: | F4: =YEAR(TODAY()) -> 2026 | G4: ← mude para ver outros meses | J4: Digite a data: | L4: =TODAY() -> 46301 | M4: =IF(ISNUMBER(L4),CHOOSE(WEEKDAY(L4),"Domingo","Segunda","Terça","Quarta","Quinta","Sexta","Sábado"),"") -> Terça | O4: =IFERROR(MATCH(C4,LISTAS!$D$2:$D$13,0),MONTH(TODAY())) -> 10
O5: =DATE(O3,O4,1)-WEEKDAY(DATE(O3,O4,1))+1 -> 46292
B6: Domingo | C6: Segunda | D6: Terça | E6: Quarta | F6: Quinta | G6: Sexta | H6: Sábado | J6: # | K6: Nome | L6: Setor | M6: Tipo | O6: =COUNT(AUX!$I$2:$I$901) -> 0
B7: =$O$5+0 -> 46292 | C7: =$O$5+1 -> 46293 | D7: =$O$5+2 -> 46294 | E7: =$O$5+3 -> 46295 | F7: =$O$5+4 -> 46296 | G7: =$O$5+5 -> 46297 | H7: =$O$5+6 -> 46298 | J7: =IF(P7="","",1) | K7: =IF(P7="","",IF(1<=$O$6,INDEX(AUX!$B:$B,P7),INDEX(FÉRIAS!$A:$A,P7))&"") | L7: =IF(P7="","",IF(1<=$O$6,INDEX(AUX!$C:$C,P7),INDEX(FÉRIAS!$B:$B,P7))&"") | M7: =IF(P7="","",IF(1<=$O$6,INDEX(AUX!$A:$A,P7),"Férias")) | O7: =COUNT(FÉRIAS!$M$2:$M$301) -> 0 | P7: =IF(1>$O$6+$O$7,"",IF(1<=$O$6,SMALL(AUX!$I$2:$I$901,1),SMALL(FÉRIAS!$M$2:$M$301,1-$O$6)))
B8: =IF(MONTH(B7)<>$O$4,"",IF(COUNTIF(AUX!$D$2:$D$901,B7)+COUNTIFS(FÉRIAS!$C$2:$C$301,"<="&B7,FÉRIAS!$D$2:$D$301,">="&B7)=0,"",IF(COUNTIF(AUX!$D$2:$D$901,B7)>0,"Folga: "&COUNTIF(AUX!$D$2:$D$901,B7),"")&IF(AND(COUNTIF(AUX!$D$2:$D$901,B7)>0,COUNTIFS(FÉRIAS!$C$2:$C$301,"<="&B7,FÉRIAS!$D$2:$D$301,">="&B7)>0),CHAR(10),"")&IF(COUNTIFS(FÉRIAS!$C$2:$C$301,"<="&B7,FÉRIAS!$D$2:$D$301,">="&B7)>0,"Férias: "&COUNTIFS(FÉRIAS!$C$2:$C$301,"<="&B7,FÉRIAS!$D$2:$D$301,">="&B7),""))) | C8: =IF(MONTH(C7)<>$O$4,"",IF(COUNTIF(AUX!$D$2:$D$901,C7)+COUNTIFS(FÉRIAS!$C$2:$C$301,"<="&C7,FÉRIAS!$D$2:$D$301,">="&C7)=0,"",IF(COUNTIF(AUX!$D$2:$D$901,C7)>0,"Folga: "&COUNTIF(AUX!$D$2:$D$901,C7),"")&IF(AND(COUNTIF(AUX!$D$2:$D$901,C7)>0,COUNTIFS(FÉRIAS!$C$2:$C$301,"<="&C7,FÉRIAS!$D$2:$D$301,">="&C7)>0),CHAR(10),"")&IF(COUNTIFS(FÉRIAS!$C$2:$C$301,"<="&C7,FÉRIAS!$D$2:$D$301,">="&C7)>0,"Férias: "&COUNTIFS(FÉRIAS!$C$2:$C$301,"<="&C7,FÉRIAS!$D$2:$D$301,">="&C7),""))) | D8: =IF(MONTH(D7)<>$O$4,"",IF(COUNTIF(AUX!$D$2:$D$901,D7)+COUNTIFS(FÉRIAS!$C$2:$C$301,"<="&D7,FÉRIAS!$D$2:$D$301,">="&D7)=0,"",IF(COUNTIF(AUX!$D$2:$D$901,D7)>0,"Folga: "&COUNTIF(AUX!$D$2:$D$901,D7),"")&IF(AND(COUNTIF(AUX!$D$2:$D$901,D7)>0,COUNTIFS(FÉRIAS!$C$2:$C$301,"<="&D7,FÉRIAS!$D$2:$D$301,">="&D7)>0),CHAR(10),"")&IF(COUNTIFS(FÉRIAS!$C$2:$C$301,"<="&D7,FÉRIAS!$D$2:$D$301,">="&D7)>0,"Férias: "&COUNTIFS(FÉRIAS!$C$2:$C$301,"<="&D7,FÉRIAS!$D$2:$D$301,">="&D7),""))) | E8: =IF(MONTH(E7)<>$O$4,"",IF(COUNTIF(AUX!$D$2:$D$901,E7)+COUNTIFS(FÉRIAS!$C$2:$C$301,"<="&E7,FÉRIAS!$D$2:$D$301,">="&E7)=0,"",IF(COUNTIF(AUX!$D$2:$D$901,E7)>0,"Folga: "&COUNTIF(AUX!$D$2:$D$901,E7),"")&IF(AND(COUNTIF(AUX!$D$2:$D$901,E7)>0,COUNTIFS(FÉRIAS!$C$2:$C$301,"<="&E7,FÉRIAS!$D$2:$D$301,">="&E7)>0),CHAR(10),"")&IF(COUNTIFS(FÉRIAS!$C$2:$C$301,"<="&E7,FÉRIAS!$D$2:$D$301,">="&E7)>0,"Férias: "&COUNTIFS(FÉRIAS!$C$2:$C$301,"<="&E7,FÉRIAS!$D$2:$D$301,">="&E7),""))) | F8: =IF(MONTH(F7)<>$O$4,"",IF(COUNTIF(AUX!$D$2:$D$901,F7)+COUNTIFS(FÉRIAS!$C$2:$C$301,"<="&F7,FÉRIAS!$D$2:$D$301,">="&F7)=0,"",IF(COUNTIF(AUX!$D$2:$D$901,F7)>0,"Folga: "&COUNTIF(AUX!$D$2:$D$901,F7),"")&IF(AND(COUNTIF(AUX!$D$2:$D$901,F7)>0,COUNTIFS(FÉRIAS!$C$2:$C$301,"<="&F7,FÉRIAS!$D$2:$D$301,">="&F7)>0),CHAR(10),"")&IF(COUNTIFS(FÉRIAS!$C$2:$C$301,"<="&F7,FÉRIAS!$D$2:$D$301,">="&F7)>0,"Férias: "&COUNTIFS(FÉRIAS!$C$2:$C$301,"<="&F7,FÉRIAS!$D$2:$D$301,">="&F7),""))) | G8: =IF(MONTH(G7)<>$O$4,"",IF(COUNTIF(AUX!$D$2:$D$901,G7)+COUNTIFS(FÉRIAS!$C$2:$C$301,"<="&G7,FÉRIAS!$D$2:$D$301,">="&G7)=0,"",IF(COUNTIF(AUX!$D$2:$D$901,G7)>0,"Folga: "&COUNTIF(AUX!$D$2:$D$901,G7),"")&IF(AND(COUNTIF(AUX!$D$2:$D$901,G7)>0,COUNTIFS(FÉRIAS!$C$2:$C$301,"<="&G7,FÉRIAS!$D$2:$D$301,">="&G7)>0),CHAR(10),"")&IF(COUNTIFS(FÉRIAS!$C$2:$C$301,"<="&G7,FÉRIAS!$D$2:$D$301,">="&G7)>0,"Férias: "&COUNTIFS(FÉRIAS!$C$2:$C$301,"<="&G7,FÉRIAS!$D$2:$D$301,">="&G7),""))) | H8: =IF(MONTH(H7)<>$O$4,"",IF(COUNTIF(AUX!$D$2:$D$901,H7)+COUNTIFS(FÉRIAS!$C$2:$C$301,"<="&H7,FÉRIAS!$D$2:$D$301,">="&H7)=0,"",IF(COUNTIF(AUX!$D$2:$D$901,H7)>0,"Folga: "&COUNTIF(AUX!$D$2:$D$901,H7),"")&IF(AND(COUNTIF(AUX!$D$2:$D$901,H7)>0,COUNTIFS(FÉRIAS!$C$2:$C$301,"<="&H7,FÉRIAS!$D$2:$D$301,">="&H7)>0),CHAR(10),"")&IF(COUNTIFS(FÉRIAS!$C$2:$C$301,"<="&H7,FÉRIAS!$D$2:$D$301,">="&H7)>0,"Férias: "&COUNTIFS(FÉRIAS!$C$2:$C$301,"<="&H7,FÉRIAS!$D$2:$D$301,">="&H7),""))) | J8: =IF(P8="","",2) | K8: =IF(P8="","",IF(2<=$O$6,INDEX(AUX!$B:$B,P8),INDEX(FÉRIAS!$A:$A,P8))&"") | L8: =IF(P8="","",IF(2<=$O$6,INDEX(AUX!$C:$C,P8),INDEX(FÉRIAS!$B:$B,P8))&"") | M8: =IF(P8="","",IF(2<=$O$6,INDEX(AUX!$A:$A,P8),"Férias")) | P8: =IF(2>$O$6+$O$7,"",IF(2<=$O$6,SMALL(AUX!$I$2:$I$901,2),SMALL(FÉRIAS!$M$2:$M$301,2-$O$6)))
B9: =$O$5+7 -> 46299 | C9: =$O$5+8 -> 46300 | D9: =$O$5+9 -> 46301 | E9: =$O$5+10 -> 46302 | F9: =$O$5+11 -> 46303 | G9: =$O$5+12 -> 46304 | H9: =$O$5+13 -> 46305 | J9: =IF(P9="","",3) | K9: =IF(P9="","",IF(3<=$O$6,INDEX(AUX!$B:$B,P9),INDEX(FÉRIAS!$A:$A,P9))&"") | L9: =IF(P9="","",IF(3<=$O$6,INDEX(AUX!$C:$C,P9),INDEX(FÉRIAS!$B:$B,P9))&"") | M9: =IF(P9="","",IF(3<=$O$6,INDEX(AUX!$A:$A,P9),"Férias")) | P9: =IF(3>$O$6+$O$7,"",IF(3<=$O$6,SMALL(AUX!$I$2:$I$901,3),SMALL(FÉRIAS!$M$2:$M$301,3-$O$6)))
B10: =IF(MONTH(B9)<>$O$4,"",IF(COUNTIF(AUX!$D$2:$D$901,B9)+COUNTIFS(FÉRIAS!$C$2:$C$301,"<="&B9,FÉRIAS!$D$2:$D$301,">="&B9)=0,"",IF(COUNTIF(AUX!$D$2:$D$901,B9)>0,"Folga: "&COUNTIF(AUX!$D$2:$D$901,B9),"")&IF(AND(COUNTIF(AUX!$D$2:$D$901,B9)>0,COUNTIFS(FÉRIAS!$C$2:$C$301,"<="&B9,FÉRIAS!$D$2:$D$301,">="&B9)>0),CHAR(10),"")&IF(COUNTIFS(FÉRIAS!$C$2:$C$301,"<="&B9,FÉRIAS!$D$2:$D$301,">="&B9)>0,"Férias: "&COUNTIFS(FÉRIAS!$C$2:$C$301,"<="&B9,FÉRIAS!$D$2:$D$301,">="&B9),""))) | C10: =IF(MONTH(C9)<>$O$4,"",IF(COUNTIF(AUX!$D$2:$D$901,C9)+COUNTIFS(FÉRIAS!$C$2:$C$301,"<="&C9,FÉRIAS!$D$2:$D$301,">="&C9)=0,"",IF(COUNTIF(AUX!$D$2:$D$901,C9)>0,"Folga: "&COUNTIF(AUX!$D$2:$D$901,C9),"")&IF(AND(COUNTIF(AUX!$D$2:$D$901,C9)>0,COUNTIFS(FÉRIAS!$C$2:$C$301,"<="&C9,FÉRIAS!$D$2:$D$301,">="&C9)>0),CHAR(10),"")&IF(COUNTIFS(FÉRIAS!$C$2:$C$301,"<="&C9,FÉRIAS!$D$2:$D$301,">="&C9)>0,"Férias: "&COUNTIFS(FÉRIAS!$C$2:$C$301,"<="&C9,FÉRIAS!$D$2:$D$301,">="&C9),""))) | D10: =IF(MONTH(D9)<>$O$4,"",IF(COUNTIF(AUX!$D$2:$D$901,D9)+COUNTIFS(FÉRIAS!$C$2:$C$301,"<="&D9,FÉRIAS!$D$2:$D$301,">="&D9)=0,"",IF(COUNTIF(AUX!$D$2:$D$901,D9)>0,"Folga: "&COUNTIF(AUX!$D$2:$D$901,D9),"")&IF(AND(COUNTIF(AUX!$D$2:$D$901,D9)>0,COUNTIFS(FÉRIAS!$C$2:$C$301,"<="&D9,FÉRIAS!$D$2:$D$301,">="&D9)>0),CHAR(10),"")&IF(COUNTIFS(FÉRIAS!$C$2:$C$301,"<="&D9,FÉRIAS!$D$2:$D$301,">="&D9)>0,"Férias: "&COUNTIFS(FÉRIAS!$C$2:$C$301,"<="&D9,FÉRIAS!$D$2:$D$301,">="&D9),""))) | E10: =IF(MONTH(E9)<>$O$4,"",IF(COUNTIF(AUX!$D$2:$D$901,E9)+COUNTIFS(FÉRIAS!$C$2:$C$301,"<="&E9,FÉRIAS!$D$2:$D$301,">="&E9)=0,"",IF(COUNTIF(AUX!$D$2:$D$901,E9)>0,"Folga: "&COUNTIF(AUX!$D$2:$D$901,E9),"")&IF(AND(COUNTIF(AUX!$D$2:$D$901,E9)>0,COUNTIFS(FÉRIAS!$C$2:$C$301,"<="&E9,FÉRIAS!$D$2:$D$301,">="&E9)>0),CHAR(10),"")&IF(COUNTIFS(FÉRIAS!$C$2:$C$301,"<="&E9,FÉRIAS!$D$2:$D$301,">="&E9)>0,"Férias: "&COUNTIFS(FÉRIAS!$C$2:$C$301,"<="&E9,FÉRIAS!$D$2:$D$301,">="&E9),""))) | F10: =IF(MONTH(F9)<>$O$4,"",IF(COUNTIF(AUX!$D$2:$D$901,F9)+COUNTIFS(FÉRIAS!$C$2:$C$301,"<="&F9,FÉRIAS!$D$2:$D$301,">="&F9)=0,"",IF(COUNTIF(AUX!$D$2:$D$901,F9)>0,"Folga: "&COUNTIF(AUX!$D$2:$D$901,F9),"")&IF(AND(COUNTIF(AUX!$D$2:$D$901,F9)>0,COUNTIFS(FÉRIAS!$C$2:$C$301,"<="&F9,FÉRIAS!$D$2:$D$301,">="&F9)>0),CHAR(10),"")&IF(COUNTIFS(FÉRIAS!$C$2:$C$301,"<="&F9,FÉRIAS!$D$2:$D$301,">="&F9)>0,"Férias: "&COUNTIFS(FÉRIAS!$C$2:$C$301,"<="&F9,FÉRIAS!$D$2:$D$301,">="&F9),""))) | G10: =IF(MONTH(G9)<>$O$4,"",IF(COUNTIF(AUX!$D$2:$D$901,G9)+COUNTIFS(FÉRIAS!$C$2:$C$301,"<="&G9,FÉRIAS!$D$2:$D$301,">="&G9)=0,"",IF(COUNTIF(AUX!$D$2:$D$901,G9)>0,"Folga: "&COUNTIF(AUX!$D$2:$D$901,G9),"")&IF(AND(COUNTIF(AUX!$D$2:$D$901,G9)>0,COUNTIFS(FÉRIAS!$C$2:$C$301,"<="&G9,FÉRIAS!$D$2:$D$301,">="&G9)>0),CHAR(10),"")&IF(COUNTIFS(FÉRIAS!$C$2:$C$301,"<="&G9,FÉRIAS!$D$2:$D$301,">="&G9)>0,"Férias: "&COUNTIFS(FÉRIAS!$C$2:$C$301,"<="&G9,FÉRIAS!$D$2:$D$301,">="&G9),""))) | H10: =IF(MONTH(H9)<>$O$4,"",IF(COUNTIF(AUX!$D$2:$D$901,H9)+COUNTIFS(FÉRIAS!$C$2:$C$301,"<="&H9,FÉRIAS!$D$2:$D$301,">="&H9)=0,"",IF(COUNTIF(AUX!$D$2:$D$901,H9)>0,"Folga: "&COUNTIF(AUX!$D$2:$D$901,H9),"")&IF(AND(COUNTIF(AUX!$D$2:$D$901,H9)>0,COUNTIFS(FÉRIAS!$C$2:$C$301,"<="&H9,FÉRIAS!$D$2:$D$301,">="&H9)>0),CHAR(10),"")&IF(COUNTIFS(FÉRIAS!$C$2:$C$301,"<="&H9,FÉRIAS!$D$2:$D$301,">="&H9)>0,"Férias: "&COUNTIFS(FÉRIAS!$C$2:$C$301,"<="&H9,FÉRIAS!$D$2:$D$301,">="&H9),""))) | J10: =IF(P10="","",4) | K10: =IF(P10="","",IF(4<=$O$6,INDEX(AUX!$B:$B,P10),INDEX(FÉRIAS!$A:$A,P10))&"") | L10: =IF(P10="","",IF(4<=$O$6,INDEX(AUX!$C:$C,P10),INDEX(FÉRIAS!$B:$B,P10))&"") | M10: =IF(P10="","",IF(4<=$O$6,INDEX(AUX!$A:$A,P10),"Férias")) | P10: =IF(4>$O$6+$O$7,"",IF(4<=$O$6,SMALL(AUX!$I$2:$I$901,4),SMALL(FÉRIAS!$M$2:$M$301,4-$O$6)))
B11: =$O$5+14 -> 46306 | C11: =$O$5+15 -> 46307 | D11: =$O$5+16 -> 46308 | E11: =$O$5+17 -> 46309 | F11: =$O$5+18 -> 46310 | G11: =$O$5+19 -> 46311 | H11: =$O$5+20 -> 46312 | J11: =IF(P11="","",5) | K11: =IF(P11="","",IF(5<=$O$6,INDEX(AUX!$B:$B,P11),INDEX(FÉRIAS!$A:$A,P11))&"") | L11: =IF(P11="","",IF(5<=$O$6,INDEX(AUX!$C:$C,P11),INDEX(FÉRIAS!$B:$B,P11))&"") | M11: =IF(P11="","",IF(5<=$O$6,INDEX(AUX!$A:$A,P11),"Férias")) | P11: =IF(5>$O$6+$O$7,"",IF(5<=$O$6,SMALL(AUX!$I$2:$I$901,5),SMALL(FÉRIAS!$M$2:$M$301,5-$O$6)))
B12: =IF(MONTH(B11)<>$O$4,"",IF(COUNTIF(AUX!$D$2:$D$901,B11)+COUNTIFS(FÉRIAS!$C$2:$C$301,"<="&B11,FÉRIAS!$D$2:$D$301,">="&B11)=0,"",IF(COUNTIF(AUX!$D$2:$D$901,B11)>0,"Folga: "&COUNTIF(AUX!$D$2:$D$901,B11),"")&IF(AND(COUNTIF(AUX!$D$2:$D$901,B11)>0,COUNTIFS(FÉRIAS!$C$2:$C$301,"<="&B11,FÉRIAS!$D$2:$D$301,">="&B11)>0),CHAR(10),"")&IF(COUNTIFS(FÉRIAS!$C$2:$C$301,"<="&B11,FÉRIAS!$D$2:$D$301,">="&B11)>0,"Férias: "&COUNTIFS(FÉRIAS!$C$2:$C$301,"<="&B11,FÉRIAS!$D$2:$D$301,">="&B11),""))) | C12: =IF(MONTH(C11)<>$O$4,"",IF(COUNTIF(AUX!$D$2:$D$901,C11)+COUNTIFS(FÉRIAS!$C$2:$C$301,"<="&C11,FÉRIAS!$D$2:$D$301,">="&C11)=0,"",IF(COUNTIF(AUX!$D$2:$D$901,C11)>0,"Folga: "&COUNTIF(AUX!$D$2:$D$901,C11),"")&IF(AND(COUNTIF(AUX!$D$2:$D$901,C11)>0,COUNTIFS(FÉRIAS!$C$2:$C$301,"<="&C11,FÉRIAS!$D$2:$D$301,">="&C11)>0),CHAR(10),"")&IF(COUNTIFS(FÉRIAS!$C$2:$C$301,"<="&C11,FÉRIAS!$D$2:$D$301,">="&C11)>0,"Férias: "&COUNTIFS(FÉRIAS!$C$2:$C$301,"<="&C11,FÉRIAS!$D$2:$D$301,">="&C11),""))) | D12: =IF(MONTH(D11)<>$O$4,"",IF(COUNTIF(AUX!$D$2:$D$901,D11)+COUNTIFS(FÉRIAS!$C$2:$C$301,"<="&D11,FÉRIAS!$D$2:$D$301,">="&D11)=0,"",IF(COUNTIF(AUX!$D$2:$D$901,D11)>0,"Folga: "&COUNTIF(AUX!$D$2:$D$901,D11),"")&IF(AND(COUNTIF(AUX!$D$2:$D$901,D11)>0,COUNTIFS(FÉRIAS!$C$2:$C$301,"<="&D11,FÉRIAS!$D$2:$D$301,">="&D11)>0),CHAR(10),"")&IF(COUNTIFS(FÉRIAS!$C$2:$C$301,"<="&D11,FÉRIAS!$D$2:$D$301,">="&D11)>0,"Férias: "&COUNTIFS(FÉRIAS!$C$2:$C$301,"<="&D11,FÉRIAS!$D$2:$D$301,">="&D11),""))) -> Férias: 1 | E12: =IF(MONTH(E11)<>$O$4,"",IF(COUNTIF(AUX!$D$2:$D$901,E11)+COUNTIFS(FÉRIAS!$C$2:$C$301,"<="&E11,FÉRIAS!$D$2:$D$301,">="&E11)=0,"",IF(COUNTIF(AUX!$D$2:$D$901,E11)>0,"Folga: "&COUNTIF(AUX!$D$2:$D$901,E11),"")&IF(AND(COUNTIF(AUX!$D$2:$D$901,E11)>0,COUNTIFS(FÉRIAS!$C$2:$C$301,"<="&E11,FÉRIAS!$D$2:$D$301,">="&E11)>0),CHAR(10),"")&IF(COUNTIFS(FÉRIAS!$C$2:$C$301,"<="&E11,FÉRIAS!$D$2:$D$301,">="&E11)>0,"Férias: "&COUNTIFS(FÉRIAS!$C$2:$C$301,"<="&E11,FÉRIAS!$D$2:$D$301,">="&E11),""))) -> Férias: 1 | F12: =IF(MONTH(F11)<>$O$4,"",IF(COUNTIF(AUX!$D$2:$D$901,F11)+COUNTIFS(FÉRIAS!$C$2:$C$301,"<="&F11,FÉRIAS!$D$2:$D$301,">="&F11)=0,"",IF(COUNTIF(AUX!$D$2:$D$901,F11)>0,"Folga: "&COUNTIF(AUX!$D$2:$D$901,F11),"")&IF(AND(COUNTIF(AUX!$D$2:$D$901,F11)>0,COUNTIFS(FÉRIAS!$C$2:$C$301,"<="&F11,FÉRIAS!$D$2:$D$301,">="&F11)>0),CHAR(10),"")&IF(COUNTIFS(FÉRIAS!$C$2:$C$301,"<="&F11,FÉRIAS!$D$2:$D$301,">="&F11)>0,"Férias: "&COUNTIFS(FÉRIAS!$C$2:$C$301,"<="&F11,FÉRIAS!$D$2:$D$301,">="&F11),""))) -> Férias: 1 | G12: =IF(MONTH(G11)<>$O$4,"",IF(COUNTIF(AUX!$D$2:$D$901,G11)+COUNTIFS(FÉRIAS!$C$2:$C$301,"<="&G11,FÉRIAS!$D$2:$D$301,">="&G11)=0,"",IF(COUNTIF(AUX!$D$2:$D$901,G11)>0,"Folga: "&COUNTIF(AUX!$D$2:$D$901,G11),"")&IF(AND(COUNTIF(AUX!$D$2:$D$901,G11)>0,COUNTIFS(FÉRIAS!$C$2:$C$301,"<="&G11,FÉRIAS!$D$2:$D$301,">="&G11)>0),CHAR(10),"")&IF(COUNTIFS(FÉRIAS!$C$2:$C$301,"<="&G11,FÉRIAS!$D$2:$D$301,">="&G11)>0,"Férias: "&COUNTIFS(FÉRIAS!$C$2:$C$301,"<="&G11,FÉRIAS!$D$2:$D$301,">="&G11),""))) -> Férias: 1 | H12: =IF(MONTH(H11)<>$O$4,"",IF(COUNTIF(AUX!$D$2:$D$901,H11)+COUNTIFS(FÉRIAS!$C$2:$C$301,"<="&H11,FÉRIAS!$D$2:$D$301,">="&H11)=0,"",IF(COUNTIF(AUX!$D$2:$D$901,H11)>0,"Folga: "&COUNTIF(AUX!$D$2:$D$901,H11),"")&IF(AND(COUNTIF(AUX!$D$2:$D$901,H11)>0,COUNTIFS(FÉRIAS!$C$2:$C$301,"<="&H11,FÉRIAS!$D$2:$D$301,">="&H11)>0),CHAR(10),"")&IF(COUNTIFS(FÉRIAS!$C$2:$C$301,"<="&H11,FÉRIAS!$D$2:$D$301,">="&H11)>0,"Férias: "&COUNTIFS(FÉRIAS!$C$2:$C$301,"<="&H11,FÉRIAS!$D$2:$D$301,">="&H11),""))) | J12: =IF(P12="","",6) | K12: =IF(P12="","",IF(6<=$O$6,INDEX(AUX!$B:$B,P12),INDEX(FÉRIAS!$A:$A,P12))&"") | L12: =IF(P12="","",IF(6<=$O$6,INDEX(AUX!$C:$C,P12),INDEX(FÉRIAS!$B:$B,P12))&"") | M12: =IF(P12="","",IF(6<=$O$6,INDEX(AUX!$A:$A,P12),"Férias")) | P12: =IF(6>$O$6+$O$7,"",IF(6<=$O$6,SMALL(AUX!$I$2:$I$901,6),SMALL(FÉRIAS!$M$2:$M$301,6-$O$6)))
B13: =$O$5+21 -> 46313 | C13: =$O$5+22 -> 46314 | D13: =$O$5+23 -> 46315 | E13: =$O$5+24 -> 46316 | F13: =$O$5+25 -> 46317 | G13: =$O$5+26 -> 46318 | H13: =$O$5+27 -> 46319 | J13: =IF(P13="","",7) | K13: =IF(P13="","",IF(7<=$O$6,INDEX(AUX!$B:$B,P13),INDEX(FÉRIAS!$A:$A,P13))&"") | L13: =IF(P13="","",IF(7<=$O$6,INDEX(AUX!$C:$C,P13),INDEX(FÉRIAS!$B:$B,P13))&"") | M13: =IF(P13="","",IF(7<=$O$6,INDEX(AUX!$A:$A,P13),"Férias")) | P13: =IF(7>$O$6+$O$7,"",IF(7<=$O$6,SMALL(AUX!$I$2:$I$901,7),SMALL(FÉRIAS!$M$2:$M$301,7-$O$6)))
B14: =IF(MONTH(B13)<>$O$4,"",IF(COUNTIF(AUX!$D$2:$D$901,B13)+COUNTIFS(FÉRIAS!$C$2:$C$301,"<="&B13,FÉRIAS!$D$2:$D$301,">="&B13)=0,"",IF(COUNTIF(AUX!$D$2:$D$901,B13)>0,"Folga: "&COUNTIF(AUX!$D$2:$D$901,B13),"")&IF(AND(COUNTIF(AUX!$D$2:$D$901,B13)>0,COUNTIFS(FÉRIAS!$C$2:$C$301,"<="&B13,FÉRIAS!$D$2:$D$301,">="&B13)>0),CHAR(10),"")&IF(COUNTIFS(FÉRIAS!$C$2:$C$301,"<="&B13,FÉRIAS!$D$2:$D$301,">="&B13)>0,"Férias: "&COUNTIFS(FÉRIAS!$C$2:$C$301,"<="&B13,FÉRIAS!$D$2:$D$301,">="&B13),""))) | C14: =IF(MONTH(C13)<>$O$4,"",IF(COUNTIF(AUX!$D$2:$D$901,C13)+COUNTIFS(FÉRIAS!$C$2:$C$301,"<="&C13,FÉRIAS!$D$2:$D$301,">="&C13)=0,"",IF(COUNTIF(AUX!$D$2:$D$901,C13)>0,"Folga: "&COUNTIF(AUX!$D$2:$D$901,C13),"")&IF(AND(COUNTIF(AUX!$D$2:$D$901,C13)>0,COUNTIFS(FÉRIAS!$C$2:$C$301,"<="&C13,FÉRIAS!$D$2:$D$301,">="&C13)>0),CHAR(10),"")&IF(COUNTIFS(FÉRIAS!$C$2:$C$301,"<="&C13,FÉRIAS!$D$2:$D$301,">="&C13)>0,"Férias: "&COUNTIFS(FÉRIAS!$C$2:$C$301,"<="&C13,FÉRIAS!$D$2:$D$301,">="&C13),""))) -> Férias: 1 | D14: =IF(MONTH(D13)<>$O$4,"",IF(COUNTIF(AUX!$D$2:$D$901,D13)+COUNTIFS(FÉRIAS!$C$2:$C$301,"<="&D13,FÉRIAS!$D$2:$D$301,">="&D13)=0,"",IF(COUNTIF(AUX!$D$2:$D$901,D13)>0,"Folga: "&COUNTIF(AUX!$D$2:$D$901,D13),"")&IF(AND(COUNTIF(AUX!$D$2:$D$901,D13)>0,COUNTIFS(FÉRIAS!$C$2:$C$301,"<="&D13,FÉRIAS!$D$2:$D$301,">="&D13)>0),CHAR(10),"")&IF(COUNTIFS(FÉRIAS!$C$2:$C$301,"<="&D13,FÉRIAS!$D$2:$D$301,">="&D13)>0,"Férias: "&COUNTIFS(FÉRIAS!$C$2:$C$301,"<="&D13,FÉRIAS!$D$2:$D$301,">="&D13),""))) -> Férias: 1 | E14: =IF(MONTH(E13)<>$O$4,"",IF(COUNTIF(AUX!$D$2:$D$901,E13)+COUNTIFS(FÉRIAS!$C$2:$C$301,"<="&E13,FÉRIAS!$D$2:$D$301,">="&E13)=0,"",IF(COUNTIF(AUX!$D$2:$D$901,E13)>0,"Folga: "&COUNTIF(AUX!$D$2:$D$901,E13),"")&IF(AND(COUNTIF(AUX!$D$2:$D$901,E13)>0,COUNTIFS(FÉRIAS!$C$2:$C$301,"<="&E13,FÉRIAS!$D$2:$D$301,">="&E13)>0),CHAR(10),"")&IF(COUNTIFS(FÉRIAS!$C$2:$C$301,"<="&E13,FÉRIAS!$D$2:$D$301,">="&E13)>0,"Férias: "&COUNTIFS(FÉRIAS!$C$2:$C$301,"<="&E13,FÉRIAS!$D$2:$D$301,">="&E13),""))) -> Férias: 1 | F14: =IF(MONTH(F13)<>$O$4,"",IF(COUNTIF(AUX!$D$2:$D$901,F13)+COUNTIFS(FÉRIAS!$C$2:$C$301,"<="&F13,FÉRIAS!$D$2:$D$301,">="&F13)=0,"",IF(COUNTIF(AUX!$D$2:$D$901,F13)>0,"Folga: "&COUNTIF(AUX!$D$2:$D$901,F13),"")&IF(AND(COUNTIF(AUX!$D$2:$D$901,F13)>0,COUNTIFS(FÉRIAS!$C$2:$C$301,"<="&F13,FÉRIAS!$D$2:$D$301,">="&F13)>0),CHAR(10),"")&IF(COUNTIFS(FÉRIAS!$C$2:$C$301,"<="&F13,FÉRIAS!$D$2:$D$301,">="&F13)>0,"Férias: "&COUNTIFS(FÉRIAS!$C$2:$C$301,"<="&F13,FÉRIAS!$D$2:$D$301,">="&F13),""))) -> Férias: 1 | G14: =IF(MONTH(G13)<>$O$4,"",IF(COUNTIF(AUX!$D$2:$D$901,G13)+COUNTIFS(FÉRIAS!$C$2:$C$301,"<="&G13,FÉRIAS!$D$2:$D$301,">="&G13)=0,"",IF(COUNTIF(AUX!$D$2:$D$901,G13)>0,"Folga: "&COUNTIF(AUX!$D$2:$D$901,G13),"")&IF(AND(COUNTIF(AUX!$D$2:$D$901,G13)>0,COUNTIFS(FÉRIAS!$C$2:$C$301,"<="&G13,FÉRIAS!$D$2:$D$301,">="&G13)>0),CHAR(10),"")&IF(COUNTIFS(FÉRIAS!$C$2:$C$301,"<="&G13,FÉRIAS!$D$2:$D$301,">="&G13)>0,"Férias: "&COUNTIFS(FÉRIAS!$C$2:$C$301,"<="&G13,FÉRIAS!$D$2:$D$301,">="&G13),""))) -> Férias: 1 | H14: =IF(MONTH(H13)<>$O$4,"",IF(COUNTIF(AUX!$D$2:$D$901,H13)+COUNTIFS(FÉRIAS!$C$2:$C$301,"<="&H13,FÉRIAS!$D$2:$D$301,">="&H13)=0,"",IF(COUNTIF(AUX!$D$2:$D$901,H13)>0,"Folga: "&COUNTIF(AUX!$D$2:$D$901,H13),"")&IF(AND(COUNTIF(AUX!$D$2:$D$901,H13)>0,COUNTIFS(FÉRIAS!$C$2:$C$301,"<="&H13,FÉRIAS!$D$2:$D$301,">="&H13)>0),CHAR(10),"")&IF(COUNTIFS(FÉRIAS!$C$2:$C$301,"<="&H13,FÉRIAS!$D$2:$D$301,">="&H13)>0,"Férias: "&COUNTIFS(FÉRIAS!$C$2:$C$301,"<="&H13,FÉRIAS!$D$2:$D$301,">="&H13),""))) -> Férias: 1 | J14: =IF(P14="","",8) | K14: =IF(P14="","",IF(8<=$O$6,INDEX(AUX!$B:$B,P14),INDEX(FÉRIAS!$A:$A,P14))&"") | L14: =IF(P14="","",IF(8<=$O$6,INDEX(AUX!$C:$C,P14),INDEX(FÉRIAS!$B:$B,P14))&"") | M14: =IF(P14="","",IF(8<=$O$6,INDEX(AUX!$A:$A,P14),"Férias")) | P14: =IF(8>$O$6+$O$7,"",IF(8<=$O$6,SMALL(AUX!$I$2:$I$901,8),SMALL(FÉRIAS!$M$2:$M$301,8-$O$6)))
B15: =$O$5+28 -> 46320 | C15: =$O$5+29 -> 46321 | D15: =$O$5+30 -> 46322 | E15: =$O$5+31 -> 46323 | F15: =$O$5+32 -> 46324 | G15: =$O$5+33 -> 46325 | H15: =$O$5+34 -> 46326 | J15: =IF(P15="","",9) | K15: =IF(P15="","",IF(9<=$O$6,INDEX(AUX!$B:$B,P15),INDEX(FÉRIAS!$A:$A,P15))&"") | L15: =IF(P15="","",IF(9<=$O$6,INDEX(AUX!$C:$C,P15),INDEX(FÉRIAS!$B:$B,P15))&"") | M15: =IF(P15="","",IF(9<=$O$6,INDEX(AUX!$A:$A,P15),"Férias")) | P15: =IF(9>$O$6+$O$7,"",IF(9<=$O$6,SMALL(AUX!$I$2:$I$901,9),SMALL(FÉRIAS!$M$2:$M$301,9-$O$6)))
B16: =IF(MONTH(B15)<>$O$4,"",IF(COUNTIF(AUX!$D$2:$D$901,B15)+COUNTIFS(FÉRIAS!$C$2:$C$301,"<="&B15,FÉRIAS!$D$2:$D$301,">="&B15)=0,"",IF(COUNTIF(AUX!$D$2:$D$901,B15)>0,"Folga: "&COUNTIF(AUX!$D$2:$D$901,B15),"")&IF(AND(COUNTIF(AUX!$D$2:$D$901,B15)>0,COUNTIFS(FÉRIAS!$C$2:$C$301,"<="&B15,FÉRIAS!$D$2:$D$301,">="&B15)>0),CHAR(10),"")&IF(COUNTIFS(FÉRIAS!$C$2:$C$301,"<="&B15,FÉRIAS!$D$2:$D$301,">="&B15)>0,"Férias: "&COUNTIFS(FÉRIAS!$C$2:$C$301,"<="&B15,FÉRIAS!$D$2:$D$301,">="&B15),""))) -> Férias: 1 | C16: =IF(MONTH(C15)<>$O$4,"",IF(COUNTIF(AUX!$D$2:$D$901,C15)+COUNTIFS(FÉRIAS!$C$2:$C$301,"<="&C15,FÉRIAS!$D$2:$D$301,">="&C15)=0,"",IF(COUNTIF(AUX!$D$2:$D$901,C15)>0,"Folga: "&COUNTIF(AUX!$D$2:$D$901,C15),"")&IF(AND(COUNTIF(AUX!$D$2:$D$901,C15)>0,COUNTIFS(FÉRIAS!$C$2:$C$301,"<="&C15,FÉRIAS!$D$2:$D$301,">="&C15)>0),CHAR(10),"")&IF(COUNTIFS(FÉRIAS!$C$2:$C$301,"<="&C15,FÉRIAS!$D$2:$D$301,">="&C15)>0,"Férias: "&COUNTIFS(FÉRIAS!$C$2:$C$301,"<="&C15,FÉRIAS!$D$2:$D$301,">="&C15),""))) -> Férias: 1 | D16: =IF(MONTH(D15)<>$O$4,"",IF(COUNTIF(AUX!$D$2:$D$901,D15)+COUNTIFS(FÉRIAS!$C$2:$C$301,"<="&D15,FÉRIAS!$D$2:$D$301,">="&D15)=0,"",IF(COUNTIF(AUX!$D$2:$D$901,D15)>0,"Folga: "&COUNTIF(AUX!$D$2:$D$901,D15),"")&IF(AND(COUNTIF(AUX!$D$2:$D$901,D15)>0,COUNTIFS(FÉRIAS!$C$2:$C$301,"<="&D15,FÉRIAS!$D$2:$D$301,">="&D15)>0),CHAR(10),"")&IF(COUNTIFS(FÉRIAS!$C$2:$C$301,"<="&D15,FÉRIAS!$D$2:$D$301,">="&D15)>0,"Férias: "&COUNTIFS(FÉRIAS!$C$2:$C$301,"<="&D15,FÉRIAS!$D$2:$D$301,">="&D15),""))) -> Férias: 1 | E16: =IF(MONTH(E15)<>$O$4,"",IF(COUNTIF(AUX!$D$2:$D$901,E15)+COUNTIFS(FÉRIAS!$C$2:$C$301,"<="&E15,FÉRIAS!$D$2:$D$301,">="&E15)=0,"",IF(COUNTIF(AUX!$D$2:$D$901,E15)>0,"Folga: "&COUNTIF(AUX!$D$2:$D$901,E15),"")&IF(AND(COUNTIF(AUX!$D$2:$D$901,E15)>0,COUNTIFS(FÉRIAS!$C$2:$C$301,"<="&E15,FÉRIAS!$D$2:$D$301,">="&E15)>0),CHAR(10),"")&IF(COUNTIFS(FÉRIAS!$C$2:$C$301,"<="&E15,FÉRIAS!$D$2:$D$301,">="&E15)>0,"Férias: "&COUNTIFS(FÉRIAS!$C$2:$C$301,"<="&E15,FÉRIAS!$D$2:$D$301,">="&E15),""))) -> Férias: 1 | F16: =IF(MONTH(F15)<>$O$4,"",IF(COUNTIF(AUX!$D$2:$D$901,F15)+COUNTIFS(FÉRIAS!$C$2:$C$301,"<="&F15,FÉRIAS!$D$2:$D$301,">="&F15)=0,"",IF(COUNTIF(AUX!$D$2:$D$901,F15)>0,"Folga: "&COUNTIF(AUX!$D$2:$D$901,F15),"")&IF(AND(COUNTIF(AUX!$D$2:$D$901,F15)>0,COUNTIFS(FÉRIAS!$C$2:$C$301,"<="&F15,FÉRIAS!$D$2:$D$301,">="&F15)>0),CHAR(10),"")&IF(COUNTIFS(FÉRIAS!$C$2:$C$301,"<="&F15,FÉRIAS!$D$2:$D$301,">="&F15)>0,"Férias: "&COUNTIFS(FÉRIAS!$C$2:$C$301,"<="&F15,FÉRIAS!$D$2:$D$301,">="&F15),""))) -> Férias: 1 | G16: =IF(MONTH(G15)<>$O$4,"",IF(COUNTIF(AUX!$D$2:$D$901,G15)+COUNTIFS(FÉRIAS!$C$2:$C$301,"<="&G15,FÉRIAS!$D$2:$D$301,">="&G15)=0,"",IF(COUNTIF(AUX!$D$2:$D$901,G15)>0,"Folga: "&COUNTIF(AUX!$D$2:$D$901,G15),"")&IF(AND(COUNTIF(AUX!$D$2:$D$901,G15)>0,COUNTIFS(FÉRIAS!$C$2:$C$301,"<="&G15,FÉRIAS!$D$2:$D$301,">="&G15)>0),CHAR(10),"")&IF(COUNTIFS(FÉRIAS!$C$2:$C$301,"<="&G15,FÉRIAS!$D$2:$D$301,">="&G15)>0,"Férias: "&COUNTIFS(FÉRIAS!$C$2:$C$301,"<="&G15,FÉRIAS!$D$2:$D$301,">="&G15),""))) -> Férias: 1 | H16: =IF(MONTH(H15)<>$O$4,"",IF(COUNTIF(AUX!$D$2:$D$901,H15)+COUNTIFS(FÉRIAS!$C$2:$C$301,"<="&H15,FÉRIAS!$D$2:$D$301,">="&H15)=0,"",IF(COUNTIF(AUX!$D$2:$D$901,H15)>0,"Folga: "&COUNTIF(AUX!$D$2:$D$901,H15),"")&IF(AND(COUNTIF(AUX!$D$2:$D$901,H15)>0,COUNTIFS(FÉRIAS!$C$2:$C$301,"<="&H15,FÉRIAS!$D$2:$D$301,">="&H15)>0),CHAR(10),"")&IF(COUNTIFS(FÉRIAS!$C$2:$C$301,"<="&H15,FÉRIAS!$D$2:$D$301,">="&H15)>0,"Férias: "&COUNTIFS(FÉRIAS!$C$2:$C$301,"<="&H15,FÉRIAS!$D$2:$D$301,">="&H15),""))) -> Férias: 1 | J16: =IF(P16="","",10) | K16: =IF(P16="","",IF(10<=$O$6,INDEX(AUX!$B:$B,P16),INDEX(FÉRIAS!$A:$A,P16))&"") | L16: =IF(P16="","",IF(10<=$O$6,INDEX(AUX!$C:$C,P16),INDEX(FÉRIAS!$B:$B,P16))&"") | M16: =IF(P16="","",IF(10<=$O$6,INDEX(AUX!$A:$A,P16),"Férias")) | P16: =IF(10>$O$6+$O$7,"",IF(10<=$O$6,SMALL(AUX!$I$2:$I$901,10),SMALL(FÉRIAS!$M$2:$M$301,10-$O$6)))
B17: =$O$5+35 -> 46327 | C17: =$O$5+36 -> 46328 | D17: =$O$5+37 -> 46329 | E17: =$O$5+38 -> 46330 | F17: =$O$5+39 -> 46331 | G17: =$O$5+40 -> 46332 | H17: =$O$5+41 -> 46333 | J17: =IF(P17="","",11) | K17: =IF(P17="","",IF(11<=$O$6,INDEX(AUX!$B:$B,P17),INDEX(FÉRIAS!$A:$A,P17))&"") | L17: =IF(P17="","",IF(11<=$O$6,INDEX(AUX!$C:$C,P17),INDEX(FÉRIAS!$B:$B,P17))&"") | M17: =IF(P17="","",IF(11<=$O$6,INDEX(AUX!$A:$A,P17),"Férias")) | P17: =IF(11>$O$6+$O$7,"",IF(11<=$O$6,SMALL(AUX!$I$2:$I$901,11),SMALL(FÉRIAS!$M$2:$M$301,11-$O$6)))
B18: =IF(MONTH(B17)<>$O$4,"",IF(COUNTIF(AUX!$D$2:$D$901,B17)+COUNTIFS(FÉRIAS!$C$2:$C$301,"<="&B17,FÉRIAS!$D$2:$D$301,">="&B17)=0,"",IF(COUNTIF(AUX!$D$2:$D$901,B17)>0,"Folga: "&COUNTIF(AUX!$D$2:$D$901,B17),"")&IF(AND(COUNTIF(AUX!$D$2:$D$901,B17)>0,COUNTIFS(FÉRIAS!$C$2:$C$301,"<="&B17,FÉRIAS!$D$2:$D$301,">="&B17)>0),CHAR(10),"")&IF(COUNTIFS(FÉRIAS!$C$2:$C$301,"<="&B17,FÉRIAS!$D$2:$D$301,">="&B17)>0,"Férias: "&COUNTIFS(FÉRIAS!$C$2:$C$301,"<="&B17,FÉRIAS!$D$2:$D$301,">="&B17),""))) | C18: =IF(MONTH(C17)<>$O$4,"",IF(COUNTIF(AUX!$D$2:$D$901,C17)+COUNTIFS(FÉRIAS!$C$2:$C$301,"<="&C17,FÉRIAS!$D$2:$D$301,">="&C17)=0,"",IF(COUNTIF(AUX!$D$2:$D$901,C17)>0,"Folga: "&COUNTIF(AUX!$D$2:$D$901,C17),"")&IF(AND(COUNTIF(AUX!$D$2:$D$901,C17)>0,COUNTIFS(FÉRIAS!$C$2:$C$301,"<="&C17,FÉRIAS!$D$2:$D$301,">="&C17)>0),CHAR(10),"")&IF(COUNTIFS(FÉRIAS!$C$2:$C$301,"<="&C17,FÉRIAS!$D$2:$D$301,">="&C17)>0,"Férias: "&COUNTIFS(FÉRIAS!$C$2:$C$301,"<="&C17,FÉRIAS!$D$2:$D$301,">="&C17),""))) | D18: =IF(MONTH(D17)<>$O$4,"",IF(COUNTIF(AUX!$D$2:$D$901,D17)+COUNTIFS(FÉRIAS!$C$2:$C$301,"<="&D17,FÉRIAS!$D$2:$D$301,">="&D17)=0,"",IF(COUNTIF(AUX!$D$2:$D$901,D17)>0,"Folga: "&COUNTIF(AUX!$D$2:$D$901,D17),"")&IF(AND(COUNTIF(AUX!$D$2:$D$901,D17)>0,COUNTIFS(FÉRIAS!$C$2:$C$301,"<="&D17,FÉRIAS!$D$2:$D$301,">="&D17)>0),CHAR(10),"")&IF(COUNTIFS(FÉRIAS!$C$2:$C$301,"<="&D17,FÉRIAS!$D$2:$D$301,">="&D17)>0,"Férias: "&COUNTIFS(FÉRIAS!$C$2:$C$301,"<="&D17,FÉRIAS!$D$2:$D$301,">="&D17),""))) | E18: =IF(MONTH(E17)<>$O$4,"",IF(COUNTIF(AUX!$D$2:$D$901,E17)+COUNTIFS(FÉRIAS!$C$2:$C$301,"<="&E17,FÉRIAS!$D$2:$D$301,">="&E17)=0,"",IF(COUNTIF(AUX!$D$2:$D$901,E17)>0,"Folga: "&COUNTIF(AUX!$D$2:$D$901,E17),"")&IF(AND(COUNTIF(AUX!$D$2:$D$901,E17)>0,COUNTIFS(FÉRIAS!$C$2:$C$301,"<="&E17,FÉRIAS!$D$2:$D$301,">="&E17)>0),CHAR(10),"")&IF(COUNTIFS(FÉRIAS!$C$2:$C$301,"<="&E17,FÉRIAS!$D$2:$D$301,">="&E17)>0,"Férias: "&COUNTIFS(FÉRIAS!$C$2:$C$301,"<="&E17,FÉRIAS!$D$2:$D$301,">="&E17),""))) | F18: =IF(MONTH(F17)<>$O$4,"",IF(COUNTIF(AUX!$D$2:$D$901,F17)+COUNTIFS(FÉRIAS!$C$2:$C$301,"<="&F17,FÉRIAS!$D$2:$D$301,">="&F17)=0,"",IF(COUNTIF(AUX!$D$2:$D$901,F17)>0,"Folga: "&COUNTIF(AUX!$D$2:$D$901,F17),"")&IF(AND(COUNTIF(AUX!$D$2:$D$901,F17)>0,COUNTIFS(FÉRIAS!$C$2:$C$301,"<="&F17,FÉRIAS!$D$2:$D$301,">="&F17)>0),CHAR(10),"")&IF(COUNTIFS(FÉRIAS!$C$2:$C$301,"<="&F17,FÉRIAS!$D$2:$D$301,">="&F17)>0,"Férias: "&COUNTIFS(FÉRIAS!$C$2:$C$301,"<="&F17,FÉRIAS!$D$2:$D$301,">="&F17),""))) | G18: =IF(MONTH(G17)<>$O$4,"",IF(COUNTIF(AUX!$D$2:$D$901,G17)+COUNTIFS(FÉRIAS!$C$2:$C$301,"<="&G17,FÉRIAS!$D$2:$D$301,">="&G17)=0,"",IF(COUNTIF(AUX!$D$2:$D$901,G17)>0,"Folga: "&COUNTIF(AUX!$D$2:$D$901,G17),"")&IF(AND(COUNTIF(AUX!$D$2:$D$901,G17)>0,COUNTIFS(FÉRIAS!$C$2:$C$301,"<="&G17,FÉRIAS!$D$2:$D$301,">="&G17)>0),CHAR(10),"")&IF(COUNTIFS(FÉRIAS!$C$2:$C$301,"<="&G17,FÉRIAS!$D$2:$D$301,">="&G17)>0,"Férias: "&COUNTIFS(FÉRIAS!$C$2:$C$301,"<="&G17,FÉRIAS!$D$2:$D$301,">="&G17),""))) | H18: =IF(MONTH(H17)<>$O$4,"",IF(COUNTIF(AUX!$D$2:$D$901,H17)+COUNTIFS(FÉRIAS!$C$2:$C$301,"<="&H17,FÉRIAS!$D$2:$D$301,">="&H17)=0,"",IF(COUNTIF(AUX!$D$2:$D$901,H17)>0,"Folga: "&COUNTIF(AUX!$D$2:$D$901,H17),"")&IF(AND(COUNTIF(AUX!$D$2:$D$901,H17)>0,COUNTIFS(FÉRIAS!$C$2:$C$301,"<="&H17,FÉRIAS!$D$2:$D$301,">="&H17)>0),CHAR(10),"")&IF(COUNTIFS(FÉRIAS!$C$2:$C$301,"<="&H17,FÉRIAS!$D$2:$D$301,">="&H17)>0,"Férias: "&COUNTIFS(FÉRIAS!$C$2:$C$301,"<="&H17,FÉRIAS!$D$2:$D$301,">="&H17),""))) | J18: =IF(P18="","",12) | K18: =IF(P18="","",IF(12<=$O$6,INDEX(AUX!$B:$B,P18),INDEX(FÉRIAS!$A:$A,P18))&"") | L18: =IF(P18="","",IF(12<=$O$6,INDEX(AUX!$C:$C,P18),INDEX(FÉRIAS!$B:$B,P18))&"") | M18: =IF(P18="","",IF(12<=$O$6,INDEX(AUX!$A:$A,P18),"Férias")) | P18: =IF(12>$O$6+$O$7,"",IF(12<=$O$6,SMALL(AUX!$I$2:$I$901,12),SMALL(FÉRIAS!$M$2:$M$301,12-$O$6)))
J19: =IF(P19="","",13) | K19: =IF(P19="","",IF(13<=$O$6,INDEX(AUX!$B:$B,P19),INDEX(FÉRIAS!$A:$A,P19))&"") | L19: =IF(P19="","",IF(13<=$O$6,INDEX(AUX!$C:$C,P19),INDEX(FÉRIAS!$B:$B,P19))&"") | M19: =IF(P19="","",IF(13<=$O$6,INDEX(AUX!$A:$A,P19),"Férias")) | P19: =IF(13>$O$6+$O$7,"",IF(13<=$O$6,SMALL(AUX!$I$2:$I$901,13),SMALL(FÉRIAS!$M$2:$M$301,13-$O$6)))
B20: Legenda: | C20: Hoje | D20: Dia com ausências | E20: Dia consultado | F20: Fora do mês | J20: =IF(P20="","",14) | K20: =IF(P20="","",IF(14<=$O$6,INDEX(AUX!$B:$B,P20),INDEX(FÉRIAS!$A:$A,P20))&"") | L20: =IF(P20="","",IF(14<=$O$6,INDEX(AUX!$C:$C,P20),INDEX(FÉRIAS!$B:$B,P20))&"") | M20: =IF(P20="","",IF(14<=$O$6,INDEX(AUX!$A:$A,P20),"Férias")) | P20: =IF(14>$O$6+$O$7,"",IF(14<=$O$6,SMALL(AUX!$I$2:$I$901,14),SMALL(FÉRIAS!$M$2:$M$301,14-$O$6)))
B21: “Folga” inclui as folgas da aba FOLGAS e as marcadas como FOLGA em NATAL e ANO NOVO. | J21: =IF(P21="","",15) | K21: =IF(P21="","",IF(15<=$O$6,INDEX(AUX!$B:$B,P21),INDEX(FÉRIAS!$A:$A,P21))&"") | L21: =IF(P21="","",IF(15<=$O$6,INDEX(AUX!$C:$C,P21),INDEX(FÉRIAS!$B:$B,P21))&"") | M21: =IF(P21="","",IF(15<=$O$6,INDEX(AUX!$A:$A,P21),"Férias")) | P21: =IF(15>$O$6+$O$7,"",IF(15<=$O$6,SMALL(AUX!$I$2:$I$901,15),SMALL(FÉRIAS!$M$2:$M$301,15-$O$6)))
J22: =IF(P22="","",16) | K22: =IF(P22="","",IF(16<=$O$6,INDEX(AUX!$B:$B,P22),INDEX(FÉRIAS!$A:$A,P22))&"") | L22: =IF(P22="","",IF(16<=$O$6,INDEX(AUX!$C:$C,P22),INDEX(FÉRIAS!$B:$B,P22))&"") | M22: =IF(P22="","",IF(16<=$O$6,INDEX(AUX!$A:$A,P22),"Férias")) | P22: =IF(16>$O$6+$O$7,"",IF(16<=$O$6,SMALL(AUX!$I$2:$I$901,16),SMALL(FÉRIAS!$M$2:$M$301,16-$O$6)))
J23: =IF(P23="","",17) | K23: =IF(P23="","",IF(17<=$O$6,INDEX(AUX!$B:$B,P23),INDEX(FÉRIAS!$A:$A,P23))&"") | L23: =IF(P23="","",IF(17<=$O$6,INDEX(AUX!$C:$C,P23),INDEX(FÉRIAS!$B:$B,P23))&"") | M23: =IF(P23="","",IF(17<=$O$6,INDEX(AUX!$A:$A,P23),"Férias")) | P23: =IF(17>$O$6+$O$7,"",IF(17<=$O$6,SMALL(AUX!$I$2:$I$901,17),SMALL(FÉRIAS!$M$2:$M$301,17-$O$6)))
J24: =IF(P24="","",18) | K24: =IF(P24="","",IF(18<=$O$6,INDEX(AUX!$B:$B,P24),INDEX(FÉRIAS!$A:$A,P24))&"") | L24: =IF(P24="","",IF(18<=$O$6,INDEX(AUX!$C:$C,P24),INDEX(FÉRIAS!$B:$B,P24))&"") | M24: =IF(P24="","",IF(18<=$O$6,INDEX(AUX!$A:$A,P24),"Férias")) | P24: =IF(18>$O$6+$O$7,"",IF(18<=$O$6,SMALL(AUX!$I$2:$I$901,18),SMALL(FÉRIAS!$M$2:$M$301,18-$O$6)))
J25: =IF(P25="","",19) | K25: =IF(P25="","",IF(19<=$O$6,INDEX(AUX!$B:$B,P25),INDEX(FÉRIAS!$A:$A,P25))&"") | L25: =IF(P25="","",IF(19<=$O$6,INDEX(AUX!$C:$C,P25),INDEX(FÉRIAS!$B:$B,P25))&"") | M25: =IF(P25="","",IF(19<=$O$6,INDEX(AUX!$A:$A,P25),"Férias")) | P25: =IF(19>$O$6+$O$7,"",IF(19<=$O$6,SMALL(AUX!$I$2:$I$901,19),SMALL(FÉRIAS!$M$2:$M$301,19-$O$6)))
J26: =IF(P26="","",20) | K26: =IF(P26="","",IF(20<=$O$6,INDEX(AUX!$B:$B,P26),INDEX(FÉRIAS!$A:$A,P26))&"") | L26: =IF(P26="","",IF(20<=$O$6,INDEX(AUX!$C:$C,P26),INDEX(FÉRIAS!$B:$B,P26))&"") | M26: =IF(P26="","",IF(20<=$O$6,INDEX(AUX!$A:$A,P26),"Férias")) | P26: =IF(20>$O$6+$O$7,"",IF(20<=$O$6,SMALL(AUX!$I$2:$I$901,20),SMALL(FÉRIAS!$M$2:$M$301,20-$O$6)))
J27: =IF($O$6+$O$7=0,"Ninguém de folga ou férias nesta data.",IF($O$6+$O$7>20,"... e mais "&($O$6+$O$7-20)&" pessoa(s).","")) -> Ninguém de folga ou férias nesta data.

Sheet FOLGAS
A1: Nome | B1: Setor | C1: Data da Folga | D1: Observação | E1: Dia da Semana | F1: Status | G1: Alerta
A2: SÉRGIO SÁ | B2: FISCALIZAÇÃO | E2: =IF(ISNUMBER(C2),CHOOSE(WEEKDAY(C2),"Domingo","Segunda","Terça","Quarta","Quinta","Sexta","Sábado"),"") | F2: =IF(NOT(ISNUMBER(C2)),"",IF(C2=TODAY(),"HOJE",IF(C2=TODAY()+1,"AMANHÃ",IF(C2<TODAY(),"Realizada",IF(C2-TODAY()<=7,"Em "&(C2-TODAY())&" dias","Agendada"))))) | G2: =IF(OR(A2="",NOT(ISNUMBER(C2))),"",IF(COUNTIFS($A$2:$A$301,A2,$C$2:$C$301,C2)>1,"⚠ Folga duplicada",IF(COUNTIFS(FÉRIAS!$A$2:$A$301,A2,FÉRIAS!$C$2:$C$301,"<="&C2,FÉRIAS!$D$2:$D$301,">="&C2)>0,"⚠ Está de férias nesta data",IF(COUNTIFS(NATAL!$A$2:$A$301,A2,NATAL!$C$2:$C$301,C2,NATAL!$D$2:$D$301,"FOLGA")+COUNTIFS('ANO NOVO'!$A$2:$A$301,A2,'ANO NOVO'!$C$2:$C$301,C2,'ANO NOVO'!$D$2:$D$301,"FOLGA")>0,"⚠ Folga já lançada em NATAL/ANO NOVO",IF(COUNTIFS(NATAL!$A$2:$A$301,A2,NATAL!$C$2:$C$301,C2,NATAL!$D$2:$D$301,"TRABALHA")+COUNTIFS('ANO NOVO'!$A$2:$A$301,A2,'ANO NOVO'!$C$2:$C$301,C2,'ANO NOVO'!$D$2:$D$301,"TRABALHA")>0,"⚠ Marcado TRABALHA em NATAL/ANO NOVO",IF(COUNTIFS($B$2:$B$301,B2,$C$2:$C$301,C2)>1,"⚠ "&COUNTIFS($B$2:$B$301,B2,$C$2:$C$301,C2)&" pessoas do setor de folga no dia",""))))))
A3: CARLOS ALEXANDRE | B3: FISCALIZAÇÃO | E3: =IF(ISNUMBER(C3),CHOOSE(WEEKDAY(C3),"Domingo","Segunda","Terça","Quarta","Quinta","Sexta","Sábado"),"") | F3: =IF(NOT(ISNUMBER(C3)),"",IF(C3=TODAY(),"HOJE",IF(C3=TODAY()+1,"AMANHÃ",IF(C3<TODAY(),"Realizada",IF(C3-TODAY()<=7,"Em "&(C3-TODAY())&" dias","Agendada"))))) | G3: =IF(OR(A3="",NOT(ISNUMBER(C3))),"",IF(COUNTIFS($A$2:$A$301,A3,$C$2:$C$301,C3)>1,"⚠ Folga duplicada",IF(COUNTIFS(FÉRIAS!$A$2:$A$301,A3,FÉRIAS!$C$2:$C$301,"<="&C3,FÉRIAS!$D$2:$D$301,">="&C3)>0,"⚠ Está de férias nesta data",IF(COUNTIFS(NATAL!$A$2:$A$301,A3,NATAL!$C$2:$C$301,C3,NATAL!$D$2:$D$301,"FOLGA")+COUNTIFS('ANO NOVO'!$A$2:$A$301,A3,'ANO NOVO'!$C$2:$C$301,C3,'ANO NOVO'!$D$2:$D$301,"FOLGA")>0,"⚠ Folga já lançada em NATAL/ANO NOVO",IF(COUNTIFS(NATAL!$A$2:$A$301,A3,NATAL!$C$2:$C$301,C3,NATAL!$D$2:$D$301,"TRABALHA")+COUNTIFS('ANO NOVO'!$A$2:$A$301,A3,'ANO NOVO'!$C$2:$C$301,C3,'ANO NOVO'!$D$2:$D$301,"TRABALHA")>0,"⚠ Marcado TRABALHA em NATAL/ANO NOVO",IF(COUNTIFS($B$2:$B$301,B3,$C$2:$C$301,C3)>1,"⚠ "&COUNTIFS($B$2:$B$301,B3,$C$2:$C$301,C3)&" pessoas do setor de folga no dia",""))))))
A4: BRUNA RAFAELA | B4: JURÍDICO | E4: =IF(ISNUMBER(C4),CHOOSE(WEEKDAY(C4),"Domingo","Segunda","Terça","Quarta","Quinta","Sexta","Sábado"),"") | F4: =IF(NOT(ISNUMBER(C4)),"",IF(C4=TODAY(),"HOJE",IF(C4=TODAY()+1,"AMANHÃ",IF(C4<TODAY(),"Realizada",IF(C4-TODAY()<=7,"Em "&(C4-TODAY())&" dias","Agendada"))))) | G4: =IF(OR(A4="",NOT(ISNUMBER(C4))),"",IF(COUNTIFS($A$2:$A$301,A4,$C$2:$C$301,C4)>1,"⚠ Folga duplicada",IF(COUNTIFS(FÉRIAS!$A$2:$A$301,A4,FÉRIAS!$C$2:$C$301,"<="&C4,FÉRIAS!$D$2:$D$301,">="&C4)>0,"⚠ Está de férias nesta data",IF(COUNTIFS(NATAL!$A$2:$A$301,A4,NATAL!$C$2:$C$301,C4,NATAL!$D$2:$D$301,"FOLGA")+COUNTIFS('ANO NOVO'!$A$2:$A$301,A4,'ANO NOVO'!$C$2:$C$301,C4,'ANO NOVO'!$D$2:$D$301,"FOLGA")>0,"⚠ Folga já lançada em NATAL/ANO NOVO",IF(COUNTIFS(NATAL!$A$2:$A$301,A4,NATAL!$C$2:$C$301,C4,NATAL!$D$2:$D$301,"TRABALHA")+COUNTIFS('ANO NOVO'!$A$2:$A$301,A4,'ANO NOVO'!$C$2:$C$301,C4,'ANO NOVO'!$D$2:$D$301,"TRABALHA")>0,"⚠ Marcado TRABALHA em NATAL/ANO NOVO",IF(COUNTIFS($B$2:$B$301,B4,$C$2:$C$301,C4)>1,"⚠ "&COUNTIFS($B$2:$B$301,B4,$C$2:$C$301,C4)&" pessoas do setor de folga no dia",""))))))
A5: FABIO FERREIRA | B5: FISCALIZAÇÃO | E5: =IF(ISNUMBER(C5),CHOOSE(WEEKDAY(C5),"Domingo","Segunda","Terça","Quarta","Quinta","Sexta","Sábado"),"") | F5: =IF(NOT(ISNUMBER(C5)),"",IF(C5=TODAY(),"HOJE",IF(C5=TODAY()+1,"AMANHÃ",IF(C5<TODAY(),"Realizada",IF(C5-TODAY()<=7,"Em "&(C5-TODAY())&" dias","Agendada"))))) | G5: =IF(OR(A5="",NOT(ISNUMBER(C5))),"",IF(COUNTIFS($A$2:$A$301,A5,$C$2:$C$301,C5)>1,"⚠ Folga duplicada",IF(COUNTIFS(FÉRIAS!$A$2:$A$301,A5,FÉRIAS!$C$2:$C$301,"<="&C5,FÉRIAS!$D$2:$D$301,">="&C5)>0,"⚠ Está de férias nesta data",IF(COUNTIFS(NATAL!$A$2:$A$301,A5,NATAL!$C$2:$C$301,C5,NATAL!$D$2:$D$301,"FOLGA")+COUNTIFS('ANO NOVO'!$A$2:$A$301,A5,'ANO NOVO'!$C$2:$C$301,C5,'ANO NOVO'!$D$2:$D$301,"FOLGA")>0,"⚠ Folga já lançada em NATAL/ANO NOVO",IF(COUNTIFS(NATAL!$A$2:$A$301,A5,NATAL!$C$2:$C$301,C5,NATAL!$D$2:$D$301,"TRABALHA")+COUNTIFS('ANO NOVO'!$A$2:$A$301,A5,'ANO NOVO'!$C$2:$C$301,C5,'ANO NOVO'!$D$2:$D$301,"TRABALHA")>0,"⚠ Marcado TRABALHA em NATAL/ANO NOVO",IF(COUNTIFS($B$2:$B$301,B5,$C$2:$C$301,C5)>1,"⚠ "&COUNTIFS($B$2:$B$301,B5,$C$2:$C$301,C5)&" pessoas do setor de folga no dia",""))))))
A6: PAULA LOBO | B6: JURÍDICO | E6: =IF(ISNUMBER(C6),CHOOSE(WEEKDAY(C6),"Domingo","Segunda","Terça","Quarta","Quinta","Sexta","Sábado"),"") | F6: =IF(NOT(ISNUMBER(C6)),"",IF(C6=TODAY(),"HOJE",IF(C6=TODAY()+1,"AMANHÃ",IF(C6<TODAY(),"Realizada",IF(C6-TODAY()<=7,"Em "&(C6-TODAY())&" dias","Agendada"))))) | G6: =IF(OR(A6="",NOT(ISNUMBER(C6))),"",IF(COUNTIFS($A$2:$A$301,A6,$C$2:$C$301,C6)>1,"⚠ Folga duplicada",IF(COUNTIFS(FÉRIAS!$A$2:$A$301,A6,FÉRIAS!$C$2:$C$301,"<="&C6,FÉRIAS!$D$2:$D$301,">="&C6)>0,"⚠ Está de férias nesta data",IF(COUNTIFS(NATAL!$A$2:$A$301,A6,NATAL!$C$2:$C$301,C6,NATAL!$D$2:$D$301,"FOLGA")+COUNTIFS('ANO NOVO'!$A$2:$A$301,A6,'ANO NOVO'!$C$2:$C$301,C6,'ANO NOVO'!$D$2:$D$301,"FOLGA")>0,"⚠ Folga já lançada em NATAL/ANO NOVO",IF(COUNTIFS(NATAL!$A$2:$A$301,A6,NATAL!$C$2:$C$301,C6,NATAL!$D$2:$D$301,"TRABALHA")+COUNTIFS('ANO NOVO'!$A$2:$A$301,A6,'ANO NOVO'!$C$2:$C$301,C6,'ANO NOVO'!$D$2:$D$301,"TRABALHA")>0,"⚠ Marcado TRABALHA em NATAL/ANO NOVO",IF(COUNTIFS($B$2:$B$301,B6,$C$2:$C$301,C6)>1,"⚠ "&COUNTIFS($B$2:$B$301,B6,$C$2:$C$301,C6)&" pessoas do setor de folga no dia",""))))))
A7: RAPHAEL PINTO | B7: JURÍDICO | E7: =IF(ISNUMBER(C7),CHOOSE(WEEKDAY(C7),"Domingo","Segunda","Terça","Quarta","Quinta","Sexta","Sábado"),"") | F7: =IF(NOT(ISNUMBER(C7)),"",IF(C7=TODAY(),"HOJE",IF(C7=TODAY()+1,"AMANHÃ",IF(C7<TODAY(),"Realizada",IF(C7-TODAY()<=7,"Em "&(C7-TODAY())&" dias","Agendada"))))) | G7: =IF(OR(A7="",NOT(ISNUMBER(C7))),"",IF(COUNTIFS($A$2:$A$301,A7,$C$2:$C$301,C7)>1,"⚠ Folga duplicada",IF(COUNTIFS(FÉRIAS!$A$2:$A$301,A7,FÉRIAS!$C$2:$C$301,"<="&C7,FÉRIAS!$D$2:$D$301,">="&C7)>0,"⚠ Está de férias nesta data",IF(COUNTIFS(NATAL!$A$2:$A$301,A7,NATAL!$C$2:$C$301,C7,NATAL!$D$2:$D$301,"FOLGA")+COUNTIFS('ANO NOVO'!$A$2:$A$301,A7,'ANO NOVO'!$C$2:$C$301,C7,'ANO NOVO'!$D$2:$D$301,"FOLGA")>0,"⚠ Folga já lançada em NATAL/ANO NOVO",IF(COUNTIFS(NATAL!$A$2:$A$301,A7,NATAL!$C$2:$C$301,C7,NATAL!$D$2:$D$301,"TRABALHA")+COUNTIFS('ANO NOVO'!$A$2:$A$301,A7,'ANO NOVO'!$C$2:$C$301,C7,'ANO NOVO'!$D$2:$D$301,"TRABALHA")>0,"⚠ Marcado TRABALHA em NATAL/ANO NOVO",IF(COUNTIFS($B$2:$B$301,B7,$C$2:$C$301,C7)>1,"⚠ "&COUNTIFS($B$2:$B$301,B7,$C$2:$C$301,C7)&" pessoas do setor de folga no dia",""))))))
A8: ANTONIO | B8: FISCALIZAÇÃO | E8: =IF(ISNUMBER(C8),CHOOSE(WEEKDAY(C8),"Domingo","Segunda","Terça","Quarta","Quinta","Sexta","Sábado"),"") | F8: =IF(NOT(ISNUMBER(C8)),"",IF(C8=TODAY(),"HOJE",IF(C8=TODAY()+1,"AMANHÃ",IF(C8<TODAY(),"Realizada",IF(C8-TODAY()<=7,"Em "&(C8-TODAY())&" dias","Agendada"))))) | G8: =IF(OR(A8="",NOT(ISNUMBER(C8))),"",IF(COUNTIFS($A$2:$A$301,A8,$C$2:$C$301,C8)>1,"⚠ Folga duplicada",IF(COUNTIFS(FÉRIAS!$A$2:$A$301,A8,FÉRIAS!$C$2:$C$301,"<="&C8,FÉRIAS!$D$2:$D$301,">="&C8)>0,"⚠ Está de férias nesta data",IF(COUNTIFS(NATAL!$A$2:$A$301,A8,NATAL!$C$2:$C$301,C8,NATAL!$D$2:$D$301,"FOLGA")+COUNTIFS('ANO NOVO'!$A$2:$A$301,A8,'ANO NOVO'!$C$2:$C$301,C8,'ANO NOVO'!$D$2:$D$301,"FOLGA")>0,"⚠ Folga já lançada em NATAL/ANO NOVO",IF(COUNTIFS(NATAL!$A$2:$A$301,A8,NATAL!$C$2:$C$301,C8,NATAL!$D$2:$D$301,"TRABALHA")+COUNTIFS('ANO NOVO'!$A$2:$A$301,A8,'ANO NOVO'!$C$2:$C$301,C8,'ANO NOVO'!$D$2:$D$301,"TRABALHA")>0,"⚠ Marcado TRABALHA em NATAL/ANO NOVO",IF(COUNTIFS($B$2:$B$301,B8,$C$2:$C$301,C8)>1,"⚠ "&COUNTIFS($B$2:$B$301,B8,$C$2:$C$301,C8)&" pessoas do setor de folga no dia",""))))))
A9: FABIO MARQUES | B9: FISCALIZAÇÃO | E9: =IF(ISNUMBER(C9),CHOOSE(WEEKDAY(C9),"Domingo","Segunda","Terça","Quarta","Quinta","Sexta","Sábado"),"") | F9: =IF(NOT(ISNUMBER(C9)),"",IF(C9=TODAY(),"HOJE",IF(C9=TODAY()+1,"AMANHÃ",IF(C9<TODAY(),"Realizada",IF(C9-TODAY()<=7,"Em "&(C9-TODAY())&" dias","Agendada"))))) | G9: =IF(OR(A9="",NOT(ISNUMBER(C9))),"",IF(COUNTIFS($A$2:$A$301,A9,$C$2:$C$301,C9)>1,"⚠ Folga duplicada",IF(COUNTIFS(FÉRIAS!$A$2:$A$301,A9,FÉRIAS!$C$2:$C$301,"<="&C9,FÉRIAS!$D$2:$D$301,">="&C9)>0,"⚠ Está de férias nesta data",IF(COUNTIFS(NATAL!$A$2:$A$301,A9,NATAL!$C$2:$C$301,C9,NATAL!$D$2:$D$301,"FOLGA")+COUNTIFS('ANO NOVO'!$A$2:$A$301,A9,'ANO NOVO'!$C$2:$C$301,C9,'ANO NOVO'!$D$2:$D$301,"FOLGA")>0,"⚠ Folga já lançada em NATAL/ANO NOVO",IF(COUNTIFS(NATAL!$A$2:$A$301,A9,NATAL!$C$2:$C$301,C9,NATAL!$D$2:$D$301,"TRABALHA")+COUNTIFS('ANO NOVO'!$A$2:$A$301,A9,'ANO NOVO'!$C$2:$C$301,C9,'ANO NOVO'!$D$2:$D$301,"TRABALHA")>0,"⚠ Marcado TRABALHA em NATAL/ANO NOVO",IF(COUNTIFS($B$2:$B$301,B9,$C$2:$C$301,C9)>1,"⚠ "&COUNTIFS($B$2:$B$301,B9,$C$2:$C$301,C9)&" pessoas do setor de folga no dia",""))))))
A10: MARINA | B10: ATENDIMENTO | E10: =IF(ISNUMBER(C10),CHOOSE(WEEKDAY(C10),"Domingo","Segunda","Terça","Quarta","Quinta","Sexta","Sábado"),"") | F10: =IF(NOT(ISNUMBER(C10)),"",IF(C10=TODAY(),"HOJE",IF(C10=TODAY()+1,"AMANHÃ",IF(C10<TODAY(),"Realizada",IF(C10-TODAY()<=7,"Em "&(C10-TODAY())&" dias","Agendada"))))) | G10: =IF(OR(A10="",NOT(ISNUMBER(C10))),"",IF(COUNTIFS($A$2:$A$301,A10,$C$2:$C$301,C10)>1,"⚠ Folga duplicada",IF(COUNTIFS(FÉRIAS!$A$2:$A$301,A10,FÉRIAS!$C$2:$C$301,"<="&C10,FÉRIAS!$D$2:$D$301,">="&C10)>0,"⚠ Está de férias nesta data",IF(COUNTIFS(NATAL!$A$2:$A$301,A10,NATAL!$C$2:$C$301,C10,NATAL!$D$2:$D$301,"FOLGA")+COUNTIFS('ANO NOVO'!$A$2:$A$301,A10,'ANO NOVO'!$C$2:$C$301,C10,'ANO NOVO'!$D$2:$D$301,"FOLGA")>0,"⚠ Folga já lançada em NATAL/ANO NOVO",IF(COUNTIFS(NATAL!$A$2:$A$301,A10,NATAL!$C$2:$C$301,C10,NATAL!$D$2:$D$301,"TRABALHA")+COUNTIFS('ANO NOVO'!$A$2:$A$301,A10,'ANO NOVO'!$C$2:$C$301,C10,'ANO NOVO'!$D$2:$D$301,"TRABALHA")>0,"⚠ Marcado TRABALHA em NATAL/ANO NOVO",IF(COUNTIFS($B$2:$B$301,B10,$C$2:$C$301,C10)>1,"⚠ "&COUNTIFS($B$2:$B$301,B10,$C$2:$C$301,C10)&" pessoas do setor de folga no dia",""))))))
A11: DIOGO | B11: ATENDIMENTO | E11: =IF(ISNUMBER(C11),CHOOSE(WEEKDAY(C11),"Domingo","Segunda","Terça","Quarta","Quinta","Sexta","Sábado"),"") | F11: =IF(NOT(ISNUMBER(C11)),"",IF(C11=TODAY(),"HOJE",IF(C11=TODAY()+1,"AMANHÃ",IF(C11<TODAY(),"Realizada",IF(C11-TODAY()<=7,"Em "&(C11-TODAY())&" dias","Agendada"))))) | G11: =IF(OR(A11="",NOT(ISNUMBER(C11))),"",IF(COUNTIFS($A$2:$A$301,A11,$C$2:$C$301,C11)>1,"⚠ Folga duplicada",IF(COUNTIFS(FÉRIAS!$A$2:$A$301,A11,FÉRIAS!$C$2:$C$301,"<="&C11,FÉRIAS!$D$2:$D$301,">="&C11)>0,"⚠ Está de férias nesta data",IF(COUNTIFS(NATAL!$A$2:$A$301,A11,NATAL!$C$2:$C$301,C11,NATAL!$D$2:$D$301,"FOLGA")+COUNTIFS('ANO NOVO'!$A$2:$A$301,A11,'ANO NOVO'!$C$2:$C$301,C11,'ANO NOVO'!$D$2:$D$301,"FOLGA")>0,"⚠ Folga já lançada em NATAL/ANO NOVO",IF(COUNTIFS(NATAL!$A$2:$A$301,A11,NATAL!$C$2:$C$301,C11,NATAL!$D$2:$D$301,"TRABALHA")+COUNTIFS('ANO NOVO'!$A$2:$A$301,A11,'ANO NOVO'!$C$2:$C$301,C11,'ANO NOVO'!$D$2:$D$301,"TRABALHA")>0,"⚠ Marcado TRABALHA em NATAL/ANO NOVO",IF(COUNTIFS($B$2:$B$301,B11,$C$2:$C$301,C11)>1,"⚠ "&COUNTIFS($B$2:$B$301,B11,$C$2:$C$301,C11)&" pessoas do setor de folga no dia",""))))))
A12: DOUGLAS | B12: ATENDIMENTO | E12: =IF(ISNUMBER(C12),CHOOSE(WEEKDAY(C12),"Domingo","Segunda","Terça","Quarta","Quinta","Sexta","Sábado"),"") | F12: =IF(NOT(ISNUMBER(C12)),"",IF(C12=TODAY(),"HOJE",IF(C12=TODAY()+1,"AMANHÃ",IF(C12<TODAY(),"Realizada",IF(C12-TODAY()<=7,"Em "&(C12-TODAY())&" dias","Agendada"))))) | G12: =IF(OR(A12="",NOT(ISNUMBER(C12))),"",IF(COUNTIFS($A$2:$A$301,A12,$C$2:$C$301,C12)>1,"⚠ Folga duplicada",IF(COUNTIFS(FÉRIAS!$A$2:$A$301,A12,FÉRIAS!$C$2:$C$301,"<="&C12,FÉRIAS!$D$2:$D$301,">="&C12)>0,"⚠ Está de férias nesta data",IF(COUNTIFS(NATAL!$A$2:$A$301,A12,NATAL!$C$2:$C$301,C12,NATAL!$D$2:$D$301,"FOLGA")+COUNTIFS('ANO NOVO'!$A$2:$A$301,A12,'ANO NOVO'!$C$2:$C$301,C12,'ANO NOVO'!$D$2:$D$301,"FOLGA")>0,"⚠ Folga já lançada em NATAL/ANO NOVO",IF(COUNTIFS(NATAL!$A$2:$A$301,A12,NATAL!$C$2:$C$301,C12,NATAL!$D$2:$D$301,"TRABALHA")+COUNTIFS('ANO NOVO'!$A$2:$A$301,A12,'ANO NOVO'!$C$2:$C$301,C12,'ANO NOVO'!$D$2:$D$301,"TRABALHA")>0,"⚠ Marcado TRABALHA em NATAL/ANO NOVO",IF(COUNTIFS($B$2:$B$301,B12,$C$2:$C$301,C12)>1,"⚠ "&COUNTIFS($B$2:$B$301,B12,$C$2:$C$301,C12)&" pessoas do setor de folga no dia",""))))))
A13: KAROLINE MANZI | B13: ATENDIMENTO | E13: =IF(ISNUMBER(C13),CHOOSE(WEEKDAY(C13),"Domingo","Segunda","Terça","Quarta","Quinta","Sexta","Sábado"),"") | F13: =IF(NOT(ISNUMBER(C13)),"",IF(C13=TODAY(),"HOJE",IF(C13=TODAY()+1,"AMANHÃ",IF(C13<TODAY(),"Realizada",IF(C13-TODAY()<=7,"Em "&(C13-TODAY())&" dias","Agendada"))))) | G13: =IF(OR(A13="",NOT(ISNUMBER(C13))),"",IF(COUNTIFS($A$2:$A$301,A13,$C$2:$C$301,C13)>1,"⚠ Folga duplicada",IF(COUNTIFS(FÉRIAS!$A$2:$A$301,A13,FÉRIAS!$C$2:$C$301,"<="&C13,FÉRIAS!$D$2:$D$301,">="&C13)>0,"⚠ Está de férias nesta data",IF(COUNTIFS(NATAL!$A$2:$A$301,A13,NATAL!$C$2:$C$301,C13,NATAL!$D$2:$D$301,"FOLGA")+COUNTIFS('ANO NOVO'!$A$2:$A$301,A13,'ANO NOVO'!$C$2:$C$301,C13,'ANO NOVO'!$D$2:$D$301,"FOLGA")>0,"⚠ Folga já lançada em NATAL/ANO NOVO",IF(COUNTIFS(NATAL!$A$2:$A$301,A13,NATAL!$C$2:$C$301,C13,NATAL!$D$2:$D$301,"TRABALHA")+COUNTIFS('ANO NOVO'!$A$2:$A$301,A13,'ANO NOVO'!$C$2:$C$301,C13,'ANO NOVO'!$D$2:$D$301,"TRABALHA")>0,"⚠ Marcado TRABALHA em NATAL/ANO NOVO",IF(COUNTIFS($B$2:$B$301,B13,$C$2:$C$301,C13)>1,"⚠ "&COUNTIFS($B$2:$B$301,B13,$C$2:$C$301,C13)&" pessoas do setor de folga no dia",""))))))
... A20: INGRID | B20: ATENDIMENTO | E20: =IF(ISNUMBER(C20),CHOOSE(WEEKDAY(C20),"Domingo","Segunda","Terça","Quarta","Quinta","Sexta","Sábado"),"") | F20: =IF(NOT(ISNUMBER(C20)),"",IF(C20=TODAY(),"HOJE",IF(C20=TODAY()+1,"AMANHÃ",IF(C20<TODAY(),"Realizada",IF(C20-TODAY()<=7,"Em "&(C20-TODAY())&" dias","Agendada"))))) | G20: =IF(OR(A20="",NOT(ISNUMBER(C20))),"",IF(COUNTIFS($A$2:$A$301,A20,$C$2:$C$301,C20)>1,"⚠ Folga duplicada",IF(COUNTIFS(FÉRIAS!$A$2:$A$301,A20,FÉRIAS!$C$2:$C$301,"<="&C20,FÉRIAS!$D$2:$D$301,">="&C20)>0,"⚠ Está de férias nesta data",IF(COUNTIFS(NATAL!$A$2:$A$301,A20,NATAL!$C$2:$C$301,C20,NATAL!$D$2:$D$301,"FOLGA")+COUNTIFS('ANO NOVO'!$A$2:$A$301,A20,'ANO NOVO'!$C$2:$C$301,C20,'ANO NOVO'!$D$2:$D$301,"FOLGA")>0,"⚠ Folga já lançada em NATAL/ANO NOVO",IF(COUNTIFS(NATAL!$A$2:$A$301,A20,NATAL!$C$2:$C$301,C20,NATAL!$D$2:$D$301,"TRABALHA")+COUNTIFS('ANO NOVO'!$A$2:$A$301,A20,'ANO NOVO'!$C$2:$C$301,C20,'ANO NOVO'!$D$2:$D$301,"TRABALHA")>0,"⚠ Marcado TRABALHA em NATAL/ANO NOVO",IF(COUNTIFS($B$2:$B$301,B20,$C$2:$C$301,C20)>1,"⚠ "&COUNTIFS($B$2:$B$301,B20,$C$2:$C$301,C20)&" pessoas do setor de folga no dia",""))))))
E21: =IF(ISNUMBER(C21),CHOOSE(WEEKDAY(C21),"Domingo","Segunda","Terça","Quarta","Quinta","Sexta","Sábado"),"") | F21: =IF(NOT(ISNUMBER(C21)),"",IF(C21=TODAY(),"HOJE",IF(C21=TODAY()+1,"AMANHÃ",IF(C21<TODAY(),"Realizada",IF(C21-TODAY()<=7,"Em "&(C21-TODAY())&" dias","Agendada"))))) | G21: =IF(OR(A21="",NOT(ISNUMBER(C21))),"",IF(COUNTIFS($A$2:$A$301,A21,$C$2:$C$301,C21)>1,"⚠ Folga duplicada",IF(COUNTIFS(FÉRIAS!$A$2:$A$301,A21,FÉRIAS!$C$2:$C$301,"<="&C21,FÉRIAS!$D$2:$D$301,">="&C21)>0,"⚠ Está de férias nesta data",IF(COUNTIFS(NATAL!$A$2:$A$301,A21,NATAL!$C$2:$C$301,C21,NATAL!$D$2:$D$301,"FOLGA")+COUNTIFS('ANO NOVO'!$A$2:$A$301,A21,'ANO NOVO'!$C$2:$C$301,C21,'ANO NOVO'!$D$2:$D$301,"FOLGA")>0,"⚠ Folga já lançada em NATAL/ANO NOVO",IF(COUNTIFS(NATAL!$A$2:$A$301,A21,NATAL!$C$2:$C$301,C21,NATAL!$D$2:$D$301,"TRABALHA")+COUNTIFS('ANO NOVO'!$A$2:$A$301,A21,'ANO NOVO'!$C$2:$C$301,C21,'ANO NOVO'!$D$2:$D$301,"TRABALHA")>0,"⚠ Marcado TRABALHA em NATAL/ANO NOVO",IF(COUNTIFS($B$2:$B$301,B21,$C$2:$C$301,C21)>1,"⚠ "&COUNTIFS($B$2:$B$301,B21,$C$2:$C$301,C21)&" pessoas do setor de folga no dia",""))))))
E22: =IF(ISNUMBER(C22),CHOOSE(WEEKDAY(C22),"Domingo","Segunda","Terça","Quarta","Quinta","Sexta","Sábado"),"") | F22: =IF(NOT(ISNUMBER(C22)),"",IF(C22=TODAY(),"HOJE",IF(C22=TODAY()+1,"AMANHÃ",IF(C22<TODAY(),"Realizada",IF(C22-TODAY()<=7,"Em "&(C22-TODAY())&" dias","Agendada"))))) | G22: =IF(OR(A22="",NOT(ISNUMBER(C22))),"",IF(COUNTIFS($A$2:$A$301,A22,$C$2:$C$301,C22)>1,"⚠ Folga duplicada",IF(COUNTIFS(FÉRIAS!$A$2:$A$301,A22,FÉRIAS!$C$2:$C$301,"<="&C22,FÉRIAS!$D$2:$D$301,">="&C22)>0,"⚠ Está de férias nesta data",IF(COUNTIFS(NATAL!$A$2:$A$301,A22,NATAL!$C$2:$C$301,C22,NATAL!$D$2:$D$301,"FOLGA")+COUNTIFS('ANO NOVO'!$A$2:$A$301,A22,'ANO NOVO'!$C$2:$C$301,C22,'ANO NOVO'!$D$2:$D$301,"FOLGA")>0,"⚠ Folga já lançada em NATAL/ANO NOVO",IF(COUNTIFS(NATAL!$A$2:$A$301,A22,NATAL!$C$2:$C$301,C22,NATAL!$D$2:$D$301,"TRABALHA")+COUNTIFS('ANO NOVO'!$A$2:$A$301,A22,'ANO NOVO'!$C$2:$C$301,C22,'ANO NOVO'!$D$2:$D$301,"TRABALHA")>0,"⚠ Marcado TRABALHA em NATAL/ANO NOVO",IF(COUNTIFS($B$2:$B$301,B22,$C$2:$C$301,C22)>1,"⚠ "&COUNTIFS($B$2:$B$301,B22,$C$2:$C$301,C22)&" pessoas do setor de folga no dia",""))))))
E23: =IF(ISNUMBER(C23),CHOOSE(WEEKDAY(C23),"Domingo","Segunda","Terça","Quarta","Quinta","Sexta","Sábado"),"") | F23: =IF(NOT(ISNUMBER(C23)),"",IF(C23=TODAY(),"HOJE",IF(C23=TODAY()+1,"AMANHÃ",IF(C23<TODAY(),"Realizada",IF(C23-TODAY()<=7,"Em "&(C23-TODAY())&" dias","Agendada"))))) | G23: =IF(OR(A23="",NOT(ISNUMBER(C23))),"",IF(COUNTIFS($A$2:$A$301,A23,$C$2:$C$301,C23)>1,"⚠ Folga duplicada",IF(COUNTIFS(FÉRIAS!$A$2:$A$301,A23,FÉRIAS!$C$2:$C$301,"<="&C23,FÉRIAS!$D$2:$D$301,">="&C23)>0,"⚠ Está de férias nesta data",IF(COUNTIFS(NATAL!$A$2:$A$301,A23,NATAL!$C$2:$C$301,C23,NATAL!$D$2:$D$301,"FOLGA")+COUNTIFS('ANO NOVO'!$A$2:$A$301,A23,'ANO NOVO'!$C$2:$C$301,C23,'ANO NOVO'!$D$2:$D$301,"FOLGA")>0,"⚠ Folga já lançada em NATAL/ANO NOVO",IF(COUNTIFS(NATAL!$A$2:$A$301,A23,NATAL!$C$2:$C$301,C23,NATAL!$D$2:$D$301,"TRABALHA")+COUNTIFS('ANO NOVO'!$A$2:$A$301,A23,'ANO NOVO'!$C$2:$C$301,C23,'ANO NOVO'!$D$2:$D$301,"TRABALHA")>0,"⚠ Marcado TRABALHA em NATAL/ANO NOVO",IF(COUNTIFS($B$2:$B$301,B23,$C$2:$C$301,C23)>1,"⚠ "&COUNTIFS($B$2:$B$301,B23,$C$2:$C$301,C23)&" pessoas do setor de folga no dia",""))))))
